# Note that single quote ' should be escaped by another single quote '
# Example(see: Can''t):     '.* ERR kernel: \[\s+\d+\.\d+\] /dev/sda3: Can''t open blockdev'
# Example: in code below - errors will be ignored:
# IF: test case name: tests/test_dbg.py::test_a
# OR
# IF: Redmine issue active AND branch is 202106 AND sn2 in platform
# OR
# IF: GitHub issue is active
#- Errors_list:
#    - '.* ERR \d+'
#    - 'ERR can''t do \d+'
#  Conditions:
#    - Affected_test_cases:
#      - tests/test_dbg.py::test_a
#    - Redmine:
#      - 2829157
#      Branch:
#      - 202106
#      Platform:
#      - sn2
#    - GitHub:
#      - https://github.com/Azure/sonic-buildimage/issues/9811

# Errors which should be ignored in tests which doing reboot/reload
- Errors_list:
    - '.* ERR mlxfwmanager: LIBMVPD: MVPD_READ4 failed on offset:.*'
    - '.* ERR container: docker cmd: kill for .* failed .*'
    - '.* ERR pmon#thermalctld: Caught exception while running thermal policy .*'
    - '.* ERR (caclmgrd|hostcfgd).*: :- poll_descriptors: readData error: Unable to read redis reply.*'
    - '.* INFO hostcfgd.*:     raise ConnectionError.*'
    - '.* ERR systemd.*: kdump-tools.service: Ignoring invalid environment assignment .* /etc/default/kdump-tools.*'
    - '.* ERR hw-management: Path /var/run/hw-management/events/.* doesn''t exist'
    - '.* ERR dhclient.*send_packet: Network is unreachable.*'
    - '.* ERR dhclient.*send_packet: please consult README file regarding broadcast address.*'
    - '.* ERR dhclient.*Failed to send 300 byte long packet over .*'
    - '.* ERR dhclient.*No buffer space available.*'
    - '.* ERR syncd#SDK:.*Invalid port type.*'
    - '.* ERR syncd#SDK:.*mlnx_sai_utils.c.*Failed attribs dispatch.*'
    - '.* ERR syncd#SDK:.*mlnx_sai_bridge.c.*Unexpected bridge type.*'
    - '.* ERR syncd#SDK:.*mlnx_sai_utils.c.*Failed getting attrib.*'
    - '.* WARNING syncd#SDK:.*skipping since it causes crash:.*'
    - '.* ERR swss#orchagent:.*ASIC sensors : failed to get .*'
    - '.* ERR syncd#SDK:.*Unsupported debug counter type.*'
    - '.* ERR syncd#SDK:.*Invalid port counter.*'
    - '.* INFO systemd.*Start.*Kernel crash dump capture service.*'
    - '.* ERR syncd#SDK:.*mlnx_initialize_switch: Transaction mode should be enabled, enabling now.*'
    - '.* NOTICE syncd#SDK:.*Create trap.*'
    - '.* ERR neighbor_advertiser: EVERFLOW.* table does not exist.*'
    - '.* INFO systemd.*: Finished Kernel crash dump capture service.*'
    - '.* ERR syncd#SDK:.*\[SAI_BRIDGE.ERR\].*Isolation group is only supported for bridge port type port.*'
    - '.* ERR syncd#SDK:.*\[SAI_PORT.ERR\].*Port index not found in DB by log id.*'
    - '.* ERR teamd#teammgrd:.*/usr/bin/teamd -k -t.*'
    - '.* ERR caclmgrd.*: message repeated \d+ times: .*poll_descriptors: readData error: Unable to read redis reply.*'
    - '.* ERR syncd#SDK:.*\[SAI_PORT.ERR\].*mlnx_sai_port.c.*Not supported stats ID.*'
    - '.* ERR syncd#SDK:.*\[SX_API_BULK_COUNTER.ERR\].*Invalid value of port counter-groups bitmap.*'
    - '.* ERR syncd#SDK:.*\[SAI_PORT.ERR\].*mlnx_sai_port.c.* Failed to convert counter IDs to counter types bitmap.*'
    - '.* ERR syncd#SDK:.*\[SAI_PORT.ERR\].*mlnx_sai_port.c.* Failed to create buffer: Parameter Error.*'
    - '.* ERR syncd#SDK:.*\[SAI_PORT.ERR\].*mlnx_sai_port.c.* Failed to allocate SDK buffer.*'
    - '.* ERR swss#\w+syncd: :- readData: netlink reports .* on reading a netlink socket.*'
    - '.* ERR syncd#SDK:.*\[SX_API_INTERNAL.ERR\].*Failed command read at communication channel: Connection reset by peer.*'
    - '.* ERR hostcfgd:.*sudo systemctl (enable|disable).*failed. RC: 1.*'
    - '.* ERR hostcfgd:.*Feature.*failed to be\s+(enabled and started|stopped and disabled).*'
    - '.* ERR (swss#portsyncd|teamd#teamsyncd):.*netlink reports an error=-33 on reading a netlink socket.*'
    - '.* ERR systemd-udevd.*: could not read from ''\/sys\/module\/acpi_cpufreq\/initstate'': No such device.*'
    - '.* (ERR|WARNING) syncd#(SAI|SDK):.*Shared memory of the.*already exists,\s*destroying it and re-creating.*'
    - '.* ERR swss#orchagent:.*removeLag: Failed to remove (ref count \d+|non-empty) LAG PortChannel.*'
    - '.* ERR hostcfgd:.*error returned by select.*'
    - '.* ERR pmon#python3: :- .*Expected to get redis type \d+ got type \d+, err: NON-STRING-REPLY.*'
  Conditions:
    - Affected_test_cases:
      # Canonical
      - tests/nightly/app_extension/test_app_extension_reboot.py::test_app_start_delay_after_reboot
      - tests/nightly/auto_negotition/test_auto_neg.py::TestAutoNeg::test_auto_neg_conf
      - tests/nightly/copp/test_copp.py::test_copp_policer
      - tests/nightly/fdb/test_fdb_basic.py::TestFdbBasic::test_fdb_aging_time_expire
      - tests/nightly/fec/test_fec.py::TestFec::test_fec_capabilities_loopback_ports
      - tests/nightly/fec/test_fec.py::TestFec::test_fec_capabilities_hosts_ports
      - tests/nightly/fec/test_fec.py::TestFec::test_negative_fec
      - tests/nightly/fec/test_fec.py::TestFec::test_fec_bug_2705016
      - tests/nightly/p4/sampling_example/test_entry_scaling.py::TestEntryScaling::test_scaling_entries
      - tests/nightly/p4/sampling_example/test_entry_priority.py::test_entries_with_different_priority
      - tests/nightly/p4/sampling_example/test_entry_priority.py::test_entries_with_same_priority
      - tests/nightly/p4/sampling_example/test_entry_advance.py::TestEntryTraffic::test_enable_disable_p4_sampling
      - tests/nightly/p4/sampling_example/test_entry_advance.py::TestEntryTraffic::test_p4_sampling_traffic_concussive
      - tests/nightly/p4/examples_application/test_reboot/test_reboot.py::test_p4_examples_reboot
      - tests/nightly/lag/test_lag.py::test_core_functionality_with_reboot
      - tests/nightly/lag/test_lag.py::test_lag_min_links
      - tests/nightly/lag/test_lag.py::test_lag_members_scale
      - tests/nightly/lag/test_lag.py::test_lags_scale
      - tests/nightly/lag/test_lag.py::test_port_cannot_be_added_to_lag
      - tests/push_build_tests/general/qos/test_qos_reload.py::test_qos_reload_ports
      - tests/nightly/routing/test_routing.py::TestRouting::test_reboot
      # 2 tests below temporary added - they doing "config reload -y"
      - tests/push_build_tests/L3/dhcp_relay/test_dhcp6_relay.py::TestDHCP6Relay::test_dhcp6_relay_remove_dhcp_server
      - tests/push_build_tests/L3/dhcp_relay/test_dhcp6_relay.py::TestDHCP6Relay::test_dhcp6_relay_multiple_dhcp_servers
      # Community
      - pc/test_po_update.py::test_po_update_io_no_loss
      - vxlan/test_vnet_route_leak.py::test_vnet_route_leak
      - drop_packets/test_wjh.py::test_wjh_starts_after_config_reload
      - platform_tests/fwutil/test_fwutil.py::test_fwutil_install_file
      - platform_tests/fwutil/test_fwutil.py::test_fwutil_install_url
      - platform_tests/fwutil/test_fwutil.py::test_fwutil_update_current
      - platform_tests/fwutil/test_fwutil.py::test_fwutil_update_next
      - platform_tests/fwutil/test_fwutil.py::test_fwutil_auto
      - copp/test_copp.py::TestCOPP::test_add_new_trap
      - copp/test_copp.py::TestCOPP::test_remove_trap
      - copp/test_copp.py::TestCOPP::test_trap_config_save_after_reboot
      - vxlan/test_vnet_vxlan.py
      - ecmp/inner_hashing/test_wr_inner_hashing.py
      - dhcp_relay/test_dhcp_relay.py::test_interface_binding
      - autorestart/test_container_autorestart.py
      - iface_loopback_action/test_iface_loopback_action.py::test_loopback_action_reload
      # Ignore reboot related errors for test which checks errors after SONiC image deploy
      - tests/nightly/logging/test_log_analyzer_errors_during_deploy_sonic.py
      - system_health/test_system_health.py
      - qos/test_buffer.py::test_port_admin_down

# Errors which should be ignored in tests which restart dockers
- Errors_list:
    - '.*ERR kernel: .* mlxsw_minimal .*: Cmd exec timed-out \(opcode=\d+\(ACCESS_REG\),opcode_mod=\d,in_mod=\d\).*'
  Conditions:
    - Affected_test_cases:
      - autorestart/test_container_autorestart.py::test_containers_autorestart

# Vivek conclaimed these error logs are not bug(RM #3238130), he suggest adding them into common ignore list
- Errors_list:
    - '.*ERR dhclient\[\d+\]: Failed to get interface index: No such device.*'
    - '.*ERR dhclient\[\d+\]: If you think you have received this message due to a bug rather.*'
    - '.*ERR dhclient\[\d+\]: than a configuration issue please read the section on submitting.*'
    - '.*ERR dhclient\[\d+\]: bugs on either our web page at www.isc.org or in the README file.*'
    - '.*ERR dhclient\[\d+\]: before submitting a bug.  These pages explain the proper.*'
    - '.*ERR dhclient\[\d+\]: process and the information we find helpful for debugging.*'
    - '.*ERR dhclient\[\d+\]: exiting.*'
    - '.*ERR dhclient\[\d+\]: '
    # Sud confirmed this Err could be ignored in # 3293075
    # After issuing reboot command, if we get the above error log we can ignore them. Please note,
    # this can be observed for any service that was issued to be enable but reboot command was give.
    - '.*ERR hostcfgd: sudo systemctl start syncd.service - failed: return code - 1.*'
  Conditions:
    - Affected_test_cases:
      - tests/nightly/logging/test_log_analyzer_errors_during_deploy_sonic.py

# Temporary errors which should be ignored in tests which doing reboot/reload - by RM issue 3024792
- Errors_list:
    - '.* ERR lldp#lldpmgrd\[\d+\]: unknown operation.*'
  Conditions:
    - Affected_test_cases:
      # Canonical
      - tests/nightly/app_extension/test_app_extension_reboot.py::test_app_start_delay_after_reboot
      - tests/nightly/auto_negotition/test_auto_neg.py::TestAutoNeg::test_auto_neg_conf
      - tests/nightly/copp/test_copp.py::test_copp_policer
      - tests/nightly/fdb/test_fdb_basic.py::TestFdbBasic::test_fdb_aging_time_expire
      - tests/nightly/fec/test_fec.py::TestFec::test_fec_capabilities_loopback_ports
      - tests/nightly/fec/test_fec.py::TestFec::test_fec_capabilities_hosts_ports
      - tests/nightly/fec/test_fec.py::TestFec::test_negative_fec
      - tests/nightly/fec/test_fec.py::TestFec::test_fec_bug_2705016
      - tests/nightly/p4/sampling_example/test_entry_scaling.py::TestEntryScaling::test_scaling_entries
      - tests/nightly/p4/sampling_example/test_entry_priority.py::test_entries_with_different_priority
      - tests/nightly/p4/sampling_example/test_entry_priority.py::test_entries_with_same_priority
      - tests/nightly/p4/sampling_example/test_entry_advance.py::TestEntryTraffic::test_enable_disable_p4_sampling
      - tests/nightly/p4/sampling_example/test_entry_advance.py::TestEntryTraffic::test_p4_sampling_traffic_concussive
      - tests/nightly/p4/examples_application/test_reboot/test_reboot.py::test_p4_examples_reboot
      - tests/nightly/lag/test_lag.py::test_core_functionality_with_reboot
      - tests/nightly/lag/test_lag.py::test_lag_min_links
      - tests/nightly/lag/test_lag.py::test_lag_members_scale
      - tests/nightly/lag/test_lag.py::test_lags_scale
      - tests/nightly/lag/test_lag.py::test_port_cannot_be_added_to_lag
      - tests/push_build_tests/L3/dhcp_relay/test_dhcp6_relay.py::TestDHCP6Relay::test_dhcp6_relay_remove_dhcp_server
      - tests/push_build_tests/L3/dhcp_relay/test_dhcp6_relay.py::TestDHCP6Relay::test_dhcp6_relay_multiple_dhcp_servers
      # Community
      - pc/test_po_update.py::test_po_update_io_no_loss
      - vxlan/test_vnet_route_leak.py::test_vnet_route_leak
      - drop_packets/test_wjh.py::test_wjh_starts_after_config_reload
      - platform_tests/fwutil/test_fwutil.py::test_fwutil_install_file
      - platform_tests/fwutil/test_fwutil.py::test_fwutil_install_url
      - platform_tests/fwutil/test_fwutil.py::test_fwutil_update_current
      - platform_tests/fwutil/test_fwutil.py::test_fwutil_update_next
      - platform_tests/fwutil/test_fwutil.py::test_fwutil_auto
      - copp/test_copp.py::TestCOPP::test_add_new_trap
      - copp/test_copp.py::TestCOPP::test_remove_trap
      - copp/test_copp.py::TestCOPP::test_trap_config_save_after_reboot
      - sub_port_interfaces/test_show_subinterface.py
      - sub_port_interfaces/test_sub_port_interfaces.py
      - sub_port_interfaces/test_sub_port_l2_forwarding.py
      # Ignore reboot related errors for test which checks errors after SONiC image deploy
      - tests/nightly/logging/test_log_analyzer_errors_during_deploy_sonic.py
      Redmine:
      - 3024792
      Branch:
      - 202111
      - master
      - 202211

- Errors_list:
    - '.* ERR swss#orchagent: :- handlePortQosMapTable: Failed to apply QoS maps to port global\. Port is not found.*'
  Conditions:
    - Affected_test_cases:
      - tests/push_build_tests/general/qos/test_qos_reload.py::test_qos_reload_ports
      Redmine:
      - 3110830

- Errors_list:
    - '.* ERR sflow#port_index_mapper: no interface with this name'
  Conditions:
    - Affected_test_cases:
      - tests/push_build_tests/L2/vlan/test_vlan.py::TestVLAN::test_vlan_4094_5
      Redmine:
      - 3130084

- Errors_list:
    - '.* ERR pmon#chassis_db_init: Fail to decode DMI /sys/firmware/dmi/entries/2-0/raw due to FileNotFoundError\(2, ''No such file or directory''\)'
    - '.* ERR watchdogutil: Failed to get watchdog module'
    - '.* ERR kernel: \[\s+\d+\.\d+\] /dev/sda3: Can''t open blockdev'
    - '.* ERR healthd: Failed to read from file \/var\/run\/hw-management\/led\/led_status_capability - FileNotFoundError.*No such file or directory.*'
    - '.* ERR healthd: Failed to write.*file \/var\/run\/hw-management\/led\/led_status_green - FileNotFoundError.*No such file or directory.*'
    - '.* ERR show: Fail to decode DMI /sys/firmware/dmi/entries/2-0/raw due to FileNotFoundError\(2, .*No such file or directory.*\)'
  Conditions:
    - Platform:
      - simx

- Errors_list:
    - '.*ERR syncd#SDK: \[FLOW_COUNTER.ERR\] spectrum_flow_counter_get: spectrum_flow_counter_lock failed.*'
    - '.*ERR syncd#SDK: \[FLOW_COUNTER.ERR\] spectrum_flow_counter_lock: cm_lock failed.*'
    - '.*ERR syncd#SDK: \[GBIN_ALLOCATOR.ERR\] LID \d+ doesn''t exist!.*'
    - '.*ERR syncd#SDK: \[SAI_ACL.ERR\] mlnx_sai_acl.c\[\d+\]- mlnx_acl_counter_get:.* Failure to get counter in SDK.*'
    - '.*ERR syncd#SDK: \[SAI_UTILS.ERR\] mlnx_sai_utils.c\[\d+\]- .*Failed getting attrib SAI_ACL_COUNTER_ATTR_BYTES.*'

  Conditions:
    - Redmine:
      - 3285631
      Platform:
        - simx

- Errors_list:
    - '.* ERR syncd#SDK: \[COMP_LIB.ERR\] failed to rename file.*'
    - '.*ERR syncd#SDK: \[SX_API_DBG.ERR\].*dump .*failed.*'
  Conditions:
    - Redmine:
        - 3075643
      Platform:
        - simx

- Errors_list:
    - '.* ERR hostcfgd: sonic-kdump-config --disable - failed: return code - 1, output:#012None'
    - '.* ERR hostcfgd: sonic-kdump-config --memory 0M-2G:256M,2G-4G:320M,4G-8G:384M,8G-:448M - failed: return code - 1, output:#012None'
  Conditions:
    - Branch:
      - 202111

# Below ignores from temp_log_analyzer_ignores.txt in LAG folder
- Errors_list:
    - '.* ERR kernel: \[.*\] mlxsw_minimal 2-0048: Could not acquire lock'
    - '.* ERR kernel: \[.*\] mlxsw_minimal 2-0048: Failed to query PWM'
    - '.* ERR kernel: \[.*\] mlxsw_minimal 2-0048: Failed to write PWM'
    - '.* ERR pmon#syseepromd: Failed to load platform-specific eeprom from deprecated plugin.*'
    - '.* WARNING pmon#syseepromd: Failed to load platform-specific eeprom from sonic_platform package due to KeyError.*'
    - '.* ERR syncd#SDK: :- translateVidToRid: unable to get RID for VID oid:0x.*'
    - '.* ERR teamd#tlm_teamd: :- process_add_queue: Can''t connect to teamd after .* attempts.*'
    - '.* ERR syncd#SDK: :- updateSupportedBufferPoolCounters: BUFFER_POOL_WATERMARK_STAT_COUNTER: counter SAI_BUFFER_POOL_STAT_XOFF_ROOM_WATERMARK_BYTES is not supported on buffer pool .*, rv: SAI_STATUS_NOT_IMPLEMENTED'
    - '.* INFO kernel: .* teamd.*: segfault at b0 ip .* sp .* error 4 in libteam.*'
    - '.* ERR snmp#snmpd.*: ioctl \d+ returned -1.*'
    - '.* ERR pmon#sensord: Error getting sensor data: mlxsw.*: Kernel interface error.*'
  Conditions:
    - Affected_test_cases:
      - tests/nightly/lag/test_lag.py

- Errors_list:
    - '.* ERR teamd#tlm_teamd: :- get_dump: Can''t get dump for LAG ''PortChannel\d+''.*'
  Conditions:
    - Affected_test_cases:
      - tests/nightly/lag/test_lag.py
      Redmine:
      - 2934692

# From ngts/tests/nightly/arp/log_analyzer_ignores.txt
- Errors_list:
    - '.* ERR swss#orchagent.*Failed to remove ref count.*\d+.*LAG.*PortChannel.*'
  Conditions:
    - Affected_test_cases:
      - tests/nightly/arp/test_arp.py

# From ngts/tests/nightly/auto_negotition/negative_auto_neg_log_analyzer_ignores
- Errors_list:
    - '.* ERR syncd#SDK: \[SAI_PORT.ERR\] mlnx_sai_port.c\[.*\]- mlnx_port_speeds_merge: Port \[Speed\[.*\] configuration is invalid.*'
    - '.* ERR syncd#SDK: \[SAI_PORT.ERR\] mlnx_sai_port.c\[.*\]- mlnx_port_update_speed: Failed to merge speeds, interface types and auto_neg.*'
    - '.* ERR syncd#SDK: \[SAI_PORT.ERR\] mlnx_sai_port.c\[.*\]- mlnx_port_attr_set: Failed to update speed.*'
    - '.* ERR syncd#SDK: \[SAI_UTILS.ERR\] mlnx_sai_utils.c\[.*\]- sai_set_attribute: Failed set attrib dispatch.*'
    - '.* ERR syncd#SDK: :- sendApiResponse: api SAI_COMMON_API_SET failed in syncd mode: SAI_STATUS_INVALID_ATTR_VALUE_.*'
    - '.* ERR syncd#SDK: :- processQuadEvent: VID: oid:.* RID: oid:.*'
    - '.* ERR syncd#SDK: :- processQuadEvent: attr: SAI_PORT_ATTR_.*INTERFACE_TYPE:.*SAI_PORT_INTERFACE_TYPE_.*'
    - '.* ERR syncd#SDK: :- processQuadEvent: attr: SAI_PORT_ATTR_AUTO_NEG_MODE:.*'
    - '.* ERR swss#orchagent: :- set: set status: SAI_STATUS_INVALID_ATTR_VALUE_.*'
    - '.* ERR swss#orchagent: :- doPortTask: Failed to set port Ethernet\d+.*interface type to .*'
    - '.* ERR swss#orchagent: :- setPortAutoNeg: Failed to set AutoNeg \d+ to port pid:\d+.*'
    - '.* ERR swss#orchagent: :- handleSaiSetStatus: Encountered failure in set operation, exiting orchagent.*'
    - '.* ERR syncd#SDK: \[SAI_PORT.ERR\] mlnx_sai_port.c\[.*\]- mlnx_port_speeds_merge: Port \[.*\] configuration doesn''t match mask for \d+ lanes.*'
    - '.* ERR syncd#SDK: :- processQuadEvent: attr: SAI_PORT_ATTR_SPEED: \d+.*'
    - '.* ERR swss#orchagent: :- handleSaiSetStatus: Encountered SAI_STATUS_INVALID_ATTR_VALUE_0 in set operation.*'
    - '.* ERR swss#orchagent: :- doPortTask: Failed to set port Ethernet\d+ speed from \d+ to \d+.*'
    - '.* ERR syncd#SDK: \[SAI_PORT.ERR\] mlnx_sai_port.c\[\d+\]- mlnx_port_update_speed_sp2: Failed to set port .* rate - Parameter Error.'
    - '.* ERR syncd#SDK: \[SAI_PORT.ERR\] mlnx_sai_port.c\[\d+\]- mlnx_port_update_speed: Failed to apply speed/intf bitmap \[0x.*\] for port\[0x.*\].'
    - '.* ERR syncd#SDK: \[PORT.ERR\] Port rate given is not compatible with the capability rate of the switch.'
    - '.* ERR syncd#SDK: \[PORT.ERR\] Port rate capability validation failed \(Parameter Error\).'
    - '.* ERR syncd#SDK: \[PORT.ERR\] Specified admin rate value is invalid, rc = Parameter Error'
  Conditions:
    - Affected_test_cases:
      - tests/nightly/auto_negotition/test_auto_neg_negative.py::TestAutoNegNegative::test_negative_config_advertised_speeds
      - tests/nightly/auto_negotition/test_auto_neg_negative.py::TestAutoNegNegative::test_negative_config_advertised_types
      - tests/nightly/auto_negotition/test_auto_neg_negative.py::TestAutoNegNegative::test_negative_advertised_speed_type_mismatch
      - tests/nightly/auto_negotition/test_auto_neg.py::TestAutoNeg::test_auto_neg_toggle_peer_port
      - tests/nightly/fec/test_fec.py::TestFec::test_negative_fec
      - tests/nightly/fec/test_fec.py::TestFec::test_fec_capabilities_hosts_ports
      - tests/nightly/fec/test_fec.py::TestFec::test_fec_capabilities_loopback_ports

# From ngts/tests/nightly/fdb/log_analyzer_ignores.txt
- Errors_list:
    - '.* ERR swss#orchagent.*doAppSwitchTableTask.*Unsupported switch attribute ordered_ecmp.*'
    - '.* WARNING syncd#SDK:.*Not supported attribute SAI_TUNNEL_ATTR_DECAP_DSCP_MODE.*'
    - '.* WARNING syncd#SDK:.*sai_set_attribute: Failed attribs check, key:tunnel ID.*'
    - '.* ERR syncd#SDK.*sendApiResponse: api SAI_COMMON_API_SET failed in syncd mode: SAI_STATUS_ATTR_NOT_SUPPORTED.*'
    - '.* ERR syncd#SDK.*processQuadEvent.*VID.*oid.*RID.*oid.*'
    - '.* ERR syncd#SDK.*processQuadEvent.*attr.*SAI_TUNNEL_ATTR_DECAP_DSCP_MODE.*SAI_TUNNEL_DSCP_MODE_PIPE_MODEL.*'
    - '.* ERR swss#orchagent.*SAI_STATUS_ATTR_NOT_SUPPORTED.*'
    - '.* ERR swss#orchagent.*setTunnelAttribute.*Failed to set attribute dscp_mode with value pipe.*'
    - '.* ERR syncd#SDK.*updateSupportedBufferPoolCounters: BUFFER_POOL_WATERMARK_STAT_COUNTER: counter SAI_BUFFER_POOL_STAT_XOFF_ROOM_WATERMARK_BYTES is not supported on buffer pool oid:.*, rv: SAI_STATUS_NOT_IMPLEMENTED.*'
  Conditions:
    - Affected_test_cases:
      - tests/nightly/fdb/test_fdb_basic.py::TestFdbBasic::test_fdb_aging_time_expire

# Errors which should be ignored on SPC1 when install the p4-examples, p4-sampling, and enable them
- Errors_list:
    - '.*ERR p4.*examples: start.sh - unsupported DEVICE_TYPE=Spectrum.*'
    - '.*ERR p4.*sampling: start.sh - unsupported DEVICE_TYPE=Spectrum.*'
  Conditions:
    - Platform:
        sn2

# From ngts/tests/nightly/p4/sampling_example/p4_sampling_loganalyzer_ignore.txt
- Errors_list:
    - '.* ERR swss#orchagent: :- removeTunnelNextHop: Remove Tunnel next hop unable to find EVPN VTEP.*'
    - '.* ERR swss#orchagent: :- removeOverlayNextHops: Tunnel Nexthop .*delete failed.*'
    - '.* ERR syncd#SAI:.*\[SAI_SWITCH.ERR\].*mlnx_sai_switch.c.*Shared memory of the SAI already exists, destroying it and re-creating'
    - '.* WARNING syncd#SAI.*\[SAI_SWITCH.WARNING\].*mlnx_sai_switch.c.*sai_qos_db_create.*Shared memory of the SAI QOS already exists, destroying it and re-creating'
    - '.* WARNING syncd#SAI.*\[SAI_SWITCH.WARNING\].*mlnx_sai_switch.c.*sai_buffer_db_create.*Shared memory of the SAI buffer already exists, destroying it and re-creating'
    - '.* WARNING syncd#SAI.*\[SAI_SWITCH.WARNING\].*mlnx_sai_switch.c.*sai_acl_db_create.*Shared memory of the SAI ACL already exists, destroying it and re-creating'
    - '.* WARNING syncd#SAI.*\[SAI_SWITCH.WARNING\].*mlnx_sai_switch.c.*sai_tunnel_db_create.*Shared memory of the SAI TUNNEL already exists, destroying it and re-creating'
    - '.* WARNING syncd#SDK.*\[SXD_DPT.WARNING\].*sxd_dpt_init().*Shared memory of the DPT already exists,destroying it and re-creating'
  Conditions:
    - Affected_test_cases:
      - tests/nightly/p4/sampling_example/test_entry_advance.py::TestEntryTraffic::test_enable_disable_p4_sampling
      - tests/nightly/p4/sampling_example/test_entry_advance.py::TestEntryTraffic::test_p4_sampling_traffic_concussive
      - tests/nightly/p4/sampling_example/test_entry_priority.py::test_entries_with_different_priority
      - tests/nightly/p4/sampling_example/test_entry_priority.py::test_entries_with_same_priority
      - tests/nightly/p4/sampling_example/test_entry_scaling.py::TestEntryScaling::test_scaling_entries
# p4-sampling related err msg
- Errors_list:
    - '.* ERR syncd#SDK: \[SPAN.ERR\] SPAN module already initialized'
  Conditions:
    - Affected_test_cases:
      - tests/nightly/p4/sampling_example/test_entry_advance.py::TestEntryTraffic::test_enable_disable_p4_sampling
      - tests/nightly/p4/sampling_example/test_entry_advance.py::TestEntryTraffic::test_p4_sampling_traffic_concussive
      - tests/nightly/p4/sampling_example/test_entry_priority.py::test_entries_with_different_priority
      - tests/nightly/p4/sampling_example/test_entry_priority.py::test_entries_with_same_priority
      - tests/nightly/p4/sampling_example/test_entry_scaling.py::TestEntryScaling::test_scaling_entries
      # this err can also happen in test case doing "config reload -y" when p4-sampling is installed and enabled
      - tests/push_build_tests/L3/dhcp_relay/test_dhcp6_relay.py::TestDHCP6Relay::test_dhcp6_relay_remove_dhcp_server

- Errors_list:
    - '.* ERR swss#orchagent: :- removeLag: Failed to remove ref count.*\d+.*LAG PortChannel.*'
    - '.* ERR swss#orchagent: message repeated \d+ times: \[ :- removeLag: Failed to remove ref count \d+ LAG PortChannel\d+\]'
  Conditions:
    - Affected_test_cases:
      - tests/push_build_tests/L3/crm/test_crm.py::test_crm_route
      - tests/push_build_tests/L3/crm/test_crm.py::test_crm_neighbor_and_nexthop
      - tests/push_build_tests/L3/crm/test_crm.py::test_crm_nexthop_group_and_member
      - tests/push_build_tests/L3/crm/test_crm.py::test_crm_fdb_entry
      - tests/push_build_tests/L3/crm/test_crm.py::test_crm_acl
      - pc/test_po_update.py::test_po_update_io_no_los
      - vxlan/test_vnet_route_leak.py::test_vnet_route_leak
      - tests/push_build_tests/L3/dhcp_relay/test_dhcp6_relay.py
      - drop_packets/test_wjh.py::test_wjh_starts_after_config_reload
      - system_health/test_system_health.py
      Redmine:
      - 2615940

- Errors_list:
    - '.* ERR swss#orchagent: :- removeLag: Failed to remove non-empty LAG PortChannel.*'
  Conditions:
    - Affected_test_cases:
      - pc/test_po_update.py::test_po_update
      Redmine:
      - 2615940

- Errors_list:
    - '.* ERR bgp#bgpmon: \*ERROR\* Failed with rc:1 when execute: \[''vtysh'', ''-c'', ''show bgp summary json''\]'
    - '.* INFO bgp#supervisord .* INFO exited: bgpd \(terminated by SIGABRT \(core dumped\); not expected\)'
    - '.* INFO bgp#supervisor-proc-exit-listener: Process ''bgpd'' exited unexpectedly\. Terminating supervisor ''bgp'''
  Conditions:
    - Affected_test_cases:
      - tests/nightly/fec/test_fec.py::TestFec::test_fec_capabilities_loopback_ports
      Redmine:
      - 3339955
      Branch:
        - 202205
        - 202211

- Errors_list:
    - '.*ERR kernel:.*mlxsw_minimal .* Eeprom query failed.*'
  Conditions:
    - Affected_test_cases:
      - tests/nightly/show_techsupport/test_techsupport.py::test_techsupport_mellanox_sdk_dump
      - tests/nightly/app_extension/test_app_extension_basic.py::test_app_techsupport_integration
      - tests/nightly/app_extension/test_app_extension_reboot.py::test_app_start_delay_after_reboot
      - platform_tests/sfp/test_sfputil.py
      - platform_tests/fwutil/test_fwutil.py::test_fwutil_install_file
      - show_techsupport/test_techsupport.py::test_techsupport
      - show_techsupport/test_auto_techsupport.py
      - show_techsupport/test_techsupport_no_secret.py::test_secret_removed_from_show_techsupport
      - tests/push_build_tests/L3/dhcp_relay/test_dhcp6_relay.py::TestDHCP6Relay::test_dhcp6_relay_remove_dhcp_server
      Redmine:
        - 2915388

- Errors_list:
    - '.*WARNING syncd#SDK: \[HOST_INTERFACE\.WARNING\] Receive event of FW SOS.*'
  Conditions:
    - Affected_test_cases:
      - tests/nightly/show_techsupport/test_techsupport.py::test_techsupport_mellanox_sdk_dump

- Errors_list:
    - '.*ERR.*dhcp_relay#dhcrelay\[\d+\]:\sparse_option_buffer:\smalformed\soption\sdhcp6\.<unknown>\s\(code 29797\):\soption\slength\sexceeds\soption\sbuffer\slength\.'
    - '.*ERR.*dhcp_relay#dhcrelay\[\d+\]:\smessage\srepeated\s\d+\stimes:\s\[\sparse_option_buffer:\smalformed\soption\sdhcp6\.<unknown>\s\(code 29797\):\soption\slength\sexceeds\soption\sbuffer\slength\.'
  Conditions:
    - Affected_test_cases:
      - tests/push_build_tests/L3/dhcp_relay/test_dhcp6_relay.py::TestDHCP6Relay::test_dhcpv6_relay_client_request_with_malformed_payload

- Errors_list:
    - '.* ERR dhcp_relay#dhcp6relay: bind: Failed to bind to socket'
  Conditions:
    - Redmine:
      - 2954292
      Branch:
        - 202012
        - 202111
        - master
        - 202211

- Errors_list:
    - '.* ERR swss#fdbsyncd: :- readData: netlink reports an error=-25 on reading a netlink socket'
  Conditions:
    - Redmine:
      - 2606325
      Branch:
        - 202012

- Errors_list:
    - '.* WARNING syncd#SDK: :- discover: skipping since it causes crash: SAI_STP_ATTR_BRIDGE_ID'
  Conditions:
    - Affected_test_cases:
      - pc/test_po_update.py::test_po_update_io_no_loss
      - vxlan/test_vnet_route_leak.py::test_vnet_route_leak
      - ecmp/inner_hashing/test_wr_inner_hashing.py
      - autorestart/test_container_autorestart.py
      - copp/test_copp.py::TestCOPP::test_no_policer
      - copp/test_copp.py::TestCOPP::test_policer
      - route/test_static_route.py::test_static_route_ecmp
      - system_health/test_system_health.py
      - iface_loopback_action/test_iface_loopback_action.py::test_loopback_action_reload

- Errors_list:
    - '.* ERR syncd#SDK: \[SAI_DEBUG_COUNTER.ERR\] mlnx_sai_debug_counter.c\[\d+\]- mlnx_debug_counter_availability_get: Unsupported debug counter type - \d'
    - '.* ERR syncd#SDK: \[SAI_PORT.ERR\] mlnx_sai_port.c\[\d+\]- mlnx_get_port_stats_ext: Invalid port counter \d+'
    - '.* ERR syncd#SAI: \[SAI_SWITCH.ERR\] mlnx_sai_switch.c\[\d+\]- sai_db_create: mlnx_sai_switch.c\[\d+\]- sai_db_create: Shared memory of the SAI already exists, destroying it and re-creating'
    - '.* WARNING syncd#SAI: \[SAI_SWITCH.WARNING\] mlnx_sai_switch.c\[\d+\]- sai_qos_db_create: mlnx_sai_switch.c\[\d+\]- sai_qos_db_create: Shared memory of the SAI QOS already exists, destroying it and re-creating'
    - '.* WARNING syncd#SAI: \[SAI_SWITCH.WARNING\] mlnx_sai_switch.c\[\d+\]- sai_buffer_db_create: mlnx_sai_switch.c\[\d+\]- sai_buffer_db_create: Shared memory of the SAI buffer already exists, destroying it and re-creating'
    - '.* WARNING syncd#SAI: \[SAI_SWITCH.WARNING\] mlnx_sai_switch.c\[\d+\]- sai_acl_db_create: mlnx_sai_switch.c\[\d+\]- sai_acl_db_create: Shared memory of the SAI ACL already exists, destroying it and re-creating'
    - '.* WARNING syncd#SAI: \[SAI_SWITCH.WARNING\] mlnx_sai_switch.c\[\d+\]- sai_tunnel_db_create: mlnx_sai_switch.c\[\d+\]- sai_tunnel_db_create: Shared memory of the SAI TUNNEL already exists, destroying it and re-creating'
    - '.* WARNING syncd#SDK: \[SXD_DPT.WARNING\] sxd_dpt_init\(\): Shared memory of the DPT already exists,destroying it and re-creating'
  Conditions:
    - Affected_test_cases:
      - pc/test_po_update.py::test_po_update_io_no_loss
      - vxlan/test_vnet_route_leak.py::test_vnet_route_leak
      - system_health/test_system_health.py
      - autorestart/test_container_autorestart.py
      - dhcp_relay/test_dhcp_relay.py::test_interface_binding
      - copp/test_copp.py::TestCOPP::test_no_policer
      - copp/test_copp.py::TestCOPP::test_policer
      - route/test_static_route.py::test_static_route_ecmp
      Branch:
        - 202012

- Errors_list:
    - '.* ERR syncd#SDK: \[SAI_BRIDGE.ERR\] mlnx_sai_bridge.c\[\d+\]- mlnx_bridge_port_lag_or_port_get: Invalid port type - 2'
    - '.* ERR syncd#SDK: \[SAI_UTILS.ERR\] mlnx_sai_utils.c\[\d+\]- get_dispatch_attribs_handler: Failed getting attrib SAI_BRIDGE_PORT_ATTR_ISOLATION_GROUP'
    - '.* ERR syncd#SDK: \[SAI_UTILS.ERR\] mlnx_sai_utils.c\[\d+\]- get_dispatch_attribs_handler: Failed getting attrib SAI_BRIDGE_ATTR_UNKNOWN_UNICAST_FLOOD_GROUP'
    - '.* ERR syncd#SDK: \[SAI_UTILS.ERR\] mlnx_sai_utils.c\[\d+\]- get_dispatch_attribs_handler: Failed getting attrib SAI_BRIDGE_ATTR_UNKNOWN_MULTICAST_FLOOD_GROUP'
    - '.* ERR syncd#SDK: \[SAI_UTILS.ERR\] mlnx_sai_utils.c\[\d+\]- get_dispatch_attribs_handler: Failed getting attrib SAI_BRIDGE_ATTR_BROADCAST_FLOOD_GROUP'
    - '.* ERR syncd#SDK: \[SAI_UTILS.ERR\] mlnx_sai_utils.c\[\d+\]- get_dispatch_attribs_handler: Failed getting attrib SAI_BRIDGE_PORT_ATTR_PORT_ID'
    - '.* ERR syncd#SDK: \[SAI_UTILS.ERR\] mlnx_sai_utils.c\[\d+\]- sai_get_attributes: Failed attribs dispatch'
    - '.* ERR syncd#SDK: \[SAI_BRIDGE.ERR\] mlnx_sai_bridge.c\[\d+\]- mlnx_bridge_port_isolation_group_get: Isolation group is only supported for bridge port type port'
    - '.* ERR syncd#SDK: \[SAI_BRIDGE.ERR\] mlnx_sai_bridge.c\[\d+\]- mlnx_bridge_1d_oid_to_data: Unexpected bridge type 0 is not 1D'
  Conditions:
    - Redmine:
      - 2619129

- Errors_list:
    - '.*ERR lldp#lldp-syncd \[lldp_syncd\] ERROR: Could not infer system information from.*'
  Conditions:
    - Affected_test_cases:
      - autorestart/test_container_autorestart.py
      Redmine:
        - 3010810

- Errors_list:
    - '.*ERR teamd#teamsyncd: :- poll_descriptors: readData error: Unable to initialize team socket: Cannot assign requested address'
  Conditions:
    - Affected_test_cases:
      - autorestart/test_container_autorestart.py
      Redmine:
        - 3071644
      GitHub:
        - https://github.com/Azure/sonic-buildimage/issues/10867

- Errors_list:
    - '.* WARNING syncd#SDK: \[SAI_TUNNEL.WARNING\] mlnx_sai_tunnel.c\[\d+\]- mlnx_sdk_fill_tunnel_ttl_data: TTL uniform model is not supported for non-ipinip type on Spectrum 1, using default settings in switch'
  Conditions:
    - Redmine:
        - 2954740
      Branch:
        - 202111
        - master
        - 202211
      Platform:
        - x86_64-mlnx_msn2
        - x86_64-mlnx_msn2700-r0
        - x86_64-mlnx_msn2010-r0

- Errors_list:
    - '.* ERR syncd#SDK: \[SAI_BRIDGE.ERR\] mlnx_sai_bridge.c\[630\]- mlnx_bridge_port_sai_to_log_port_not_locked: Invalid bridge port type 4 - should be port or sub-port'
    - '.* ERR swss#orchagent: :- flushFDBEntries: Flushing FDB failed. rv:-5'
  Conditions:
    - Affected_test_cases:
      - vxlan/test_vxlan_decap.py::test_vxlan_decap[Removed]
      - vxlan/test_vnet_vxlan.py
      Redmine:
        - 2954778
      Branch:
        - 202111
        - master
        - 202211

- Errors_list:
    - '.* ERR teamd#tlm_teamd: :- get_dump: Can''t get dump for LAG ''PortChannel\d+''. Skipping'
  Conditions:
    - Affected_test_cases:
      - pc/test_po_update.py::test_po_update
      Redmine:
        - 2934692
      Branch:
        - 202111
        - master
        - 202211

- Errors_list:
    - '.*ERR teamd#tlm_teamd: :- process_add_queue:.*connect to teamd after 10 attempts. LAG.*'
  Conditions:
    - Affected_test_cases:
      - tests/sub_port_interfaces/test_sub_port_interfaces.py::TestSubPorts::test_admin_status_down_disables_forwarding[port_in_lag]
      Redmine:
        - 2910559
      Branch:
        - 202111

- Errors_list:
    - '.* teamd\[\d+\]: segfault at .* ip .* sp .* error 4 in libteam.so.5.6.0.*'
  Conditions:
    - Affected_test_cases:
      - tests/nightly/lag/test_lag.py
      Redmine:
        - 2910559
      Branch:
        - 202111
        - master
        - 202012
        - 202211

- Errors_list:
    - '.* ERR syncd#SDK: \[PORT_DB.ERR\] Failed to get SWID\(255\) type - Parameter Exceeds Range'
    - '.* ERR syncd#SDK: \[PORT.ERR\] SWID\(255\) type mismatch'
    - '.* ERR syncd#SDK: \[PORT.ERR\] SWID\(0\) type mismatch'
    - '.* ERR syncd#SDK: \[PORT.ERR\] Failed to retrieve counters values for prio \(\d\)'
    - '.* ERR syncd#SDK: \[PORT.ERR\] port_buff_cntr_get failed, for chip type CHIP_TYPE_SWITCH_SPECTRUM.*, err = Parameter Exceeds Range'
    - '.* ERR syncd#SDK: \[PORT.ERR\] port_tc_cntr_get failed, for chip type CHIP_TYPE_SWITCH_SPECTRUM.*, err = Parameter Exceeds Range'
    - '.* ERR syncd#SDK: \[SAI_BUFFER.ERR\] mlnx_sai_buffer.c\[\d+\]- mlnx_sai_get_ingress_priority_group_stats_ext: Failed to get port pg counters - Parameter Exceeds Range'
    - '.* ERR syncd#SDK: :- collectPriorityGroupCounters: PG_DROP_STAT_COUNTER: failed to get \d+/\d+ stats of PG 0x.*: -5'
    - '.* ERR syncd#SDK: \[PORT.ERR\] Failed to retrieve counters values for TC \(\d\)'
    - '.* ERR syncd#SDK: \[PORT.ERR\] port_tc_cntr_get failed, for chip type CHIP_TYPE_SPECTRUM.*, err = Parameter Exceeds Range'
    - '.* ERR syncd#SDK: \[PORT.ERR\] port_buff_cntr_get failed, for chip type CHIP_TYPE_SPECTRUM.*, err = Parameter Exceeds Range'
    - '.* ERR syncd#SDK: \[SAI_QUEUE.ERR\] mlnx_sai_queue.c\[\d+\]- mlnx_get_queue_statistics_ext: Failed to get port tc counters - Parameter Exceeds Range'
    - '.* ERR syncd#SDK: :- collectQueueCounters: QUEUE_STAT_COUNTER: failed to get stats of queue 0x.*: -5'
  Conditions:
    - Affected_test_cases:
      - tests/nightly/dynamic_port_breakout
      Redmine:
        - 2934289
      Branch:
        - 202111
        - master
        - 202211

- Errors_list:
    - '.* ERR memory_checker: \[memory_checker\] Failed to execute the command ''docker stats --no-stream --format \\{\\{.MemUsage\\}\\} .*''. Return code: ''1'''
  Conditions:
    - Affected_test_cases:
      - tests/nightly/fec/test_fec.py::TestFec::test_fec_bug_2705016
      - tests/nightly/fec/test_fec.py::TestFec::test_fec_capabilities_loopback_ports
      - tests/nightly/auto_negotition/test_auto_neg.py::TestAutoNeg::test_auto_neg_conf
      - tests/nightly/lag/test_lag.py::test_core_functionality_with_reboot
      Redmine:
        - 2966714
      Branch:
        - 202111
        - master
        - 202211

- Errors_list:
    - '.* ERR syncd#SDK: :- threadFunction: time span WD exceeded \d+ ms for create:SAI_OBJECT_TYPE_SWITCH:oid:0x.*'
    - '.* ERR syncd#SDK: :- logEventData: op: create, key: SAI_OBJECT_TYPE_SWITCH:oid:0x.*'
    - '.* ERR syncd#SDK: :- logEventData: fv: SAI_SWITCH_ATTR_FDB_EVENT_NOTIFY: 0x.*'
    - '.* ERR syncd#SDK: :- logEventData: fv: SAI_SWITCH_ATTR_PORT_STATE_CHANGE_NOTIFY: 0x.*'
    - '.* ERR syncd#SDK: :- logEventData: fv: SAI_SWITCH_ATTR_BFD_SESSION_STATE_CHANGE_NOTIFY: 0x.*'
    - '.* ERR syncd#SDK: :- logEventData: fv: SAI_SWITCH_ATTR_SWITCH_SHUTDOWN_REQUEST_NOTIFY: 0x.*'
    - '.* ERR syncd#SDK: :- setEndTime: event ''create:SAI_OBJECT_TYPE_SWITCH:oid:0x.*'' took \d+ ms to execute'
    - '.* ERR syncd#SDK: :- logEventData: fv: SAI_SWITCH_ATTR_INIT_SWITCH: true'
  Conditions:
    - Redmine:
      - 3172522
      Branch:
        - 202111
        - master
        - 202205
        - 202211

- Errors_list:
    - '.* ERR syncd#SDK: \[SAI_PORT.ERR\] mlnx_sai_port.c.*mlnx_get_port_stats_ext: Failed to wait for bulk counter read event.*'
    - '.* ERR syncd#SDK.*collectPortCounters: Failed to get stats of port*'
    - '.* ERR syncd#SDK: \[SAI_PORT.ERR\] mlnx_sai_port.c.* mlnx_port_stats_wait_for_bulk_read_event: Bulk read event status is not OK.*'
    - '.* ERR syncd#SDK: \[SAI_PORT.ERR\] mlnx_sai_port.c.*mlnx_port_stats_allocate_sx_bulk_buffer: Failed to create buffer: Driver.*Return Status is Non-Zero.*'
    - '.* ERR syncd#SDK: \[SAI_PORT.ERR\] mlnx_sai_port.c\[6757\]- mlnx_get_port_stats_ext: Failed to allocate SDK buffer.*'
    - '.* ERR swss#orchagent: :- wait: SELECT operation result: TIMEOUT on object_type_get_availability_response.*'
    - '.* ERR swss#orchagent: :- wait: failed to get response for object_type_get_availability_response.*'
    - '.* ERR swss#orchagent: :- on_switch_shutdown_request: Syncd stopped.*'
  Conditions:
    - Redmine:
      - 2942594
      Platform:
        - simx

- Errors_list:
    - '.* ERR syncd#SDK: \[SAI_PORT.ERR\] mlnx_sai_port.c\[\d+\]- mlnx_get_port_stats_ext: Failed to allocate SDK buffer.*'
  Conditions:
    - Redmine:
      - 3141564
      Platform:
        - simx

- Errors_list:
    - '.*ERR syncd#SDK: \[SAI_OBJECT.ERR\] mlnx_sai_object.c\[\d+\]- .* Bulk read event status is not OK.*'
    - '.*ERR syncd#SDK: \[SAI_PORT.ERR\] mlnx_sai_port.c\[\d+\]- .* Failed to prepare bulk counter for port stats.'
    - '.*ERR syncd#SDK.*collectPortCounters: Failed to get stats of port*'
  Conditions:
    - Redmine:
      - 3154876
      Platform:
        - simx

- Errors_list:
    - '.*ERR syncd#SDK: \[SAI_BUFFER.ERR\] mlnx_sai_buffer.c\[\d+\].*Failed to prepare bulk counter for pg occupancy stats.*'
    - '.*ERR syncd#SDK: \[SAI_QUEUE\.ERR\] mlnx_sai_queue.c\[\d*\]- .*Failed to prepare bulk counter for queue stats.'
  Conditions:
    - Redmine:
      - 3356398
      Platform:
        - simx

- Errors_list:
    - '.* ERR syncd#SDK: \[SAI_LAG.ERR\] mlnx_sai_lag.c\[\d+\]- mlnx_hostif_reapply: Failed running.*'
    - '.* ERR syncd#SDK: \[SAI_LAG.ERR\] mlnx_sai_lag.c\[\d+\]- mlnx_remove_lag_member: Error reapplying host interface on port.*'
    - '.* ERR syncd#SDK: :- sendApiResponse: api SAI_COMMON_API_REMOVE failed in syncd mode: SAI_STATUS_FAILURE.*'
    - '.* ERR swss#orchagent: :- remove: remove status: SAI_STATUS_FAILURE.*'
    - '.* ERR swss#orchagent: :- removeLagMember: Failed to remove member.* from .*'
    - '.* ERR swss#orchagent: :- handleSaiRemoveStatus: Encountered failure in remove operation, exiting orchagent.*'
  Conditions:
    - Redmine:
        - 3141585
      Platform:
        - simx

- Errors_list:
    - '.* ERR syncd#SDK: \[SAI_BUFFER.ERR] mlnx_sai_buffer.c\[\d+\]- .* Failed to find.*'
    - '.* ERR syncd#SDK: :- exit_with_sai_failure: saisdkdump exited with SAI rc:.* Failed to create a switch .'
  Conditions:
    - Redmine:
        - 3160523
      Platform:
        - simx

- Errors_list:
    - '.*ERR sflow#hsflowd: device .* Get SIOCGIFFLAGS failed : No such device'
  Conditions:
    - Redmine:
        - 3160535
      Platform:
        - simx

- Errors_list:
    - '.*ERR wjhcli: :- requestDaemon: Timeout waiting for daemon to send data'
  Conditions:
    - Redmine:
        - 3160544
      Platform:
        - simx

- Errors_list:
    - '.*ERR syncd#SDK: \[SX_API_INIT.ERR\] Could not open SX-API client communication channel.'
    - '.*ERR syncd#SDK: \[SAI_SWITCH.ERR\] mlnx_sai_switch.c\[\d+\]- mlnx_connect_switch: mlnx_sai_switch.c\[\d+\]- mlnx_connect_switch: .* Communication Error.'
  Conditions:
    - Redmine:
        - 3160591
      Platform:
        - simx

- Errors_list:
    - '.* ERR pmon#thermalctld: Failed to read from file /var/run/hw-management/led/led_fan\d_capability - FileNotFoundError\(2, ''No such file or directory''\)'
  Conditions:
    - Redmine:
      - 2972123
      Platform:
      - x86_64-nvidia_sn2201-r0

- Errors_list:
    - '.* ERR swss#vlanmgrd: :- main: Runtime error: \/bin\/bash -c .*'
  Conditions:
    - Affected_test_cases:
      - tests/nightly/lag/test_lag.py::test_core_functionality_with_reboot
      Redmine:
      - 3014357

- Errors_list:
    - '.*ERR sonic_yang: Data Loading Failed:Duplicated instance of "profile_list" leaf-list.*'
    - '.*ERR ConfigMgmt: Data Loading Failed.*Duplicated instance of "profile_list" leaf-list.*'
  Conditions:
    - Affected_test_cases:
      - dhcp_relay/test_dhcpv6_relay.py::test_dhcp_relay_after_link_flap
      Redmine:
      - 2972065

- Errors_list:
    - '.* ERR syncd#SDK: :- guard: RedisReply catches system_error: command:.*Lua redis.* command arguments must be strings or integers.*Input\/output error.*'
    - '.* ERR syncd#SDK: :- runRedisScript: Caught exception while running Redis lua script: RedisReply catches system_error: command:.*Lua redis.* command arguments must be strings or integers.*Input\/output error.*'
    - '.* ERR syncd#SDK: :- guard: RedisReply catches system_error: command: .*attempt to perform arithmetic on local .*in_octets.* \(a boolean value\).*Input\/output error.*'
    - '.* ERR syncd#SDK: :- runRedisScript: Caught exception while running Redis lua script: RedisReply catches system_error: command:.*attempt to perform arithmetic on local.*'
  Conditions:
    - Redmine:
      - 2972668
      Platform:
        - simx

- Errors_list:
    - '.* ERR kernel: \[.*\] mlxsw_minimal 2-0048: Could not acquire lock.*'
    - '.* ERR kernel: \[.*\] hwmon hwmon\d+: Failed to query module temperature.*'
    - '.* ERR kernel: \[.*\] mlxsw_minimal 2-0048: Failed to query temp sensor.*'
    - '.* ERR kernel: \[.*\] mlxsw_minimal 2-0048: Failed to query PWM.*'
    - '.* ERR kernel: \[.*\] mlxsw_minimal 2-0048: Failed to query fan.*'
    - '.* ERR pmon#thermalctld: Failed to read from file /run/hw-management/thermal/module.*_temp_fault - OSError.*'
  Conditions:
    - Redmine:
      - 2856406

- Errors_list:
    - '.* ERR syncd#SDK: \[SAI_PORT.ERR\] mlnx_sai_port.c\[\d+\]- mlnx_port_by_log_id: Failed lookup port config by log id.*'
    - '.* ERR syncd#SDK: \[SAI_QUEUE.ERR\] mlnx_sai_queue.c\[\d+\]- mlnx_queue_cfg_lookup: Filed to lookup queue by index \d+ on port log id.*'
    - '.* ERR syncd#SDK: :- collectQueueCounters: QUEUE_WATERMARK_STAT_COUNTER: failed to get stats of queue 0x.*: -9'
  Conditions:
    - Affected_test_cases:
      - tests/nightly/dynamic_port_breakout/test_dpb_speeds.py
      Redmine:
      - 2754703

- Errors_list:
    - '.* ERR swss#orchagent: message repeated \d+ times: .* :- removeLag: Failed to remove LAG PortChannel\d+, it is still in VLAN.*'
  Conditions:
    - Affected_test_cases:
      - tests/nightly/lag/test_lag.py
      Redmine:
      - 2825653

- Errors_list:
    - '.* ERR swss#orchagent: :- update: FdbOrch LEARN notification: Failed to locate vlan port from bv_id .*'
  Conditions:
    - Affected_test_cases:
      - tests/push_build_tests/L2/vlan/test_vlan.py::TestVLAN::test_vlan_trunk_mode
      - tests/push_build_tests/L2/vlan/test_vlan.py::TestVLAN::test_vlan_access_with_trunk_mode
      - tests/push_build_tests/general/wjh/test_wjh.py::test_l1_agg_drop
      - tests/push_build_tests/L2/vlan/test_vlan.py::TestVLAN::test_vlan_on_split_port
      - tests/nightly/lag/test_lag.py::test_core_functionality_with_reboot
      Redmine:
      - 3074216

- Errors_list:
    - '.* ERR swss#orchagent: :- update: FdbOrch MOVE notification: Failed to locate vlan port from bv_id .*'
  Conditions:
    - Affected_test_cases:
      - tests/push_build_tests/L2/vlan/test_vlan.py::TestVLAN::test_vlan_trunk_mode
      - tests/push_build_tests/L2/vlan/test_vlan.py::TestVLAN::test_vlan_access_with_trunk_mode
      - tests/push_build_tests/general/wjh/test_wjh.py::test_l1_agg_drop
      - tests/push_build_tests/L2/vlan/test_vlan.py::TestVLAN::test_vlan_on_split_port
      Redmine:
      - 3074230

- Errors_list:
    - '.* ERR swss#orchagent: :- update: Unsupported FDB Flush: .*'
  Conditions:
    - Affected_test_cases:
      - tests/push_build_tests/L2/vlan/test_vlan.py::TestVLAN::test_vlan_trunk_mode
      - tests/push_build_tests/L2/vlan/test_vlan.py::TestVLAN::test_vlan_access_with_trunk_mode
      - tests/push_build_tests/L2/vlan/test_vlan.py::TestVLAN::test_vlan_on_split_port
      - tests/push_build_tests/L2/vlan/test_vlan.py::TestVLAN::test_vlan_4094_5
      - tests/nightly/fdb/test_fdb_advance.py::TestFdbAdvance::test_fdb_item_be_removed_after_removing_corresponding_vlan
      Redmine:
      - 3074219

- Errors_list:
    - '.* ERR kernel.*Failed to query module temperature thresholds'
  Conditions:
    - Redmine:
        - 2915388

- Errors_list:
    - '.* WARNING syncd#SDK: \[SAI_SWITCH\.WARNING\] mlnx_sai_switch\.c\[\d+\]- event_thread_func: sx_api_host_ifc_recv on callback fd returned unknown port, waiting for next packet.*'
    - '.* WARNING syncd#SDK: message repeated \d+ times: \[ \[SAI_SWITCH\.WARNING\] mlnx_sai_switch\.c\[\d+\]- event_thread_func: sx_api_host_ifc_recv on callback fd returned unknown port, waiting for next packet\]'
  Conditions:
    - Redmine:
        - 3001584

- Errors_list:
    - '.* ERR syncd#SDK: \[SAI_UTILS.ERR\] mlnx_sai_utils.c\[\d+\]- mlnx_log_port_to_object: Failed to find log port \d+ in SAI DB'
  Conditions:
    - Affected_test_cases:
      - vxlan/test_vnet_vxlan.py
      Redmine:
      - 3001583
      Branch:
      - 202012

- Errors_list:
    - '.* ERR syncd#SDK: \[EMAD_RX_THREAD.ERR\] EMAD transaction FW error.*'
    - '.* ERR syncd#SDK: \[EMAD.ERR\] emad-send failed on register.*'
    - '.* ERR syncd#SDK: \[REG_BULK.ERR\] sx_reg_layer_sxd_reg_call - Error at access reg call reg_id.*'
    - '.* ERR syncd#SDK: \[REG_BULK.ERR\] __reg_bulk_post_completion_cb Error got in completion data sxd_status .*'
    - '.* ERR syncd#SDK: \[MGMT_LIB.ERR\] Slot .* Module .* Attr get, MCION GET failed.*'
  Conditions:
    - Affected_test_cases:
      - show_techsupport/test_techsupport.py
      - app_extension/test_app_extension_basic.py::test_app_techsupport_integration
      - tests/show_techsupport/test_auto_techsupport.py
      - tests/show_techsupport/test_techsupport_no_secret.py

- Errors_list:
    - '.* ERR dhclient\[\d+\]: send_packet: No such device or address'
    - '.* ERR dhclient\[\d+\]: dhclient\.c:\d+: Failed to send \d+ byte long packet over .* interface.*'
  Conditions:
    - Redmine:
      - 3006222
      Platform:
      - simx

- Errors_list:
    - '.* ERR dhclient\[\d+\]: receive_packet failed on .*: Network is down'
  Conditions:
    - Affected_test_cases:
      - tests/push_build_tests/L3/dhcp_relay/test_dhcp6_relay::test_dhcp6_relay_multiple_dhcp_servers
      - tests/push_build_tests/L3/dhcp_relay/test_dhcp6_relay::test_dhcp6_relay_remove_dhcp_server
      Platform:
        - simx

- Errors_list:
    - '.* ERR systemd\[\d+\]: Failed to start what-just-happened container'
  Conditions:
    - Affected_test_cases:
      - tests/push_build_tests/L3/static_route/test_static_route.py::test_basic_static_route
      - tests/push_build_tests/general/wjh/test_wjh.py
      - tests/push_build_tests/system/test_cpu_ram_hdd_usage.py
      - tests/push_build_tests/L3/dhcp_relay/test_dhcp_relay.py
      - tests/push_build_tests/L3/dhcp_relay/test_dhcp6_relay.py
      Redmine:
      - 3038334

- Errors_list:
    - ".* ERR bgp#bgpcfgd: Peer .*: Can't update the peer. Only 'admin_status' attribute is supported"
    - '.* ERR swss#intfmgrd: :- setIntfIp: Command .*\/sbin\/ip address "add" .* failed with rc 2'
    - '.* ERR swss#intfmgrd: :- setIntfIp: Command .*\/sbin\/ip -6 address "add" .* failed with rc 2'
    - '.* ERR syncd#SDK: \[SX_API_COS.ERR\] Port buffers configuration is not supported for LAG'
    - '.* ERR syncd#SDK: \[SAI_PORT.ERR\] mlnx_sai_port\.c\[\d+\]- mlnx_port_qos_map_.* Failed to get prio to buff qos map - Parameter Error'
    - '.* ERR syncd#SDK: \[SAI_QOS_MAPS.ERR\] mlnx_sai_qosmaps.c\[\d+\]- mlnx_qos_map_list_set: Failed to update port \d+ with new QoS map'
    - '.* ERR syncd#SDK: \[SAI_UTILS.ERR\] mlnx_sai_utils.c\[\d+\]- sai_set_attribute: Failed set attrib dispatch'
    - '.* ERR syncd#SDK: :- sendApiResponse: api SAI_COMMON_API_SET failed in syncd mode: SAI_STATUS_INVALID_PARAMETER'
    - '.* ERR syncd#SDK: :- processQuadEvent: VID: oid:.* RID: oid:.*'
    - '.* ERR syncd#SDK: :- processQuadEvent: attr: SAI_QOS_MAP_ATTR_MAP_TO_VALUE_LIST: .*'
    - '.* ERR swss#orchagent: :- modifyQosItem: Failed to modify map. status:.*'
    - '.* ERR swss#orchagent: :- processWorkItem: Failed to set \[.*_MAP:AZURE\]'
    - '.* ERR swss#orchagent: :- doTask: Failed to process QOS task, drop it'
  Conditions:
    - Affected_test_cases:
      - sub_port_interfaces/test_show_subinterface.py
      - sub_port_interfaces/test_sub_port_interfaces.py
      - sub_port_interfaces/test_sub_port_l2_forwarding.py
      Redmine:
      - 3050436
      Branch:
      - master
      - 202111
      - 202211

- Errors_list:
    - '.* ERR syncd#SDK: \[FDB_UC\.ERR\] FDB: not supported fid type \(\d+\) for fid \(\d+\)\. \(Success\)'
  Conditions:
    - Affected_test_cases:
      - sub_port_interfaces
      Redmine:
      - 3224978

- Errors_list:
    - '.* ERR swss#orchagent: message repeated \d+ times: \[ :- update: Failed to get port by bridge port ID 0x.*.\]'
  Conditions:
    - Affected_test_cases:
      - tests/nightly/lag/test_lag.py::test_core_functionality_with_reboot
      Redmine:
      - 3030960
      Branch:
      - 202012
      - 202111

- Errors_list:
    - '.* ERR wjhd: :- removeBufferConfiguration: Fail to deinit SDK telemetry, error: \[4\]: \[Communication Error\]'
    - '.* ERR wjhd\[\d+\]: \[WJH_LIB.ERROR\s+\].*'
    - '.* ERR wjhd\[\d+\]: :- deleteDropGroupReason:.*'
    - '.* ERR wjhd\[\d+\]: :- destroy: Failed to destroy channel.*'
    - '.* ERR wjhd\[\d+\]: :- deinitialize: Failed to de-initialize WJH library, status 1.*'

  Conditions:
    - Affected_test_cases:
      - autorestart/test_container_autorestart.py

- Errors_list:
    - '.*ERR wjhcli: :- connect: connect\(\) failed to connect to daemon: No such file or directory.*'
  Conditions:
    - Redmine:
        - 3044595

- Errors_list:
    - ".*Failed to add device '/dev/sda\\d*' to watch: Operation not permitted.*"
    - ".*Failed to add device '/dev/loop\\d*' to watch: Operation not permitted.*"
  Conditions:
    - Redmine:
        - 3044633

- Errors_list:
    - ".*ERR pmon#psud: sensor -s does not recover PSU threshold sensor after 5 seconds.*"
  Conditions:
    - Redmine:
        - 3042689

- Errors_list:
    - '.*ERR pmon#thermalctld: Failed to read from file /var/run/hw-management/thermal/psu1_fan_max - ValueError\("invalid literal for int\(\) with base 10:.*"\).*'
  Conditions:
    - Redmine:
        - 3045534

- Errors_list:
    - '.*ERR pmon#xcvrd.*: Expected to get redis type \d+ got type \d+, err: NON-STRING-REPLY.*'
  Conditions:
    - Redmine:
        - 3016938

- Errors_list:
    - '.*ERR healthd: Failed to read from file /var/run/hw-management/led/led_status_capability - FileNotFoundError.*'
  Conditions:
    - Redmine:
        - 3046455

- Errors_list:
    - '.* ERR pmon#xcvrd: Receive PMPE error event on module \d+: status 3 error type 1.*'
  Conditions:
    - Redmine:
      - 2976288

- Errors_list:
    - '.* ERR pmon#thermalctld: Failed to get minimum ambient temperature, use pessimistic instead.*'
  Conditions:
    - Affected_test_cases:
      - platform_tests/test_platform_info.py::test_show_platform_temperature_mocked
      Redmine:
      - 3058264

- Errors_list:
    - '.* ERR syncd#SDK:.*command \d+ not found in api_cmd_db.*'
  Conditions:
    - Affected_test_cases:
      - platform_tests/sfp/test_sfputil.py::test_check_sfputil_reset
      Redmine:
      - 3068928

- Errors_list:
    - '.*ERR kernel:.* mlx5_core .* mlx5e_get_module_info: cable type not recognized:.*'
    - '.*ERR kernel: .* mlx5_core .* mlx5_query_module_eeprom:.* Module ID not recognized:.*'
    - '.*ERR kernel: .* mlx5_core .* mlx5e_get_module_eeprom: mlx5_query_eeprom.*'
  Conditions:
    - Redmine:
      - 3084763
      Platform:
      - nvda_bf

- Errors_list:
    - '.*ERR kernel:.* mlx5_core .* mlx5_cmd_out_err:.* DESTROY_LAG.* failed, status bad system state.* syndrome.*'
    - '.*ERR kernel:.* mlx5_core.*mlx5_deactivate_lag.* Failed to deactivate VF LAG; driver restart required.*'
    - '.*ERR kernel:.* Make sure all VFs are unbound prior to VF LAG activation or deactivation.*'
  Conditions:
    - Affected_test_cases:
      - tests/nightly/routing/test_routing.py
      Redmine:
      - 3269038
      Platform:
      - nvda_bf

- Errors_list:
    - '.*ERR systemd-udevd.*: eth\d+: Failed to rename network interface \d+ from.*eth\d+.*to.*Ethernet\d+.*File exists.*'
  Conditions:
    - Affected_test_cases:
      - tests/nightly/routing/test_routing.py
      Redmine:
      - 3269050
      Platform:
      - nvda_bf

- Errors_list:
    - '.*ERR hostcfgd: sudo systemctl enable dhcp_relay.service - failed: return code - 1, output:.*'
    - '.*ERR swss#swssconfig: :- main: Exception caught: parse error - unexpected end of input.*'
    - '.*ERR syncd#syncd: :- threadFunction: time span WD exceeded \d+ ms for create:SAI_OBJECT_TYPE_SWITCH.*'
    - '.*ERR syncd#syncd: :- logEventData: op: create, key: SAI_OBJECT_TYPE_SWITCH:oid.*'
    - '.*ERR syncd#syncd: :- logEventData: fv: SAI_SWITCH_ATTR_INIT_SWITCH: true'
    - '.*ERR syncd#syncd: :- logEventData: fv: SAI_SWITCH_ATTR_PORT_STATE_CHANGE_NOTIFY.*'
    - '.*ERR syncd#syncd: :- logEventData: fv: SAI_SWITCH_ATTR_SWITCH_SHUTDOWN_REQUEST_NOTIFY.*'
    - '.*ERR syncd#syncd: :- logEventData: fv: SAI_SWITCH_ATTR_SRC_MAC_ADDRESS.*'
    - '.*ERR syncd#syncd: :- setEndTime: event .* took \d+ ms to execute'
  Conditions:
    - Affected_test_cases:
      - tests/nightly/routing/test_routing.py
      Redmine:
      - 3151802
      Platform:
      - nvda_bf

- Errors_list:
    - '.*INFO syncd#supervisord: syncd ERR rsai_lib_remote_call:\d+ remote_call\(api=\d+ method=\d+\) failed 0x.*'
    - '.*INFO syncd#supervisord: syncd ERR rsai_proxy_ioctl_invoke:\d+.*'
  Conditions:
    - Affected_test_cases:
      - tests/nightly/routing/test_routing.py
      Redmine:
      - 3259311
      Platform:
      - nvda_bf

- Errors_list:
    - '.*ERR syncd#syncd: :- processBulkOidCreate: bulkCreate api is not implemented or not supported, object_type = SAI_OBJECT_TYPE_NEXT_HOP_GROUP_MEMBER'
    - '.*ERR syncd#syncd: :- processBulkOidRemove: bulkRemove api is not implemented or not supported, object_type = SAI_OBJECT_TYPE_NEXT_HOP_GROUP_MEMBER'
  Conditions:
    - Affected_test_cases:
      - tests/nightly/routing/test_routing.py
      Redmine:
      - 3179551
      Platform:
      - nvda_bf

- Errors_list:
    - '.*ERR watchdogutil: Failed to get watchdog module'
  Conditions:
    - Affected_test_cases:
      - tests/nightly/routing/test_routing.py
      Redmine:
      - 3107695
      Platform:
      - nvda_bf

- Errors_list:
    - '.* ERR kernel:.*UBIFS error.*cannot initialize compressor zstd, error.*'
  Conditions:
    - Affected_test_cases:
      - tests/nightly/routing/test_routing.py
      Redmine:
      - 3190595
      Platform:
      - nvda_bf

- Errors_list:
    - '.* ERR hostcfgd: sonic-kdump-config --num_dumps.*'
    - '.* ERR dhclient\[\d+\]: receive_packet failed on.*'
    - '.* ERR dhclient\[\d+\]: dhclient.c:\d+: Failed to send.*'
    - '.* ERR dhclient\[\d+\]: send_packet.*: No such device*'
    - '.* ERR dhclient\[\d+\]: dhc\d+: send_packet\d+.*'
  Conditions:
    - Affected_test_cases:
      - tests/nightly/logging/test_log_analyzer_errors_during_deploy_sonic.py
      Redmine:
      - 3061632

- Errors_list:
    - '.*ERR systemd\[\d+\]: Failed to start Rotate log files.*'
  Conditions:
    - Affected_test_cases:
      - tests/nightly/logging/test_log_analyzer_errors_during_deploy_sonic.py
      Redmine:
      - 3320283

- Errors_list:
    - '.*ERR watchdogutil: Failed to get watchdog module.*'
  Conditions:
    - Affected_test_cases:
      - tests/nightly/logging/test_log_analyzer_errors_during_deploy_sonic.py
      Redmine:
      - 3273006

- Errors_list:
    - '.* INFO kernel: \[   \d+\.\d+\] orchagent\[\d+\]: segfault at 60 ip \S+ sp \S+ error 4 in libc-\d+.\d+.so\[\S+\+\S+\].*'
    - '.* ERR hostcfgd: sudo systemctl start pmon\.service - failed: return code - 1, output:#012None.*'
  Conditions:
    - Affected_test_cases:
      - tests/nightly/logging/test_log_analyzer_errors_during_deploy_sonic.py
      Redmine:
      - 3168487

- Errors_list:
    - '.* ERR .*rsyslogd: omfwd\/udp: socket 6: sendto\(\) error: Network is unreachable.*'
    - '.* ERR .*rsyslogd: omfwd: socket 6: error 101 sending via udp: Network is unreachable.*'
  Conditions:
    - Redmine:
      - 3168474

- Errors_list:
    - '.* ERR bgp#rsyslogd: imfile: error reading state file for .*'
  Conditions:
    - Affected_test_cases:
      - tests/nightly/lag/test_lag.py::test_core_functionality_with_reboot
      Redmine:
      - 3358387
      Platform:
      - simx

- Errors_list:
    - '.* ERR systemd\[\d\]: \/etc\/systemd\/system\/mst\.service:97: Invalid section header.*'
  Conditions:
    - Redmine:
      - 3168291

- Errors_list:
    - '.* ERR healthd: Container folder does not exist.*'
  Conditions:
    - Affected_test_cases:
      - tests/nightly/app_extension/test_app_extension_upgrade.py
      Redmine:
      - 3099493

- Errors_list:
    - '.*ERR lldp#lldpmgrd\[\d+\]: unknown operation.*'
    - '.*ERR syncd#SDK: \[SAI_PORT.ERR\] mlnx_sai_port.c\[\d+\]- mlnx_port_by_log_id: Failed lookup port config.*'
    - '.*ERR syncd#SDK: \[SAI_QUEUE.ERR\] mlnx_sai_queue.c\[\d+\]- mlnx_queue_cfg_lookup: Filed to lookup queue.*'
    - '.*ERR syncd#SDK: :- collectQueueCounters: QUEUE_WATERMARK_STAT_COUNTER: failed to get stats of queue.*'
  Conditions:
    - Affected_test_cases:
      - tests/nightly/dynamic_port_breakout/test_dpb_all_ports.py
      Redmine:
      - 3099410

- Errors_list:
    - '.*ERR swss#orchagent: :- mcCounterCheck: Invalid port oid.*'
    - '.*ERR swss#orchagent: :- pfcFrameCounterCheck: Invalid port oid.*'
  Conditions:
    - Affected_test_cases:
      - tests/nightly/dynamic_port_breakout/test_dpb_all_ports.py
      Redmine:
      - 3327983

- Errors_list:
    - '.*ERR syncd#SDK: :- setEndTime: event .?create:SAI_OBJECT_TYPE_SWITCH.*'
    - '.*ERR syncd#SDK: :- logEventData: op: create, key: SAI_OBJECT_TYPE_SWITCH.*'
    - '.*ERR syncd#SDK: :- logEventData: fv: SAI_SWITCH_ATTR_FDB_EVENT_NOTIFY.*'
    - '.*ERR syncd#SDK: :- logEventData: fv: SAI_SWITCH_ATTR_PORT_STATE_CHANGE_NOTIFY.*'
    - '.*ERR syncd#SDK: :- logEventData: fv: SAI_SWITCH_ATTR_SWITCH_SHUTDOWN_REQUEST_NOTIFY.*'
  Conditions:
    - Affected_test_cases:
      - tests/nightly/fec/test_fec.py
      Redmine:
      - 3061632

- Errors_list:
    - '.*ERR bgp#bgpcfgd: Directory: Can.?t remove key .?PortChannel.*'
    - '.*ERR bgp#bgpcfgd: Directory: Can.?t remove key .?Vlan.*'
  Conditions:
    - Affected_test_cases:
      - tests/nightly/lag/test_lag.py
      Redmine:
      - 3101252

- Errors_list:
    - '.* ERR pmon#xcvrd: Receive PMPE unknown event on module \d+: status 5'
    - '.* ERR pmon#xcvrd: message repeated \d+ times: \[ Receive PMPE unknown event on module \d+: status 5\]'
  Conditions:
    - Affected_test_cases:
      - tests/nightly/lag/test_lag.py::test_lag_members_scale
      - tests/nightly/lag/test_lag.py::test_lags_scale
      Redmine:
      - 3101770
      Platform:
      - sn2201

- Errors_list:
    - '.* ERR healthd: system_service''state'''
  Conditions:
    - Affected_test_cases:
      - tests/nightly/lag/test_lag.py::test_lags_scale
      - tests/push_build_tests/general/qos/test_qos_reload.py::test_qos_reload_ports
      Redmine:
      - 3102116

- Errors_list:
    - '.* WARNING kernel: \[.+\] get_operation_tlv: Err: Got status 0x4 for register 0x9053'
  Conditions:
    - Redmine:
      - 3105020

- Errors_list:
    - '.* WARNING kernel: \[.*\] get_operation_tlv: Err: Got status .* for register .*'
  Conditions:
    - Affected_test_cases:
      - tests/nightly/app_extension/test_app_extension_reboot.py::test_app_start_delay_after_reboot
      - tests/nightly/auto_negotition/test_auto_neg.py::TestAutoNeg::test_auto_neg_conf
      - tests/nightly/lag/test_lag.py::test_lag_members_scale
      - platform_tests/fwutil/test_fwutil.py::test_fwutil_install_file
      - platform_tests/fwutil/test_fwutil.py::test_fwutil_install_url
      Redmine:
      - 3110376
      Branch:
      - master
      - 202211

- Errors_list:
    - '.* ERR kernel.* PMBus status register not found'
    - '.* ERR kernel.* Chip identification failed'
    - '.* WARNING kernel.* probe of .* failed with error -22'
  Conditions:
    - Affected_test_cases:
      - platform_tests/fwutil/test_fwutil.py::test_fwutil_install_url
      Platform:
      - 4600c
      Reason: "when 4600c downgrade CPLD these errors are expected "

- Errors_list:
    - '.* ERR pmon#xcvrd: :- checkReplyType: Expected to get redis type \d+ got type \d+, err: NON-STRING-REPLY'
    - '.* ERR pmon#xcvrd: :- guard: RedisReply catches system_error: command: .*, reason: Expected to get redis type \d+ got type \d+, err: NON-STRING-REPLY: Input/output error'
  Conditions:
    - Affected_test_cases:
      - tests/nightly/lag/test_lag.py::test_lag_members_scale
      - tests/nightly/lag/test_lag.py::test_lags_scale
      Redmine:
      - 3120567
      Platform:
      - 2201

- Errors_list:
    - '.* ERR pmon#thermalctld: Failed to read from file /var/run/hw-management/thermal/fan\d_speed_get - OSError\(6, ''No such device or address''\)'
  Conditions:
    - Affected_test_cases:
      - show_techsupport/test_auto_techsupport.py::TestAutoTechSupport
      Redmine:
      - 3216785
      Branch:
      - 202205

- Errors_list:
    - ".* ERR ntpd\\[\\d+\\]: leapsecond file \\('/usr/share/zoneinfo/leap-seconds.list'\\): expired 1 day ago.*"
    - ".* ERR ntpd\\[\\d+\\]: leapsecond file \\('/usr/share/zoneinfo/leap-seconds.list'\\): expired less than \\d+ days ago.*"
  Conditions:
    - Affected_test_cases:
      - tests/nightly/logging/test_log_analyzer_errors_during_deploy_sonic.py::test_check_errors_in_log_during_deploy_sonic_image
      Redmine:
      - 3120607

- Errors_list:
    - '.* ERR show: Fail to decode DMI /sys/firmware/dmi/entries/2-0/raw due to PermissionError\(13, ''Permission denied''\)'
  Conditions:
    - Affected_test_cases:
      - tests/nightly/logging/test_log_analyzer_errors_during_deploy_sonic.py::test_check_errors_in_log_during_deploy_sonic_image
      Redmine:
      - 3120621
      Platform:
      - 2201

- Errors_list:
    - '.* ERR syncd#SDK: \[MGMT_LIB\.ERR\] Slot \[\d+\] Module \[\d+\] has logport \[.*\] in enabled state.*'
    - '.* ERR syncd#SDK: \[SDK_MGMT_LIB\.ERR\] Failed in __sdk_mgmt_phy_module_pwr_attr_set, error:.*'
    - '.* ERR pmon#-c: Error occurred when setting power mode for SFP module \d+, slot \d+, error code 1.*'
  Conditions:
    - Affected_test_cases:
      - platform_tests/sfp/test_sfputil.py::test_check_sfputil_low_power_mode
    - Redmine:
      - 3123080
      Branch:
      - master
      - 202211

- Errors_list:
    - '.* ERR syncd#SDK: :- translateVidToRid: unable to get RID for VID oid:0x.*'
  Conditions:
    - Redmine:
      - 3001563
      Branch:
      - master
      - 202111
      - 202205
      - 202211

# #3071827: Won't fix
- Errors_list:
    - '.* ERR radv#radvd\[\d+\]: Vlan1000 not found: No such device.*'
  Conditions:
    - Affected_test_cases:
      - autorestart/test_container_autorestart.py

- Errors_list:
    - '.* ERR pmon#psud: Fail to read model number: No key PN_VPD_FIELD in VPD /var/run/hw-management/eeprom/psu1_vpd.*'
    - '.* ERR pmon#psud: Fail to read serial number: No key SN_VPD_FIELD in VPD /var/run/hw-management/eeprom/psu1_vpd.*'
    - '.* ERR pmon#psud: Fail to read revision: No key REV_VPD_FIELD in VPD /var/run/hw-management/eeprom/psu1_vpd.*'
    - ".* ERR healthd: system_service'state' .*"
    - '.* ERR pmon#psud: Failed to read from file /var/run/hw-management/eeprom/psu1_vpd - UnicodeDecodeError.*'
  Conditions:
    - Redmine:
      - 3130554
      Platform:
      - msn2700

- Errors_list:
    - '.* ERR swss#orchagent: :- meta_sai_on_port_state_change_single: data.port_id oid.* has unexpected type: SAI_OBJECT_TYPE_NULL, expected PORT, BRIDGE_PORT or LAG.*'
    - '.* ERR swss#orchagent: :- handlePortStatusChangeNotification: Failed to get port object for port id.*'
    - '.* ERR swss#orchagent: :- doTask: Failed to get port object for port id.*'
  Conditions:
    - Redmine:
      - 3131583

# Below error should be ignored permanently for this test(issue: 3131511 related to 2200131 which is "Won't fix"
- Errors_list:
    - '.* ERR pmon#xcvrd: Receive PMPE error event on module \d+: status \d+ error type \d+.*'
    - '.* ERR pmon#xcvrd: Got unrecognized event \d+, ignored.*'
  Conditions:
    - Affected_test_cases:
      - platform_tests/sfp/test_sfputil.py

- Errors_list:
    - '.* ERR swss#orchagent: :- recordingFileReopen: failed to open recording file : No such file or directory.*'
  Conditions:
    - Redmine:
      - 3144113
    - Branch:
      - 202205

- Errors_list:
    - '.* WARNING kernel:.*get_operation_tlv: Err: Got status 0x4 for register 0x9029.*'
  Conditions:
    - Affected_test_cases:
      - show_techsupport/test_techsupport.py
      - show_techsupport/test_auto_techsupport.py
      - tests/nightly/app_extension/test_app_extension_basic.py::test_app_techsupport_integration
      - tests/nightly/show_techsupport/test_techsupport.py::test_techsupport_mellanox_sdk_dump
    - Redmine:
      - 3149713

- Errors_list:
    - '.* ERR syncd#SDK: \[SX_API_INTERNAL.ERR\] Failed command read at communication channel: Connection reset by peer.*'
    - '.* WARNING syncd#SDK: :- discover: skipping since it causes crash: SAI_STP_ATTR_BRIDGE_ID.*'
  Conditions:
    - Affected_test_cases:
      -  bgp/test_traffic_shift.py
    - Redmine:
      - 3067340

- Errors_list:
    - '.* ERR syncd#SDK: \[COMMAND_IFC.ERR\] sxd_open_device error: \[No such device or address\].*'
    - '.* ERR syncd#SDK: \[ACCESS_REG_INIT.ERR\] Failed initializing command ifc lib.*'
    - '.* ERR syncd#SDK: \[SAI_SWITCH.ERR\] mlnx_sai_switch.c.*- mlnx_resource_mng_stage: mlnx_sai_switch.c.*- mlnx_resource_mng_stage: Failed to init access reg - DEVICE OPEN ERROR.*'
    - '.* ERR syncd#SDK: :- onSwitchCreateInInitViewMode: failed to create switch in init view mode: SAI_STATUS_FAILURE.*'
    - '.* ERR syncd#SDK: :- run: Runtime error: :- onSwitchCreateInInitViewMode: failed to create switch in init view mode: SAI_STATUS_FAILURE.*'
    - '.* ERR swss#orchagent: :- wait: SELECT operation result: TIMEOUT on getresponse.*'
    - '.* ERR swss#orchagent: :- wait: failed to get response for getresponse.*'
    - '.* ERR swss#orchagent: :- create: create status: SAI_STATUS_FAILURE.*'
    - '.* ERR swss#orchagent: :- main: Failed to create a switch, rv:-1.*'
  Conditions:
    - Affected_test_cases:
      - tests/nightly/logging/test_log_analyzer_errors_during_deploy_sonic.py
      Redmine:
      - 3162498

- Errors_list:
    - '.* ERR syncd#SDK: :- guard: RedisReply catches system_error.*attempt to perform arithmetic on local.*in_octets.*\(a boolean value\).*'
    - '.* ERR syncd#SDK: :- runRedisScript: Caught exception while running Redis lua script: RedisReply catches system_error.*attempt to perform arithmetic on local.*in_octets.*\(a boolean value\).*'
    - '.* ERR syncd#SDK: :- guard: RedisReply catches system_error.*Lua redis\(\) command arguments must be strings or integers.*'
    - '.* ERR syncd#SDK: :- runRedisScript: Caught exception while running Redis lua script: RedisReply catches system_error.*Lua redis\(\) command arguments must be strings or integers.*'
  Conditions:
    - Redmine:
      - 3166325

- Errors_list:
    - '.* ERR hw-management: mlxreg_io is not loaded.*'
  Conditions:
    - Redmine:
      - 3177482

- Errors_list:
    - '.* ERR vnet_route_check.py:.*results.*missed_in_asic_db_routes.*Vnet.*'
    - '.* ERR vnet_route_check.py:  Vnet Route Mismatch reported.*'
  Conditions:
    - Affected_test_cases:
      - vxlan/test_vnet_route_leak.py
      Redmine:
      - 3165489

- Errors_list:
    - '.* ERR bgp#fpmsyncd: :- onRouteMsg: Invalid VRF name .*ifindex \d+.*'
  Conditions:
    - Affected_test_cases:
      - vxlan/test_vnet_route_leak.py
      Redmine:
      - 3221776

- Errors_list:
    - '.* ERR dhcp_relay#dhcp6relay: bind: Failed to bind socket to link local ipv6 address on interface Vlan1000 after 6 retries with Success.*'
  Conditions:
    - Affected_test_cases:
      - tests/nightly/logging/test_log_analyzer_errors_during_deploy_sonic.py
      Redmine:
      - 3136253

- Errors_list:
    - '.* ERR syncd#SDK: :- processSwitches: failed to create switch RID: SAI_STATUS_FAILURE.*'
    - '.* ERR syncd#SDK: :- run: Runtime error during syncd init: :- processSwitches: failed to create switch RID: SAI_STATUS_FAILURE.*'
    - '.* ERR syncd#SDK: \[SAI_SWITCH.ERR\] mlnx_sai_switch.c.*- mlnx_dvs_mng_stage: Failed running.*ip link set address.*dev swid0_eth > \/dev\/null 2\>&1.*'
    - '.* ERR kernel:.*sx_core: create EMAD sdq 0 failed. err: -16.*'
    - '.* ERR syncd#SDK: \[SAI_SWITCH.ERR\] mlnx_sai_switch.c.*- mlnx_resource_mng_stage: mlnx_sai_switch.c.*mlnx_resource_mng_stage: failed to set pci profile in asic, error: Device or resource busy.*'
    - '.* ERR syncd#SDK: :- sendApiResponse: api SAI_COMMON_API_CREATE failed in syncd mode: SAI_STATUS_FAILURE'
    - '.* ERR syncd#SDK: :- processQuadEvent: attr: SAI_SWITCH_ATTR_INIT_SWITCH: true.*'
    - '.* ERR syncd#SDK: :- processQuadEvent: attr: SAI_SWITCH_ATTR_FDB_EVENT_NOTIFY.*'
    - '.* ERR syncd#SDK: :- processQuadEvent: attr: SAI_SWITCH_ATTR_PORT_STATE_CHANGE_NOTIFY.*'
    - '.* ERR syncd#SDK: :- processQuadEvent: attr.*SAI_SWITCH_ATTR_SWITCH_SHUTDOWN_REQUEST_NOTIFY.*'
    - '.* ERR swss#orchagent: :- create: create status: SAI_STATUS_FAILURE.*'
    - '.* ERR swss#orchagent: :- main: Failed to create a switch, rv:-1.*'
  Conditions:
    - Affected_test_cases:
      - autorestart/test_container_autorestart.py::test_containers_autorestart
      Redmine:
      - 3116539

- Errors_list:
    - '.* ERR syncd#SAI: \[SAI_SWITCH.ERR\] mlnx_sai_switch.c.*- sai_db_create: mlnx_sai_switch.c.*- sai_db_create: Shared memory of the SAI already exists, destroying it and re-creating.*'
  Conditions:
    - Affected_test_cases:
      - bgp/test_traffic_shift.py
      Redmine:
      - 3144720

- Errors_list:
    - '.*sonic ERR hostcfgd: sonic-kdump-config --disable - failed: return code.*output:#.*None.*'
    - '.*sonic ERR hostcfgd: sonic-kdump-config --memory.*failed: return code.*, output:#.*None.*'
  Conditions:
    - Affected_test_cases:
      - tests/nightly/logging/test_log_analyzer_errors_during_deploy_sonic.py
      Redmine:
      - 2951102

- Errors_list:
    - ".*ERR mellanox_buffer_migrator: Trying to get DEVICE_METADATA from DB but doesn't exist, skip migration.*"
  Conditions:
    - Affected_test_cases:
      - tests/nightly/logging/test_log_analyzer_errors_during_deploy_sonic.py
      Redmine:
      - 3278707

- Errors_list:
    - '.* ERR sflow#port_index_mapper: \<built-in function Select_select\> returned a result with an error set'
  Conditions:
    - Affected_test_cases:
      - tests/push_build_tests/general/qos/test_qos_reload.py::test_qos_reload_ports
      Redmine:
      - 3172649

- Errors_list:
    - '.* ERR syncd#SDK: :- addObject: Queue Counter RID oid.*provide the statistic.*'
  Conditions:
    - Redmine:
      - 2876749
      Branch:
      - master
      - 202211

- Errors_list:
    - '.*ERR syncd#SDK: \[SAI_MIRROR.ERR\] mlnx_sai_mirror.c.*- mlnx_mirror_policer_sx_attrs_validate: Span policer must be SAI_POLICER_COLOR_SOURCE_BLIND.*'
    - '.*ERR syncd#SDK: :- sendApiResponse: api SAI_COMMON_API_CREATE failed in syncd mode:.*'
    - '.*ERR syncd#SDK: :- processQuadEvent: attr: SAI_MIRROR_SESSION_ATTR_MONITOR_PORT: oid:.*'
    - '.*ERR syncd#SDK: :- processQuadEvent: attr: SAI_MIRROR_SESSION_ATTR_TYPE: SAI_MIRROR_SESSION_TYPE_ENHANCED_REMOTE.*'
    - '.*ERR syncd#SDK: :- processQuadEvent: attr: SAI_MIRROR_SESSION_ATTR_ERSPAN_ENCAPSULATION_TYPE: SAI_ERSPAN_ENCAPSULATION_TYPE_MIRROR_L3_GRE_TUNNEL.*'
    - '.*ERR syncd#SDK: :- processQuadEvent: attr: SAI_MIRROR_SESSION_ATTR_IPHDR_VERSION.*'
    - '.*ERR syncd#SDK: :- processQuadEvent: attr: SAI_MIRROR_SESSION_ATTR_TOS:.*'
    - '.*ERR syncd#SDK: :- processQuadEvent: attr: SAI_MIRROR_SESSION_ATTR_TTL.*'
    - '.*ERR swss#orchagent: :- create: create status.*'
    - '.*ERR swss#orchagent: :- activateSession: Failed to activate mirroring session mirror_session_dscp.*'
    - '.*ERR swss#orchagent: :- handleSaiCreateStatus: Encountered failure in create operation, exiting orchagent, SAI API: SAI_API_MIRROR, status:.*'
    - '.*ERR syncd#SDK: :- processQuadEvent: attr: SAI_MIRROR_SESSION_ATTR_SRC_IP_ADDRESS.*'
    - '.*ERR syncd#SDK: :- processQuadEvent: attr: SAI_MIRROR_SESSION_ATTR_DST_IP_ADDRESS:.*'
    - '.*ERR syncd#SDK: :- processQuadEvent: attr: SAI_MIRROR_SESSION_ATTR_SRC_MAC_ADDRESS.*'
    - '.*ERR syncd#SDK: :- processQuadEvent: attr: SAI_MIRROR_SESSION_ATTR_DST_MAC_ADDRESS:.*'
    - '.*ERR syncd#SDK: :- processQuadEvent: attr: SAI_MIRROR_SESSION_ATTR_GRE_PROTOCOL_TYPE.*'
    - '.*ERR syncd#SDK: :- processQuadEvent: attr: SAI_MIRROR_SESSION_ATTR_POLICER: oid.*'
  Conditions:
    - Affected_test_cases:
      - generic_config_updater/test_monitor_config.py
      Redmine:
      - 3174870

- Errors_list:
    - ".* ERR teamd#tlm_teamd: :- process_add_queue: Can't connect to teamd after 10 attempts. LAG.*"
  Conditions:
    - Affected_test_cases:
      - iface_loopback_action
    - Redmine:
      - 3109165

- Errors_list:
    - ".* ERR swss#intfmgrd: :- main: Runtime error: \/sbin\/ip link set .*mtu.*"
  Conditions:
    - Affected_test_cases:
      - iface_loopback_action/test_iface_loopback_action.py::test_loopback_action_reload
    - Redmine:
      - 3259489

- Errors_list:
    - '.* ERR syncd#SDK: \[SX_API_INTERNAL\.ERR\] Invalid handle: handle is NULL'
    - '.* ERR syncd#SDK: \[SAI_SWITCH\.ERR\] mlnx_sai_switch\.c\[\d+\]- mlnx_switch_fdb_record_check_and_age: Failed to get port .+ learn mode - Invalid Handle'
  Conditions:
    - Affected_test_cases:
      - iface_loopback_action/test_iface_loopback_action.py::test_loopback_action_reload
      Redmine:
      - 3308748
      Branch:
      - 202205

- Errors_list:
    - ".* sai_db_create: Shared memory of the SAI already exists, destroying it and re-creating.*"
  Conditions:
    - Redmine:
      - 3144720


- Errors_list:
    - '.* WARNING kernel: .* probe of 5-006a failed with error -22.*'
  Conditions:
    - Affected_test_cases:
      - platform_tests/fwutil/test_fwutil.py::test_fwutil_install_file
    - Redmine:
      - 3278778

- Errors_list:
    - ".* ERR hostcfgd: sudo systemctl enable eventd.timer - failed: return code - 1, output:#.*None.*"
    - '.* ERR eventd#eventd: :- main: ERR:The eventd service started.*'
    - '.* ERR eventd#eventd: :- deserialize: deserialize Failed: input stream errorstr.*data type: std::__cxx11::basic_string<char, std::char_traits<char>, std::allocator<char> >&.*'
    - '.* ERR eventd#eventd: :- zmq_read_part: Failed to deserialize part rc=-2.*'
    - '.* ERR eventd#eventd: :- zmq_read_part: last:errno.*'
    - '.* ERR eventd#eventd: :- zmq_message_read: Failure to read part1 rc.*'
    - '.* ERR eventd#eventd: :- zmq_message_read: last:errno.*'
  Conditions:
    - Affected_test_cases:
      - tests/push_build_tests/general/qos/test_qos_reload.py
      - platform_tests/fwutil/test_fwutil.py::test_fwutil_install_url
      - platform_tests/fwutil/test_fwutil.py::test_fwutil_update_current
    - Redmine:
      - 3201740

- Errors_list:
    - '.* ERR syncd#SDK: \[SAI_UTILS.ERR\] mlnx_sai_utils.c.*- mlnx_object_to_type: Expected object SCHEDULER_GROUP got QUEUE.*'
    - '.* ERR swss#orchagent: :- getSchedulerGroup: Failed to get child list for scheduler group:.* of port:Ethernet.*'
    - '.* ERR swss#orchagent: :- applySchedulerToQueueSchedulerGroup: Failed to find a scheduler group for port: Ethernet.* queue:.*'
    - '.* ERR swss#orchagent: :- handleQueueTable: Failed setting field:scheduler to port:Ethernet.*, queue:\d+, line:.*'
    - '.* ERR swss#orchagent: :- doTask: Failed to process QOS task, drop it.*'
  Conditions:
    - Affected_test_cases:
      - tests/push_build_tests/general/qos/test_qos_reload.py
    - Redmine:
      - 3205239

- Errors_list:
    - '.* ERR syncd#SAI: \[SAI_OBJECT.ERR\] mlnx_sai_object.c\[\d+\]- sai_object_type_get_availability: Can''t get object type availability before creating a switch'
    - '.* ERR syncd#SAI: message repeated \d+ times: \[ \[SAI_OBJECT.ERR\] mlnx_sai_object.c\[\d+\]- sai_object_type_get_availability: Can''t get object type availability before creating a switch\]'
  Conditions:
    - Redmine:
        - 3358104
      Platform:
        - arm64-nvda_bf-mbf2h536c
        - arm64-nvda_bf-9009d3b600cvaa

- Errors_list:
    - '.* ERR syncd#SDK: :- collectData: Failed to get stats of Port Counter.*'
  Conditions:
    - Redmine:
        - 3205278
      Platform:
        - simx

- Errors_list:
    - '.* ERR pmon#xcvrd: Error! Unable to read data for \d+ port, page \d+ offset \d+, rc = 1, err msg: Sending access register.*'
  Conditions:
    - Redmine:
      - 3213401

- Errors_list:
    - '.* ERR swss#orchagent: :- removeVlan: Failed to remove ref count 1 VLAN.*'
  Conditions:
    - Affected_test_cases:
      - show_techsupport/test_auto_techsupport.py::TestAutoTechSupport::test_max_limit
      - show_techsupport/test_auto_techsupport.py::TestAutoTechSupport::test_rate_limit_interval
      - show_techsupport/test_auto_techsupport.py::TestAutoTechSupport::test_sanity
      Redmine:
      - 3214914

- Errors_list:
    - '.* ERR .*echo_receive: failing to read echo rc.*'
    - '.* ERR .*echo_receive: last:errno=.*'
  Conditions:
    - Redmine:
      - 3216736
      Branch:
      - master
      - 202211

- Errors_list:
    - '.* ERR syncd#SDK: \[BULK_COUNTER\.ERR\] BULK-CNTR ioctl failed \(cmd=\d+\) error Invalid argument.*'
    - '.* ERR syncd#SDK: \[BULK_COUNTER\.ERR\] BULK-CNTR transaction parameter is invalid.*'
    - '.* ERR syncd#SDK: \[BULK_COUNTER\.ERR\] Port-Counter-Transaction-Start: failed to start transaction in driver.*'
    - '.* ERR syncd#SDK: \[BULK_COUNTER\.ERR\] failed to start port counters bulk-read transaction.*'
    - '.* ERR kernel: \[.*\] Bulk-Counter DB add - invalid buffer_id.*'
  Conditions:
    - Affected_test_cases:
      - tests/nightly/routing/test_routing.py::TestRouting::test_reboot
      - tests/nightly/fec/test_fec.py::TestFec::test_fec_capabilities_loopback_ports
      Redmine:
      - 3216771
      Branch:
      - 202205

- Errors_list:
    - '.* ERR wjhcli: :- requestDaemon: Timeout waiting for daemon to send data.*'
    - '.* ERR wjhd: :- send: send\(\): failed to sent data to client: Broken pipe.*'
  Conditions:
    - Affected_test_cases:
      - tests/nightly/show_techsupport/test_techsupport.py::test_techsupport_mellanox_sdk_dump
      - tests/show_techsupport/test_auto_techsupport.py
      - tests/show_techsupport/test_techsupport_no_secret.py
      Redmine:
      - 3216781
      Branch:
      - 202205

- Errors_list:
    - ".*ERR bgp#bgpcfgd: Peer.*: Can't update the peer. Only 'admin_status' attribute is supported.*"
  Conditions:
    - Affected_test_cases:
      - bgp/test_bgp_bounce.py
      Redmine:
      - 3217740

- Errors_list:
    - ".*ERR swss#orchagent: :- set: switch id oid:0x0 doesn't exist.*"
    - '.*ERR swss#orchagent: :- updatePortOperStatus: Failed to set host interface  operational status down.*'
  Conditions:
    - Affected_test_cases:
      - tests/nightly/dynamic_port_breakout/test_dpb_all_ports.py
      Redmine:
      - 2872994

- Errors_list:
    - '.*WARNING kernel: .* NOHZ tick-stop error: Non-RCU local softirq work is pending, handler #08!!!*'
  Conditions:
    - Affected_test_cases:
      - tests/nightly/routing/test_routing.py::TestRouting::test_reboot
      Redmine:
      - 3230829
      Platform:
      - nvda_bf

- Errors_list:
    - '.*ERR kernel:.*mlxbf2_gpio MLNXBF.*IRQ index \d+ not found.*'
  Conditions:
    - Affected_test_cases:
      - tests/nightly/routing/test_routing.py::TestRouting::test_reboot
      Redmine:
      - 3280702
      Platform:
      - nvda_bf

- Errors_list:
    - '.*ERR dhclient.*: receive_packet failed on .*: Network is down.*'
    - '.*ERR dhclient.*: send_packet: No such device or address*'
    - '.*ERR dhclient.*: dhclient.c:.*: Failed to send \d+ byte long packet over .* interface.*'
    - '.*ERR dhclient\[\d+\]: send_packet6: No such device.*'
    - '.*ERR dhclient\[\d+\]: dhc6: send_packet6\(\) sent -.* of .* bytes.*'
  Conditions:
    - Affected_test_cases:
      - tests/nightly/logging/test_log_analyzer_errors_during_deploy_sonic.py
      Redmine:
      - 3114029

- Errors_list:
    - '.*INFO kernel.*dhcp6relay.*segfault at.*ip.*sp.*error.*in libswsscommon.*'
  Conditions:
    - Affected_test_cases:
      - tests/push_build_tests/L3/dhcp_relay/test_dhcp6_relay.py::TestDHCP6Relay::test_dhcp6_relay_remove_dhcp_server
      Redmine:
      - 3238357

- Errors_list:
    - '.* ERR syncd#SDK: :- setQueueCounterList: Queue RID oid:.* can''t provide the statistic'
    - '.* ERR syncd#SDK: :- addObject: Queue Counter RID oid:.* can''t provide the statistic'
  Conditions:
    - Redmine:
      - 2876749
      Platform:
        - simx

- Errors_list:
    - '.* ERR systemd\[\d+\]: Failed to start Update hostname based on configdb.'
  Conditions:
    - Redmine:
      - 3238754
      Platform:
        - simx

- Errors_list:
    - '.*ERR wjhd\[\d+\]: \[WJH_LIB.ERROR\s+\]: Failed to create a span session, err: Command Error.*'
    - '.*ERR wjhd\[\d+\]: \[WJH_LIB.ERROR\s+\]: Wjh lib dev specific cb span init failed, err.*'
    - '.*ERR wjhd\[\d+\]: \[WJH_LIB.ERROR\s+\]: Failed to set WJH span configuration, err.*'
    - '.*ERR wjhd\[\d+\]: \[WJH_LIB.ERROR\s+\]: Failed to initialize the WJH buffer drop mechanism, err.*'
    - '.*ERR wjhd\[\d+\]: \[WJH_LIB.ERROR\s+\]: wjh_drop_reason_group_init_cb failed, err.*'
    - '.*ERR wjhd\[\d+\]: :- setDropGroupReason: Failed to initialize drop reason group BUFFER for channel buffer, status.*'
    - '.*ERR wjhd\[\d+\]: :- initializeDefaultWjhChannels: Failed to initialize default channels.*'
    - '.*ERR wjhd\[\d+\]: :- main: exception: :- initializeDefaultWjhChannels: Failed to initialize default channels.*'
    - '.*ERR wjhd\[\d+\]: :- removeBufferConfiguration: Fail to deinit SDK telemetry, error: \[\d+\]: \[Invalid Handle\].*'
    - '.*ERR wjhd\[\d+\]: :- removeBufferConfiguration: Failed to close SDK handler, error: \[\d+\]: \[Invalid Handle\].*'
    - '.*ERR wjhd\[\d+\]: \[WJH_LIB.ERROR\s+\]: User channel \d+ is not destroyed, destroy it first.*'
    - '.*ERR wjhd\[\d+\]: \[WJH_LIB.ERROR\s+\]: wjh_db_deinit_resource_check failed, err.*'
    - '.*ERR wjhd\[\d+\]: :- deinitialize: Failed to de-initialize WJH library, status.*'
  Conditions:
    - Affected_test_cases:
      - tests/push_build_tests/general/qos/test_qos_reload.py::test_qos_reload_ports
      Redmine:
      - 3238763

# The below errors should be ignored, because it is caused by FW was busing(err is -16) , and it is an expected behaviour
- Errors_list:
    - '.*ERR kernel: \[.*\] Fails to get module type, err: -16.*'
    - '.*ERR pmon#xcvrd: Failed to read sfp=\d+ EEPROM.*page=\/sys\/module\/sx_core.*eeprom\/pages.*Device or resource busy.*'
    - '.*ERR pmon#xcvrd: message repeated \d+ times: \[ Failed to read sfp=\d+ EEPROM.*page=\/sys\/module\/sx_core.*eeprom\/pages.*Device or resource busy.*\]'
    - '.*ERR kernel: \[.*\] Fails to access .* register MCIA \(module:\d+, page:\d+, device_addr:\d+, size:\d+, i2c_addr:.*, slot:\d+, status:.*err: -16.*'
    - '.*ERR kernel: \[.*\] Fails to read module eeprom, status: -16.*'
    - '.*ERR kernel: \[.*\] Fails to access .* module eeprom, status: -16.*'
    - '.*ERR pmon#xcvrd: Failed to get SFP type, index=\d+, error=\[Errno \d+\] Device or resource busy'
  Conditions:
    - Affected_test_cases:
      - tests/nightly/show_techsupport/test_techsupport.py
      - tests/nightly/app_extension/test_app_extension_basic.py::test_app_techsupport_integration
      - show_techsupport/test_auto_techsupport.py
      - show_techsupport/test_techsupport_no_secret.py
      - show_techsupport/test_techsupport.py
      - tests/nightly/arp/test_arp.py::test_arp_gratuitous_without_arp_update
      - tests/nightly/fec/test_fec.py
      - tests/nightly/auto_negotition/test_auto_neg.py::TestAutoNeg::test_auto_neg_toggle_peer_port
      - tests/nightly/auto_negotition/test_auto_neg.py::TestAutoNeg::test_auto_neg_conf
      - tests/nightly/auto_negotition/test_auto_neg_negative.py::TestAutoNegNegative::test_negative_advertised_speed_type_mismatch

- Errors_list:
    - '.* ERR healthd: Get unit status .*''LoadState'''
    - '.* ERR healthd: system_service\[Errno \d+\] Connection reset by peer'
    - '.* ERR healthd: .*system_service\[Errno \d+\] Broken pipe.*'
  Conditions:
    - Affected_test_cases:
      - tests/nightly/lag/test_lag.py::test_core_functionality_with_reboot
      - tests/nightly/fec/test_fec.py
      - tests/nightly/auto_negotition/test_auto_neg.py::TestAutoNeg::test_auto_neg_conf
      - iface_loopback_action/test_iface_loopback_action.py::test_loopback_action_reload
      Redmine:
      - 3352372

- Errors_list:
    - '.* ERR swss#vxlanmgrd: :- doVxlanTunnelMapCreateTask: Map already present : vtep\d+:map_\d+_Vlan\d+'
    - '.* ERR swss#intfmgrd: :- setIntfIp: Command ''/sbin/ip address "add" ".*" broadcast ".*" dev ".*"'' failed with rc \d+'
    - '.* ERR swss#intfmgrd: :- setIntfIp: Command ''/sbin/ip -6 address "add" ".*" broadcast ".*" dev ".*"'' failed with rc \d+'
    - '.* ERR swss#intfmgrd: :- setIntfIp: Command ''/sbin/ip address "add" ".*" dev ".*"'' failed with rc \d+'
    - '.* ERR swss#orchagent: :- addOperation: Vxlan tunnel .* is already exists'
    - '.* ERR sflow#port_index_mapper: <built-in function Select_select> returned a result with an error set'
    - '.* WARNING syncd#SDK: :- discover: skipping since it causes crash: SAI_STP_ATTR_BRIDGE_ID'
    - '.* ERR swss#vxlanmgrd: :- doVxlanEvpnNvoCreateTask: Only Single NVO object allowed.*'
  Conditions:
    - Affected_test_cases:
      - tests/push_build_tests/general/doroce/test_doroce.py
      Redmine:
      - 3263991

- Errors_list:
    - '.* ERR kernel: \[.*\] Fails to access \(\d+\) module eeprom, status: -\d+.'
    - '.* ERR pmon#xcvrd: Failed to read sfp=\d+ EEPROM page=/sys/module/sx_core/asic\d+/module\d+/eeprom/pages/.*/data, page_offset=\d+,\s+size=\d+, offset=\d+, error = \[Errno \d+\] Input/output error'
    - '.* ERR pmon#xcvrd: message repeated \d+ times: \[ Failed to read sfp=\d+ EEPROM page=/sys/module/sx_core/asic\d+/module\d+/eeprom/pages/.*/data, page_offset=\d+,\s+size=\d+, offset=\d+, error = \[Errno \d+\] Input/output error\]'
  Conditions:
    - Affected_test_cases:
      - tests/nightly/show_techsupport/test_techsupport.py::test_techsupport_mellanox_sdk_dump
      - show_techsupport/test_auto_techsupport.py
      - show_techsupport/test_techsupport_no_secret.py
      - show_techsupport/test_techsupport.py::test_techsupport
      - platform_tests/sfp/test_sfputil.py::test_check_sfputil_reset
      - tests/nightly/app_extension/test_app_extension_basic.py::test_app_techsupport_integration
      Redmine:
      - 3263805
      Branch:
      - 202205
      - 202211

- Errors_list:
    - '.* ERR pmon#sensord: Error getting sensor data: emc\d+/#\d+: Can''t read'
  Conditions:
    - Affected_test_cases:
      - show_techsupport/test_auto_techsupport.py
      Redmine:
      - 3273940
      Branch:
      - 202205
      Platform:
      - 2201

- Errors_list:
    - '.* ERR hostcfgd: Hostname was not updated: Already set up'
  Conditions:
    - Redmine:
      - 3273797
      Branch:
      - 202211

- Errors_list:
    - '.*Bulk-Cntr PPCNT parser - unexpected local port.*'
  Conditions:
    - Affected_test_cases:
      - tests/push_build_tests/general/qos/test_qos_reload.py
      Redmine:
      - 3279709

- Errors_list:
    - '.*Failed to start Update logrotate configuration.*'
  Conditions:
    - Affected_test_cases:
      - platform_tests/fwutil/test_fwutil.py::test_fwutil_update_current
      Redmine:
      - 3289596

- Errors_list:
    - '.*ERR kernel.*Unknown EEPROM type.*'
  Conditions:
    - Affected_test_cases:
      - tests/show_techsupport/test_auto_techsupport.py::TestAutoTechSupport::test_max_limit
      - platform_tests/sfp/test_sfputil.py
      Redmine:
      - 3283464

- Errors_list:
    - ".*ERR lldp#lldpmgrd\\[\\d+\\]: Command failed 'lldpcli configure ports Ethernet\\d+ lldp portidsubtype local etp\\d+ .*unknown command from argument .*`configure`.*command was failed \\d+ times, disabling retry"
  Conditions:
    - Affected_test_cases:
      - tests/qos/test_qos_sai.py
      Redmine:
      - 3322141

- Errors_list:
    - '.*ERR syncd#SDK: \[SAI_DEBUG_COUNTER\.ERR\] mlnx_sai_debug_counter\.c\[\d+\]- mlnx_debug_counter_db_idx_to_data: Debug counter at index \d+ is removed or not created yet.*'
    - '.*ERR syncd#SDK: :- collectSwitchDebugCounters: Failed to get stats of port.*'
    - '.*ERR syncd#SDK: :- collectData: Failed to get stats of Switch Debug Counter.*'
  Conditions:
    - Affected_test_cases:
      - tests/drop_packets/test_configurable_drop_counters.py
      Redmine:
      - 3310078

- Errors_list:
    - '.*ERR swss#buffermgrd: :- isHeadroomResourceValid: Unable to update profile for port Ethernet\d+. Accumulative headroom size exceeds limit.*'
    - '.*ERR swss#buffermgrd: :- refreshPgsForPort: Update speed \(\d+\) and cable length .* for port Ethernet0 failed, accumulative headroom size exceeds the limit*'
    - '.*ERR swss#buffermgrd: :- doTask: Failed to process table update.*'
  Conditions:
    - Affected_test_cases:
      - platform_tests/test_auto_negotiation.py
      Redmine:
      - 3331335

# Errors which should be ignored in tests which doing reboot
- Errors_list:
    - '.* ERR healthd: system_service.*'
  Conditions:
    - Affected_test_cases:
      # Canonical
      - tests/nightly/app_extension/test_app_extension_reboot.py::test_app_start_delay_after_reboot
      - tests/nightly/auto_negotition/test_auto_neg.py::TestAutoNeg::test_auto_neg_conf
      - tests/nightly/copp/test_copp.py::test_copp_policer
      - tests/nightly/fdb/test_fdb_basic.py::TestFdbBasic::test_fdb_aging_time_expire
      - tests/nightly/fec/test_fec.py::TestFec::test_fec_capabilities_loopback_ports
      - tests/nightly/fec/test_fec.py::TestFec::test_fec_capabilities_hosts_ports
      - tests/nightly/fec/test_fec.py::TestFec::test_negative_fec
      - tests/nightly/fec/test_fec.py::TestFec::test_fec_bug_2705016
      - tests/nightly/p4/sampling_example/test_entry_scaling.py::TestEntryScaling::test_scaling_entries
      - tests/nightly/p4/sampling_example/test_entry_priority.py::test_entries_with_different_priority
      - tests/nightly/p4/sampling_example/test_entry_priority.py::test_entries_with_same_priority
      - tests/nightly/p4/sampling_example/test_entry_advance.py::TestEntryTraffic::test_enable_disable_p4_sampling
      - tests/nightly/p4/sampling_example/test_entry_advance.py::TestEntryTraffic::test_p4_sampling_traffic_concussive
      - tests/nightly/p4/examples_application/test_reboot/test_reboot.py::test_p4_examples_reboot
      - tests/nightly/lag/test_lag.py::test_core_functionality_with_reboot
      - tests/nightly/lag/test_lag.py::test_lag_min_links
      - tests/nightly/lag/test_lag.py::test_lag_members_scale
      - tests/nightly/lag/test_lag.py::test_lags_scale
      - tests/nightly/lag/test_lag.py::test_port_cannot_be_added_to_lag
      - tests/push_build_tests/general/qos/test_qos_reload.py::test_qos_reload_ports
      - tests/nightly/routing/test_routing.py::TestRouting::test_reboot
      # Community
      - pc/test_po_update.py::test_po_update_io_no_loss
      - vxlan/test_vnet_route_leak.py::test_vnet_route_leak
      - drop_packets/test_wjh.py::test_wjh_starts_after_config_reload
      - platform_tests/fwutil/test_fwutil.py::test_fwutil_install_file
      - platform_tests/fwutil/test_fwutil.py::test_fwutil_install_url
      - platform_tests/fwutil/test_fwutil.py::test_fwutil_update_current
      - platform_tests/fwutil/test_fwutil.py::test_fwutil_update_next
      - platform_tests/fwutil/test_fwutil.py::test_fwutil_auto
      - copp/test_copp.py::TestCOPP::test_add_new_trap
      - copp/test_copp.py::TestCOPP::test_remove_trap
      - copp/test_copp.py::TestCOPP::test_trap_config_save_after_reboot
      - vxlan/test_vnet_vxlan.py
      - ecmp/inner_hashing/test_wr_inner_hashing.py
      - dhcp_relay/test_dhcp_relay.py::test_interface_binding
      - autorestart/test_container_autorestart.py
      - iface_loopback_action/test_iface_loopback_action.py::test_loopback_action_reload
      # Ignore reboot related errors for test which checks errors after SONiC image deploy
      - tests/nightly/logging/test_log_analyzer_errors_during_deploy_sonic.py
      - system_health/test_system_health.py
      Redmine:
      - 3294192
      Branch:
      - 202205
      - 202211

- Errors_list:
    - '.* ERR python: :- initializeGlobalConfig: Sonic database config global file doesn.*t exist at /var/run/redis/sonic-db/database_global.json.*'
  Conditions:
    - Affected_test_cases:
      - tests/nightly/logging/test_log_analyzer_errors_during_deploy_sonic.py::test_check_errors_in_log_during_deploy_sonic_image
      - show_techsupport/test_auto_techsupport.py::TestAutoTechSupport::test_max_limit
      Redmine:
      - 3333068

- Errors_list:
    - '.* ERR decode-syseeprom: Nowhere to read syseeprom from! No symlink found.*'
  Conditions:
    - Redmine:
        - 3238754
      Platform:
        - 2700
        - 2410

- Errors_list:
    - '.* ERR kernel.* QAT: AE0 is inactive.*'
    - '.* ERR kernel.* QAT: failed to get device out of reset.*'
    - '.* ERR kernel.* qat_hal_clr_reset error.*'
    - '.* ERR kernel.* Failed to init the AEs.*'
    - '.* ERR kernel.* Failed to initialise Acceleration Engine.*'
    - '.* WARNING kernel.* probe of .* failed with error -14.*'
  Conditions:
    - Affected_test_cases:
      - tests/nightly/lag/test_lag.py::test_core_functionality_with_reboot
      Redmine:
        - 3333468
      Platform:
        - 2201

- Errors_list:
    - '.* ERR teamd#teammgrd: :- addLagMember: Failed to add Ethernet\d+ to port channel .*'
  Conditions:
    - Affected_test_cases:
      - tests/nightly/lag/test_lag.py
      Redmine:
        - 3137284

- Errors_list:
    - '.* ERR pmon#thermalctld: Failed to read from file /var/run/hw-management/thermal/fan1_speed_get - OSError.*'
  Conditions:
    - Affected_test_cases:
      - tests/nightly/show_techsupport/test_techsupport.py::test_techsupport_mellanox_sdk_dump
      - show_techsupport/test_auto_techsupport.py::TestAutoTechSupport::test_rate_limit_interval
      Redmine:
        - 3334337
      Platform:
        - 2201

- Errors_list:
    - '.* ERR swss#orchagent: :- doPortTask: Failed to set port Ethernet\d+ AN from 0 to 1.*'
  Conditions:
    - Affected_test_cases:
      - tests/nightly/fec/test_fec.py::TestFec::test_fec_capabilities_hosts_ports
      Redmine:
        - 3335880

- Errors_list:
    - '.* ERR syncd#SDK: \[SAI_INTERFACE_QUERY_ETH.ERR\] mlnx_sai_interfacequery_eth.c\[\d+\]- sai_dbg_generate_dump_ext: Failed to lock DFW semaphore - Connection timed out'
    - '.* ERR syncd#SDK: \[SX_API_DBG.ERR\] dump generation failed'
    - '.* ERR syncd#SDK: \[SX_API_DBG.ERR\] Cr space dump failed#\d+'
    - '.* ERR syncd#SDK: \[SX_API_DBG.ERR\] FW dump generation failed to move meta file to:\[/tmp/saisdkdump/sdkdump_ext_meta_.*\]'
    - '.* ERR syncd#SDK: \[COMP_LIB.ERR\] failed to rename file:\[/tmp/saisdkdump/.*.tmp\] to:\[/tmp/saisdkdump/.*\] code:\[2,No such file or directory\]'
    - '.* ERR syncd#SDK: \[SX_API_DBG.ERR\] FW dump generation failed to move CR file to:\[/tmp/saisdkdump/.*]'
  Conditions:
    - Affected_test_cases:
      - tests/push_build_tests/general/qos/test_qos_reload.py::test_qos_reload_ports
      - tests/nightly/app_extension/test_app_extension_basic.py::test_app_techsupport_integration
      - tests/nightly/evpn_vxlan/tech_support/test_evpn_vxlan_tech_support.py::TestEvpnVxlanTechSupport::test_tech_support
      Redmine:
        - 3272016

- Errors_list:
    - '.* ERR what-just-happened#wjhd: :- removeBufferConfiguration: Fail to deinit SDK telemetry, error: \[4\]: \[Communication Error\]'
    - '.* ERR what-just-happened#wjhd\[\d+\]: \[WJH_LIB.ERROR  \]: Failed to set trap ID \(\d+\) to trap group \(\d+\) with trap action \(\d+\), error: Communication Error'
    - '.* ERR what-just-happened#wjhd\[\d+\]: \[WJH_LIB.ERROR  \]: Failed to set traps.'
    - '.* ERR what-just-happened#wjhd\[\d+]: \[WJH_LIB.ERROR  \]: Failed to enable severity bits .* on drop reason group \d+'
    - '.* ERR what-just-happened#wjhd\[\d+\]: \[WJH_LIB.ERROR  \]: wjh_drop_reason_group_disable_cb failed, err = 1.'
    - '.* ERR what-just-happened#wjhd\[\d+\]: :- deleteDropGroupReason: Failed to disable drop group ACL on channel acl, status 1'
    - '.* ERR what-just-happened#wjhd\[\d+\]: \[WJH_LIB.ERROR  \]: Drop reason group \(\d+\) is bound to user channel \(id: \d+\), please unbind first.'
    - '.* ERR what-just-happened#wjhd\[\d+\]: :- destroy: Failed to destroy channel acl, status 1'
    - '.* ERR what-just-happened#wjhd\[\d+\]: \[WJH_LIB.ERROR  \]: Failed to get the current number of ports, err: Invalid Handle'
    - '.* ERR what-just-happened#wjhd\[\d+\]: \[WJH_LIB.ERROR  \]: Failed to bind all ports to the span session, err: 1'
    - '.* ERR what-just-happened#wjhd\[\d+\]: \[WJH_LIB.ERROR  \]: Failed to set drop reason bits .* on group \d+ to state 0.'
    - '.* ERR what-just-happened#wjhd\[\d+\]: \[WJH_LIB.ERROR  \]: Failed to enable drop reasons for drop group 0.'
    - '.* ERR what-just-happened#wjhd\[\d+\]: :- deleteDropGroupReason: Failed to disable drop group BUFFER on channel buffer, status 1'
    - '.* ERR what-just-happened#wjhd\[\d+\]: :- destroy: Failed to destroy channel buffer, status 1'
    - '.* ERR what-just-happened#wjhd\[\d+\]: \[WJH_LIB.ERROR  \]: Failed to set trap ID \(\d+\) to trap group \(\d+\) with trap action \(\d+\), error: Invalid Handle'
    - '.* ERR what-just-happened#wjhd\[\d+\]: :- deleteDropGroupReason: Failed to disable drop group L\d on channel forwarding, status 1'
    - '.* ERR what-just-happened#wjhd\[\d+\]: :- deleteDropGroupReason: Failed to disable drop group TUNNEL on channel forwarding, status 1'
    - '.* ERR what-just-happened#wjhd\[\d+]\: :- destroy: Failed to destroy channel forwarding, status 1'
    - '.* ERR what-just-happened#wjhd\[\d+\]: \[WJH_LIB.ERROR  \]: Failed to unbind policer \(\d+\) from trap group \(\d+\), error: Invalid Handle'
    - '.* ERR what-just-happened#wjhd\[\d+\]: \[WJH_LIB.ERROR  \]: wjh_user_channel_destroy_cb failed, err = 1.'
    - '.* ERR what-just-happened#wjhd\[\d+\]: \[WJH_LIB.ERROR  \]: __wjh_user_channel_destroy failed, err = 1'
    - '.* ERR what-just-happened#wjhd\[\d+\]: :- destroy: Failed to destroy channel layer-1, status 1'
    - '.* ERR what-just-happened#wjhd\[\d+\]: \[WJH_LIB.ERROR  \]: User channel \d+ is not destroyed, destroy it first.'
    - '.* ERR what-just-happened#wjhd\[\d+\]: \[WJH_LIB.ERROR  \]: wjh_db_deinit_resource_check failed, err = 1'
    - '.* ERR what-just-happened#wjhd\[\d+\]: :- deinitialize: Failed to de-initialize WJH library, status \d+.*'
    - '.* ERR what-just-happened#wjhd\[23\]: \[WJH_LIB.ERROR  \]: WJH libs are not initialized.*'
    - '.* ERR what-just-happened#wjhd\[\d+\]: :- removeBufferConfiguration: Failed to close SDK handler, error: \[\d+\]: \[Invalid Handle\].*'
    - '.* ERR what-just-happened#wjhd\[\d+\]: :- removeBufferConfiguration: Fail to deinit SDK telemetry, error: \[\d+\]: \[Invalid Handle\].*'
    - '.* ERR what-just-happened#wjhd\[\d+\]: :- main: exception: :- initialize: Failed to initialize WJH library .*'
    - '.* ERR what-just-happened#wjhd\[\d+\]: :- initialize: Failed to initialize WJH library .*'
    - '.* ERR syncd#SDK: \[SPAN.ERR\] __span_delete for span_session_id 0 failed, err: Resource is in use.*'
    - '.* ERR syncd#SDK: \[SPAN.ERR\] SPAN session \d+ still has policer ID \d+ bound, so can.* be destroyed.*'
    - '.* ERR what-just-happened#wjhd\[\d+\]: \[WJH_LIB.ERROR  \]: __wjh_resources_pre_init_clean_up failed, err = d+.*'
    - '.* ERR what-just-happened#wjhd\[\d+\]: \[WJH_LIB.ERROR  \]: Failed to disable monitor on buffer drop reason group.*'
    - '.* ERR what-just-happened#wjhd\[\d+\]: \[WJH_LIB.ERROR  \]: wjh buffer cleanup failed to destroy WJH span configuration, err: \d+.*'
    - '.* ERR what-just-happened#wjhd\[\d+\]: \[WJH_LIB.ERROR  \]: Wjh lib dev specific cb span deinit failed, err=\d+.*'
    - '.* ERR what-just-happened#wjhd\[\d+\]: \[WJH_LIB.ERROR  \]: Failed to destroy the span session, err: Resource is in use.*'
    - '.* ERR what-just-happened#wjhd\[\d+\]: \[WJH_LIB.ERROR  \]: wjh buffer cleanup failed to destroy the ACL configuration, err: \d+.*'
    - '.* ERR what-just-happened#wjhd\[\d+\]: \[WJH_LIB.ERROR  \]: Wjh lib dev specific cb for acl create failed, err=\d.*'
    - '.* ERR what-just-happened#wjhd\[\d+\]: \[WJH_LIB.ERROR  \]: Failed to unbind ACL group to the analyzer port, err:.*'
    - '.* ERR syncd#SDK: \[ACL.ERR\] ACL : Error at check access for group id\[\d+\].*'
    - '.* ERR syncd#SDK: \[ACL.ERR\] ACL : Failed to get ACL \(or ACL group entry type\), ACL id\[\d+\].*'
    - '.* ERR syncd#SDK: \[ACL.ERR\] Get acl \[\d+\].*'
    - '.* ERR syncd#SDK: \[ACL.ERR\] Trying to get a non-allocated table id \[\d+\].*'
    - '.* ERR syncd#SDK: \[ACL.ERR\] ACL: ACL group access denied, entry type is not FLEX_ACL_ENTRY_TYPE_USER_E..*'
  Conditions:
    - Affected_test_cases:
      - autorestart/test_container_autorestart.py::test_containers_autorestart
      Redmine:
        - 3315995

- Errors_list:
    - '.* ERR lldp#lldp-syncd \[lldp_syncd\] ERROR: Failed to parse LLDPd JSON.*does not match format ''%H:%M:%S'''
  Conditions:
    - Platform:
      - arm64-nvda_bf-mbf2h536c
      - arm64-nvda_bf-9009d3b600cvaa
      Redmine:
      - 3346254

# Errors which should be ignored in tests which doing reboot/reload
- Errors_list:
    - '.* ERR watchdogutil: Failed to get watchdog module'
  Conditions:
    - Affected_test_cases:
      # Canonical
      - tests/nightly/app_extension/test_app_extension_reboot.py::test_app_start_delay_after_reboot
      - tests/nightly/auto_negotition/test_auto_neg.py::TestAutoNeg::test_auto_neg_conf
      - tests/nightly/copp/test_copp.py::test_copp_policer
      - tests/nightly/fdb/test_fdb_basic.py::TestFdbBasic::test_fdb_aging_time_expire
      - tests/nightly/fec/test_fec.py::TestFec::test_fec_capabilities_loopback_ports
      - tests/nightly/fec/test_fec.py::TestFec::test_fec_capabilities_hosts_ports
      - tests/nightly/fec/test_fec.py::TestFec::test_negative_fec
      - tests/nightly/fec/test_fec.py::TestFec::test_fec_bug_2705016
      - tests/nightly/p4/sampling_example/test_entry_scaling.py::TestEntryScaling::test_scaling_entries
      - tests/nightly/p4/sampling_example/test_entry_priority.py::test_entries_with_different_priority
      - tests/nightly/p4/sampling_example/test_entry_priority.py::test_entries_with_same_priority
      - tests/nightly/p4/sampling_example/test_entry_advance.py::TestEntryTraffic::test_enable_disable_p4_sampling
      - tests/nightly/p4/sampling_example/test_entry_advance.py::TestEntryTraffic::test_p4_sampling_traffic_concussive
      - tests/nightly/p4/examples_application/test_reboot/test_reboot.py::test_p4_examples_reboot
      - tests/nightly/lag/test_lag.py::test_core_functionality_with_reboot
      - tests/nightly/lag/test_lag.py::test_lag_min_links
      - tests/nightly/lag/test_lag.py::test_lag_members_scale
      - tests/nightly/lag/test_lag.py::test_lags_scale
      - tests/nightly/lag/test_lag.py::test_port_cannot_be_added_to_lag
      - tests/push_build_tests/general/qos/test_qos_reload.py::test_qos_reload_ports
      - tests/nightly/routing/test_routing.py::TestRouting::test_reboot
      - tests/push_build_tests/system/test_startup_time_degradation.py::TestStartupTime::test_startup_time_degradation
      # 2 tests below temporary added - they doing "config reload -y"
      - tests/push_build_tests/L3/dhcp_relay/test_dhcp6_relay.py::TestDHCP6Relay::test_dhcp6_relay_remove_dhcp_server
      - tests/push_build_tests/L3/dhcp_relay/test_dhcp6_relay.py::TestDHCP6Relay::test_dhcp6_relay_multiple_dhcp_servers
      # Community
      - pc/test_po_update.py::test_po_update_io_no_loss
      - vxlan/test_vnet_route_leak.py::test_vnet_route_leak
      - drop_packets/test_wjh.py::test_wjh_starts_after_config_reload
      - platform_tests/fwutil/test_fwutil.py::test_fwutil_install_file
      - platform_tests/fwutil/test_fwutil.py::test_fwutil_install_url
      - platform_tests/fwutil/test_fwutil.py::test_fwutil_update_current
      - platform_tests/fwutil/test_fwutil.py::test_fwutil_update_next
      - platform_tests/fwutil/test_fwutil.py::test_fwutil_auto
      - copp/test_copp.py::TestCOPP::test_add_new_trap
      - copp/test_copp.py::TestCOPP::test_remove_trap
      - copp/test_copp.py::TestCOPP::test_trap_config_save_after_reboot
      - vxlan/test_vnet_vxlan.py
      - ecmp/inner_hashing/test_wr_inner_hashing.py
      - dhcp_relay/test_dhcp_relay.py::test_interface_binding
      - autorestart/test_container_autorestart.py
      - iface_loopback_action/test_iface_loopback_action.py::test_loopback_action_reload
      # Ignore reboot related errors for test which checks errors after SONiC image deploy
      - tests/nightly/logging/test_log_analyzer_errors_during_deploy_sonic.py
      - system_health/test_system_health.py
      - qos/test_buffer.py::test_port_admin_down
      Redmine:
      - 3273006

# Errors which should be ignored in tests which doing warm-reboot
- Errors_list:
    - '.* ERR syncd#SDK: \[DBG\.ERR\] Fatal failure not allowed when BOOT_MODE_ISSU_STARTED'
  Conditions:
    - Affected_test_cases:
      # Canonical
      - tests/nightly/app_extension/test_app_extension_reboot.py::test_app_start_delay_after_reboot
      - tests/nightly/auto_negotition/test_auto_neg.py::TestAutoNeg::test_auto_neg_conf
      - tests/nightly/copp/test_copp.py::test_copp_policer
      - tests/nightly/fdb/test_fdb_basic.py::TestFdbBasic::test_fdb_aging_time_expire
      - tests/nightly/fec/test_fec.py::TestFec::test_fec_capabilities_loopback_ports
      - tests/nightly/fec/test_fec.py::TestFec::test_fec_capabilities_hosts_ports
      - tests/nightly/fec/test_fec.py::TestFec::test_negative_fec
      - tests/nightly/fec/test_fec.py::TestFec::test_fec_bug_2705016
      - tests/nightly/p4/sampling_example/test_entry_scaling.py::TestEntryScaling::test_scaling_entries
      - tests/nightly/p4/sampling_example/test_entry_priority.py::test_entries_with_different_priority
      - tests/nightly/p4/sampling_example/test_entry_priority.py::test_entries_with_same_priority
      - tests/nightly/p4/sampling_example/test_entry_advance.py::TestEntryTraffic::test_enable_disable_p4_sampling
      - tests/nightly/p4/sampling_example/test_entry_advance.py::TestEntryTraffic::test_p4_sampling_traffic_concussive
      - tests/nightly/p4/examples_application/test_reboot/test_reboot.py::test_p4_examples_reboot
      - tests/nightly/lag/test_lag.py::test_core_functionality_with_reboot
      - tests/nightly/lag/test_lag.py::test_lag_min_links
      - tests/nightly/lag/test_lag.py::test_lag_members_scale
      - tests/nightly/lag/test_lag.py::test_lags_scale
      - tests/nightly/lag/test_lag.py::test_port_cannot_be_added_to_lag
      - tests/push_build_tests/general/qos/test_qos_reload.py::test_qos_reload_ports
      - tests/nightly/routing/test_routing.py::TestRouting::test_reboot
      # 2 tests below temporary added - they doing "config reload -y"
      - tests/push_build_tests/L3/dhcp_relay/test_dhcp6_relay.py::TestDHCP6Relay::test_dhcp6_relay_remove_dhcp_server
      - tests/push_build_tests/L3/dhcp_relay/test_dhcp6_relay.py::TestDHCP6Relay::test_dhcp6_relay_multiple_dhcp_servers
      # Community
      - pc/test_po_update.py::test_po_update_io_no_loss
      - vxlan/test_vnet_route_leak.py::test_vnet_route_leak
      - drop_packets/test_wjh.py::test_wjh_starts_after_config_reload
      - platform_tests/fwutil/test_fwutil.py::test_fwutil_install_file
      - platform_tests/fwutil/test_fwutil.py::test_fwutil_install_url
      - platform_tests/fwutil/test_fwutil.py::test_fwutil_update_current
      - platform_tests/fwutil/test_fwutil.py::test_fwutil_update_next
      - platform_tests/fwutil/test_fwutil.py::test_fwutil_auto
      - copp/test_copp.py::TestCOPP::test_add_new_trap
      - copp/test_copp.py::TestCOPP::test_remove_trap
      - copp/test_copp.py::TestCOPP::test_trap_config_save_after_reboot
      - vxlan/test_vnet_vxlan.py
      - ecmp/inner_hashing/test_wr_inner_hashing.py
      - dhcp_relay/test_dhcp_relay.py::test_interface_binding
      - autorestart/test_container_autorestart.py
      - iface_loopback_action/test_iface_loopback_action.py::test_loopback_action_reload
      # Ignore reboot related errors for test which checks errors after SONiC image deploy
      - tests/nightly/logging/test_log_analyzer_errors_during_deploy_sonic.py
      - system_health/test_system_health.py
      - qos/test_buffer.py::test_port_admin_down
      Redmine:
      - 3359849

- Errors_list:
    - '.* ERR docker-wait-any: :- blockable: Bad DB request \[STATE_DB\].*'
    - '.* ERR docker-wait-any: :- guard: RedisReply catches system_error: command:.* reason: WRONGTYPE Operation against a key holding the wrong kind of value: Input\/output error.*'
  Conditions:
    - Affected_test_cases:
      - drop_packets/test_wjh.py::test_wjh_starts_after_config_reload
      - tests/nightly/lag/test_lag.py::test_lags_scale
      - tests/push_build_tests/general/qos/test_qos_reload.py::test_qos_reload_ports
      Redmine:
      - 3359469

- Errors_list:
    - 'ERR pmon#.*: Failed to read from file .* - OSError\(\d+, ''No such device or address''\)'
  Conditions:
    - Affected_test_cases:
      - platform_tests/test_platform_info.py::test_thermal_control_fan_status
      - tests/nightly/evpn_vxlan/tech_support/test_evpn_vxlan_tech_support.py::TestEvpnVxlanTechSupport::test_tech_support
      Redmine:
      - 3345290

- Errors_list:
    - '.* ERR systemd\[\d+\]: Failed to start System Logging Service.*'
  Conditions:
    - Affected_test_cases:
      - tests/nightly/logging/test_log_analyzer_errors_during_deploy_sonic.py
      Redmine:
      - 3362009
