# Note that single quote ' should be escaped by another single quote '
# Example(see: Can''t):     '.* ERR kernel: \[\s+\d+\.\d+\] /dev/sda3: Can''t open blockdev'
# Example: in code below - errors will be ignored:
# IF: test case name: tests/test_dbg.py::test_a
# OR
# IF: Redmine issue active AND branch is 202106 AND sn2 in platform
# OR
# IF: GitHub issue is active
#- Errors_list:
#    - '.* ERR \d+'
#    - 'ERR can''t do \d+'
#  Conditions:
#    - Affected_test_cases:
#      - tests/test_dbg.py::test_a
#    - Redmine:
#      - 2829157
#      Branch:
#      - 202106
#      Platform:
#      - sn2
#    - GitHub:
#      - https://github.com/Azure/sonic-buildimage/issues/9811

# Errors which should be ignored in tests which doing reboot/reload
- Errors_list:
    - '.* ERR mlxfwmanager: LIBMVPD: MVPD_READ4 failed on offset:.*'
    - '.* ERR container: docker cmd: kill for .* failed .*'
    - '.* ERR pmon#thermalctld: Caught exception while running thermal policy .*'
    - '.* ERR (caclmgrd|hostcfgd).*: :- poll_descriptors: readData error: Unable to read redis reply.*'
    - '.* INFO hostcfgd.*:     raise ConnectionError.*'
    - '.* ERR systemd.*: kdump-tools.service: Ignoring invalid environment assignment .* /etc/default/kdump-tools.*'
    - '.* ERR hw-management: Path /var/run/hw-management/events/.* doesn''t exist'
    - '.* ERR dhclient.*send_packet: Network is unreachable.*'
    - '.* ERR dhclient.*send_packet: please consult README file regarding broadcast address.*'
    - '.* ERR dhclient.*Failed to send 300 byte long packet over .*'
    - '.* ERR dhclient.*No buffer space available.*'
    - '.* ERR syncd#SDK:.*Invalid port type.*'
    - '.* ERR syncd#SDK:.*mlnx_sai_utils.c.*Failed attribs dispatch.*'
    - '.* ERR syncd#SDK:.*mlnx_sai_bridge.c.*Unexpected bridge type.*'
    - '.* ERR syncd#SDK:.*mlnx_sai_utils.c.*Failed getting attrib.*'
    - '.* WARNING syncd#SDK:.*skipping since it causes crash:.*'
    - '.* ERR swss#orchagent:.*ASIC sensors : failed to get .*'
    - '.* ERR syncd#SDK:.*Unsupported debug counter type.*'
    - '.* ERR syncd#SDK:.*Invalid port counter.*'
    - '.* INFO systemd.*Start.*Kernel crash dump capture service.*'
    - '.* ERR syncd#SDK:.*mlnx_initialize_switch: Transaction mode should be enabled, enabling now.*'
    - '.* NOTICE syncd#SDK:.*Create trap.*'
    - '.* ERR neighbor_advertiser: EVERFLOW.* table does not exist.*'
    - '.* INFO systemd.*: Finished Kernel crash dump capture service.*'
    - '.* ERR syncd#SDK:.*\[SAI_BRIDGE.ERR\].*Isolation group is only supported for bridge port type port.*'
    - '.* ERR syncd#SDK:.*\[SAI_PORT.ERR\].*Port index not found in DB by log id.*'
    - '.* ERR teamd#teammgrd:.*/usr/bin/teamd -k -t.*'
    - '.* ERR caclmgrd.*: message repeated \d+ times: .*poll_descriptors: readData error: Unable to read redis reply.*'
    - '.* ERR syncd#SDK:.*\[SAI_PORT.ERR\].*mlnx_sai_port.c.*Not supported stats ID.*'
    - '.* ERR syncd#SDK:.*\[SX_API_BULK_COUNTER.ERR\].*Invalid value of port counter-groups bitmap.*'
    - '.* ERR syncd#SDK:.*\[SAI_PORT.ERR\].*mlnx_sai_port.c.* Failed to convert counter IDs to counter types bitmap.*'
    - '.* ERR syncd#SDK:.*\[SAI_PORT.ERR\].*mlnx_sai_port.c.* Failed to create buffer: Parameter Error.*'
    - '.* ERR syncd#SDK:.*\[SAI_PORT.ERR\].*mlnx_sai_port.c.* Failed to allocate SDK buffer.*'
    - '.* ERR swss#\w+syncd: :- readData: netlink reports .* on reading a netlink socket.*'
    - '.* ERR syncd#SDK:.*\[SX_API_INTERNAL.ERR\].*Failed command read at communication channel: Connection reset by peer.*'
    - '.* ERR hostcfgd:.*sudo systemctl (enable|disable).*failed. RC: 1.*'
    - '.* ERR hostcfgd:.*Feature.*failed to be\s+(enabled and started|stopped and disabled).*'
    - '.* ERR (swss#portsyncd|teamd#teamsyncd):.*netlink reports an error=-33 on reading a netlink socket.*'
    - '.* ERR systemd-udevd.*: could not read from ''\/sys\/module\/acpi_cpufreq\/initstate'': No such device.*'
    - '.* (ERR|WARNING) syncd#(SAI|SDK):.*Shared memory of the.*already exists,\s*destroying it and re-creating.*'
    - '.* ERR swss#orchagent:.*removeLag: Failed to remove (ref count \d+|non-empty) LAG PortChannel.*'
    - '.* ERR hostcfgd:.*error returned by select.*'
    - '.* ERR pmon#python3: :- .*Expected to get redis type \d+ got type \d+, err: NON-STRING-REPLY.*'
    - '.* ERR pmon#xcvrd: sx_api_host_ifc_trap_id_register_set exited with error, rc 4.*'
    - '.* ERR pmon#xcvrd: sx_api_host_ifc_close exited with error, rc 3.*'
    - '.* ERR syncd#SDK: \[ROUTER.ERR\] VRID \[\d+\] is in use.'
    - '.* ERR syncd#SDK: \[ROUTER.ERR\] Cannot deinit - resources are in use. \[Resource is in use\]'
    - '.* ERR syncd#SDK: \[SAI_SWITCH.ERR\] mlnx_sai_switch.c\[\d+\]- mlnx_shutdown_switch: Router deinit failed.'
    - '.* ERR syncd#SDK: \[SAI_SWITCH.ERR\] mlnx_sai_switch.c\[\d+\]- mlnx_shutdown_switch: mlnx_sai_switch.c\[\d+\]- mlnx_shutdown_switch: killall -w sx_sdk failed.'
    - '.* ERR bgp#bgpmon: \*ERROR\* Failed with rc:1 when execute: \[''vtysh'', ''-c'', ''show bgp summary json''\]'
  Conditions:
    - Affected_test_cases:
      # Canonical
      - tests/nightly/app_extension/test_app_extension_reboot.py::test_app_start_delay_after_reboot
      - tests/nightly/auto_negotition/test_auto_neg.py::TestAutoNeg::test_auto_neg_conf
      - tests/nightly/copp/test_copp.py::test_copp_policer
      - tests/nightly/fdb/test_fdb_basic.py::TestFdbBasic::test_fdb_aging_time_expire
      - tests/nightly/fec/test_fec.py::TestFec::test_fec_capabilities_loopback_ports
      - tests/nightly/fec/test_fec.py::TestFec::test_fec_capabilities_hosts_ports
      - tests/nightly/fec/test_fec.py::TestFec::test_negative_fec
      - tests/nightly/fec/test_fec.py::TestFec::test_fec_bug_2705016
      - tests/nightly/p4/sampling_example/test_entry_scaling.py::TestEntryScaling::test_scaling_entries
      - tests/nightly/p4/sampling_example/test_entry_priority.py::test_entries_with_different_priority
      - tests/nightly/p4/sampling_example/test_entry_priority.py::test_entries_with_same_priority
      - tests/nightly/p4/sampling_example/test_entry_advance.py::TestEntryTraffic::test_enable_disable_p4_sampling
      - tests/nightly/p4/sampling_example/test_entry_advance.py::TestEntryTraffic::test_p4_sampling_traffic_concussive
      - tests/nightly/p4/examples_application/test_reboot/test_reboot.py::test_p4_examples_reboot
      - tests/nightly/lag/test_lag.py::test_core_functionality_with_reboot
      - tests/nightly/lag/test_lag.py::test_lag_min_links
      - tests/nightly/lag/test_lag.py::test_lag_members_scale
      - tests/nightly/lag/test_lag.py::test_lags_scale
      - tests/nightly/lag/test_lag.py::test_port_cannot_be_added_to_lag
      - tests/push_build_tests/general/qos/test_qos_reload.py::test_qos_reload_ports
      - tests/push_build_tests/system/test_startup_time_degradation.py
      - tests/nightly/routing/test_routing.py::TestRouting::test_reboot
      # 2 tests below temporary added - they doing "config reload -y"
      - tests/push_build_tests/L3/dhcp_relay/test_dhcp6_relay.py::TestDHCP6Relay::test_dhcp6_relay_remove_dhcp_server
      - tests/push_build_tests/L3/dhcp_relay/test_dhcp6_relay.py::TestDHCP6Relay::test_dhcp6_relay_multiple_dhcp_servers
      # Community
      - pc/test_po_update.py::test_po_update_io_no_loss
      - vxlan/test_vnet_route_leak.py::test_vnet_route_leak
      - drop_packets/test_wjh.py::test_wjh_starts_after_config_reload
      - platform_tests/fwutil/test_fwutil.py::test_fwutil_install_file
      - platform_tests/fwutil/test_fwutil.py::test_fwutil_install_url
      - platform_tests/fwutil/test_fwutil.py::test_fwutil_update_current
      - platform_tests/fwutil/test_fwutil.py::test_fwutil_update_next
      - platform_tests/fwutil/test_fwutil.py::test_fwutil_auto
      - copp/test_copp.py::TestCOPP::test_add_new_trap
      - copp/test_copp.py::TestCOPP::test_remove_trap
      - copp/test_copp.py::TestCOPP::test_trap_config_save_after_reboot
      - vxlan/test_vnet_vxlan.py
      - ecmp/inner_hashing/test_wr_inner_hashing.py
      - dhcp_relay/test_dhcp_relay.py::test_interface_binding
      - autorestart/test_container_autorestart.py
      - iface_loopback_action/test_iface_loopback_action.py::test_loopback_action_reload
      # Ignore reboot related errors for test which checks errors after SONiC image deploy
      - tests/nightly/logging/test_log_analyzer_errors_during_deploy_sonic.py
      - system_health/test_system_health.py
      - qos/test_buffer.py::test_port_admin_down

# Errors which should be ignored in tests which restart dockers
- Errors_list:
    - '.*ERR kernel: .* mlxsw_minimal .*: Cmd exec timed-out \(opcode=\d+\(ACCESS_REG\),opcode_mod=\d,in_mod=\d\).*'
  Conditions:
    - Affected_test_cases:
      - autorestart/test_container_autorestart.py::test_containers_autorestart
      - tests/nightly/logging/test_log_analyzer_errors_during_deploy_sonic.py::test_check_errors_in_log_during_deploy_sonic_image

# Vivek conclaimed these error logs are not bug(RM #3238130), he suggest adding them into common ignore list
- Errors_list:
    - '.*ERR dhclient\[\d+\]: Failed to get interface index: No such device.*'
    - '.*ERR dhclient\[\d+\]: If you think you have received this message due to a bug rather.*'
    - '.*ERR dhclient\[\d+\]: than a configuration issue please read the section on submitting.*'
    - '.*ERR dhclient\[\d+\]: bugs on either our web page at www.isc.org or in the README file.*'
    - '.*ERR dhclient\[\d+\]: before submitting a bug.  These pages explain the proper.*'
    - '.*ERR dhclient\[\d+\]: process and the information we find helpful for debugging.*'
    - '.*ERR dhclient\[\d+\]: exiting.*'
    - '.*ERR dhclient\[\d+\]: '
    # Sud confirmed this Err could be ignored in # 3293075
    # After issuing reboot command, if we get the above error log we can ignore them. Please note,
    # this can be observed for any service that was issued to be enable but reboot command was give.
    - '.*ERR hostcfgd: sudo systemctl start syncd.service - failed: return code - 1.*'
    - '.* ERR hostcfgd: \[.*\] - failed: return code - (\d+|-\d+), output:.*'
  Conditions:
    - Affected_test_cases:
      - tests/nightly/logging/test_log_analyzer_errors_during_deploy_sonic.py

# Temporary errors which should be ignored in tests which doing reboot/reload - by RM issue 3024792
- Errors_list:
    - '.* ERR lldp#lldpmgrd\[\d+\]: unknown operation.*'
  Conditions:
    - Affected_test_cases:
      # Canonical
      - tests/nightly/app_extension/test_app_extension_reboot.py::test_app_start_delay_after_reboot
      - tests/nightly/auto_negotition/test_auto_neg.py::TestAutoNeg::test_auto_neg_conf
      - tests/nightly/copp/test_copp.py::test_copp_policer
      - tests/nightly/fdb/test_fdb_basic.py::TestFdbBasic::test_fdb_aging_time_expire
      - tests/nightly/fec/test_fec.py::TestFec::test_fec_capabilities_loopback_ports
      - tests/nightly/fec/test_fec.py::TestFec::test_fec_capabilities_hosts_ports
      - tests/nightly/fec/test_fec.py::TestFec::test_negative_fec
      - tests/nightly/fec/test_fec.py::TestFec::test_fec_bug_2705016
      - tests/nightly/p4/sampling_example/test_entry_scaling.py::TestEntryScaling::test_scaling_entries
      - tests/nightly/p4/sampling_example/test_entry_priority.py::test_entries_with_different_priority
      - tests/nightly/p4/sampling_example/test_entry_priority.py::test_entries_with_same_priority
      - tests/nightly/p4/sampling_example/test_entry_advance.py::TestEntryTraffic::test_enable_disable_p4_sampling
      - tests/nightly/p4/sampling_example/test_entry_advance.py::TestEntryTraffic::test_p4_sampling_traffic_concussive
      - tests/nightly/p4/examples_application/test_reboot/test_reboot.py::test_p4_examples_reboot
      - tests/nightly/lag/test_lag.py::test_core_functionality_with_reboot
      - tests/nightly/lag/test_lag.py::test_lag_min_links
      - tests/nightly/lag/test_lag.py::test_lag_members_scale
      - tests/nightly/lag/test_lag.py::test_lags_scale
      - tests/nightly/lag/test_lag.py::test_port_cannot_be_added_to_lag
      - tests/push_build_tests/L3/dhcp_relay/test_dhcp6_relay.py::TestDHCP6Relay::test_dhcp6_relay_remove_dhcp_server
      - tests/push_build_tests/L3/dhcp_relay/test_dhcp6_relay.py::TestDHCP6Relay::test_dhcp6_relay_multiple_dhcp_servers
      # Community
      - pc/test_po_update.py::test_po_update_io_no_loss
      - vxlan/test_vnet_route_leak.py::test_vnet_route_leak
      - drop_packets/test_wjh.py::test_wjh_starts_after_config_reload
      - platform_tests/fwutil/test_fwutil.py::test_fwutil_install_file
      - platform_tests/fwutil/test_fwutil.py::test_fwutil_install_url
      - platform_tests/fwutil/test_fwutil.py::test_fwutil_update_current
      - platform_tests/fwutil/test_fwutil.py::test_fwutil_update_next
      - platform_tests/fwutil/test_fwutil.py::test_fwutil_auto
      - copp/test_copp.py::TestCOPP::test_add_new_trap
      - copp/test_copp.py::TestCOPP::test_remove_trap
      - copp/test_copp.py::TestCOPP::test_trap_config_save_after_reboot
      - sub_port_interfaces/test_show_subinterface.py
      - sub_port_interfaces/test_sub_port_interfaces.py
      - sub_port_interfaces/test_sub_port_l2_forwarding.py
      # Ignore reboot related errors for test which checks errors after SONiC image deploy
      - tests/nightly/logging/test_log_analyzer_errors_during_deploy_sonic.py
      Redmine:
      - 3024792
      Branch:
      - 202111
      - master
      - 202211

- Errors_list:
    - '.* ERR swss#orchagent: :- handlePortQosMapTable: Failed to apply QoS maps to port global\. Port is not found.*'
  Conditions:
    - Affected_test_cases:
      - tests/push_build_tests/general/qos/test_qos_reload.py::test_qos_reload_ports
      Redmine:
      - 3110830

- Errors_list:
    - '.* ERR sflow#port_index_mapper: no interface with this name'
  Conditions:
    - Affected_test_cases:
      - tests/push_build_tests/L2/vlan/test_vlan.py::TestVLAN::test_vlan_4094_5
      Redmine:
      - 3439686


- Errors_list:
    - '.* ERR pmon#chassis_db_init: Fail to decode DMI /sys/firmware/dmi/entries/2-0/raw due to FileNotFoundError\(2, ''No such file or directory''\)'
    - '.* ERR watchdogutil: Failed to get watchdog module'
    - '.* ERR kernel: \[\s+\d+\.\d+\] /dev/sda3: Can''t open blockdev'
    - '.* ERR healthd: Failed to read from file \/var\/run\/hw-management\/led\/led_status_capability - FileNotFoundError.*No such file or directory.*'
    - '.* ERR healthd: Failed to write.*file \/var\/run\/hw-management\/led\/led_status_green - FileNotFoundError.*No such file or directory.*'
    - '.* ERR show: Fail to decode DMI /sys/firmware/dmi/entries/2-0/raw due to FileNotFoundError\(2, .*No such file or directory.*\)'
  Conditions:
    - Platform:
      - simx

- Errors_list:
    - '.*ERR syncd#SDK: \[FLOW_COUNTER.ERR\] spectrum_flow_counter_get: spectrum_flow_counter_lock failed.*'
    - '.*ERR syncd#SDK: \[FLOW_COUNTER.ERR\] spectrum_flow_counter_lock: cm_lock failed.*'
    - '.*ERR syncd#SDK: \[GBIN_ALLOCATOR.ERR\] LID \d+ doesn''t exist!.*'
    - '.*ERR syncd#SDK: \[SAI_ACL.ERR\] mlnx_sai_acl.c\[\d+\]- mlnx_acl_counter_get:.* Failure to get counter in SDK.*'
    - '.*ERR syncd#SDK: \[SAI_UTILS.ERR\] mlnx_sai_utils.c\[\d+\]- .*Failed getting attrib SAI_ACL_COUNTER_ATTR_BYTES.*'

  Conditions:
    - Redmine:
      - 3285631
      Platform:
        - simx

- Errors_list:
    - '.*ERR syncd#SDK: \[SX_API_PORT.ERR\] sx_api_port_parsing_depth_set: This API is deprecated and will be removed in the future.*'

  Conditions:
    - Redmine:
      - 3500892

- Errors_list:
    - '.*ERR python: :- initializeGlobalConfig: Sonic database config global file doesn''t exist at /var/run/redis/sonic-db/database_global.json*'

  Conditions:
    - Redmine:
      - 3510718


- Errors_list:
    - '.* ERR syncd#SDK: \[COMP_LIB.ERR\] failed to rename file.*'
    - '.*ERR syncd#SDK: \[SX_API_DBG.ERR\].*dump .*failed.*'
  Conditions:
    - Redmine:
        - 3075643
      Platform:
        - simx

- Errors_list:
    - '.* ERR hostcfgd: sonic-kdump-config --disable - failed: return code - 1, output:#012None'
    - '.* ERR hostcfgd: sonic-kdump-config --memory 0M-2G:256M,2G-4G:320M,4G-8G:384M,8G-:448M - failed: return code - 1, output:#012None'
  Conditions:
    - Branch:
      - 202111

# Below ignores from temp_log_analyzer_ignores.txt in LAG folder
- Errors_list:
    - '.* ERR kernel: \[.*\] mlxsw_minimal 2-0048: Could not acquire lock'
    - '.* ERR kernel: \[.*\] mlxsw_minimal 2-0048: Failed to query PWM'
    - '.* ERR kernel: \[.*\] mlxsw_minimal 2-0048: Failed to write PWM'
    - '.* ERR pmon#syseepromd: Failed to load platform-specific eeprom from deprecated plugin.*'
    - '.* WARNING pmon#syseepromd: Failed to load platform-specific eeprom from sonic_platform package due to KeyError.*'
    - '.* ERR syncd#SDK: :- translateVidToRid: unable to get RID for VID oid:0x.*'
    - '.* ERR teamd#tlm_teamd: :- process_add_queue: Can''t connect to teamd after .* attempts.*'
    - '.* ERR syncd#SDK: :- updateSupportedBufferPoolCounters: BUFFER_POOL_WATERMARK_STAT_COUNTER: counter SAI_BUFFER_POOL_STAT_XOFF_ROOM_WATERMARK_BYTES is not supported on buffer pool .*, rv: SAI_STATUS_NOT_IMPLEMENTED'
    - '.* INFO kernel: .* teamd.*: segfault at b0 ip .* sp .* error 4 in libteam.*'
    - '.* ERR snmp#snmpd.*: ioctl \d+ returned -1.*'
    - '.* ERR pmon#sensord: Error getting sensor data: mlxsw.*: Kernel interface error.*'
  Conditions:
    - Affected_test_cases:
      - tests/nightly/lag/test_lag.py

- Errors_list:
    - '.* ERR teamd#tlm_teamd: :- get_dump: Can''t get dump for LAG ''PortChannel\d+''.*'
  Conditions:
    - Affected_test_cases:
      - tests/nightly/lag/test_lag.py
      Redmine:
      - 2934692

# From ngts/tests/nightly/arp/log_analyzer_ignores.txt
- Errors_list:
    - '.* ERR swss#orchagent.*Failed to remove ref count.*\d+.*LAG.*PortChannel.*'
  Conditions:
    - Affected_test_cases:
      - tests/nightly/arp/test_arp.py

# From ngts/tests/nightly/auto_negotition/negative_auto_neg_log_analyzer_ignores
- Errors_list:
    - '.* ERR syncd#SDK: \[SAI_PORT.ERR\] mlnx_sai_port.c\[.*\]- mlnx_port_speeds_merge: Port \[Speed\[.*\] configuration is invalid.*'
    - '.* ERR syncd#SDK: \[SAI_PORT.ERR\] mlnx_sai_port.c\[.*\]- mlnx_port_update_speed: Failed to merge speeds, interface types and auto_neg.*'
    - '.* ERR syncd#SDK: \[SAI_PORT.ERR\] mlnx_sai_port.c\[.*\]- mlnx_port_attr_set: Failed to update speed.*'
    - '.* ERR syncd#SDK: \[SAI_UTILS.ERR\] mlnx_sai_utils.c\[.*\]- sai_set_attribute: Failed set attrib dispatch.*'
    - '.* ERR syncd#SDK: :- sendApiResponse: api SAI_COMMON_API_SET failed in syncd mode: SAI_STATUS_INVALID_ATTR_VALUE_.*'
    - '.* ERR syncd#SDK: :- processQuadEvent: VID: oid:.* RID: oid:.*'
    - '.* ERR syncd#SDK: :- processQuadEvent: attr: SAI_PORT_ATTR_.*INTERFACE_TYPE:.*SAI_PORT_INTERFACE_TYPE_.*'
    - '.* ERR syncd#SDK: :- processQuadEvent: attr: SAI_PORT_ATTR_AUTO_NEG_MODE:.*'
    - '.* ERR swss#orchagent: :- set: set status: SAI_STATUS_INVALID_ATTR_VALUE_.*'
    - '.* ERR swss#orchagent: :- doPortTask: Failed to set port Ethernet\d+.*interface type to .*'
    - '.* ERR swss#orchagent: :- setPortAutoNeg: Failed to set AutoNeg \d+ to port pid:\d+.*'
    - '.* ERR swss#orchagent: :- handleSaiSetStatus: Encountered failure in set operation, exiting orchagent.*'
    - '.* ERR syncd#SDK: \[SAI_PORT.ERR\] mlnx_sai_port.c\[.*\]- mlnx_port_speeds_merge: Port \[.*\] configuration doesn''t match mask for \d+ lanes.*'
    - '.* ERR syncd#SDK: :- processQuadEvent: attr: SAI_PORT_ATTR_SPEED: \d+.*'
    - '.* ERR swss#orchagent: :- handleSaiSetStatus: Encountered SAI_STATUS_INVALID_ATTR_VALUE_0 in set operation.*'
    - '.* ERR swss#orchagent: :- doPortTask: Failed to set port Ethernet\d+ speed from \d+ to \d+.*'
    - '.* ERR syncd#SDK: \[SAI_PORT.ERR\] mlnx_sai_port.c\[\d+\]- mlnx_port_update_speed_sp2: Failed to set port .* rate - Parameter Error.'
    - '.* ERR syncd#SDK: \[SAI_PORT.ERR\] mlnx_sai_port.c\[\d+\]- mlnx_port_update_speed: Failed to apply speed/intf bitmap \[0x.*\] for port\[0x.*\].'
    - '.* ERR syncd#SDK: \[PORT.ERR\] Port rate given is not compatible with the capability rate of the switch.'
    - '.* ERR syncd#SDK: \[PORT.ERR\] Port rate capability validation failed \(Parameter Error\).'
    - '.* ERR syncd#SDK: \[PORT.ERR\] Specified admin rate value is invalid, rc = Parameter Error'
  Conditions:
    - Affected_test_cases:
      - tests/nightly/auto_negotition/test_auto_neg_negative.py::TestAutoNegNegative::test_negative_config_advertised_speeds
      - tests/nightly/auto_negotition/test_auto_neg_negative.py::TestAutoNegNegative::test_negative_config_advertised_types
      - tests/nightly/auto_negotition/test_auto_neg_negative.py::TestAutoNegNegative::test_negative_advertised_speed_type_mismatch
      - tests/nightly/auto_negotition/test_auto_neg.py::TestAutoNeg::test_auto_neg_toggle_peer_port
      - tests/nightly/fec/test_fec.py::TestFec::test_negative_fec
      - tests/nightly/fec/test_fec.py::TestFec::test_fec_capabilities_hosts_ports
      - tests/nightly/fec/test_fec.py::TestFec::test_fec_capabilities_loopback_ports

# From ngts/tests/nightly/fdb/log_analyzer_ignores.txt
- Errors_list:
    - '.* ERR swss#orchagent.*doAppSwitchTableTask.*Unsupported switch attribute ordered_ecmp.*'
    - '.* WARNING syncd#SDK:.*Not supported attribute SAI_TUNNEL_ATTR_DECAP_DSCP_MODE.*'
    - '.* WARNING syncd#SDK:.*sai_set_attribute: Failed attribs check, key:tunnel ID.*'
    - '.* ERR syncd#SDK.*sendApiResponse: api SAI_COMMON_API_SET failed in syncd mode: SAI_STATUS_ATTR_NOT_SUPPORTED.*'
    - '.* ERR syncd#SDK.*processQuadEvent.*VID.*oid.*RID.*oid.*'
    - '.* ERR syncd#SDK.*processQuadEvent.*attr.*SAI_TUNNEL_ATTR_DECAP_DSCP_MODE.*SAI_TUNNEL_DSCP_MODE_PIPE_MODEL.*'
    - '.* ERR swss#orchagent.*SAI_STATUS_ATTR_NOT_SUPPORTED.*'
    - '.* ERR swss#orchagent.*setTunnelAttribute.*Failed to set attribute dscp_mode with value pipe.*'
    - '.* ERR syncd#SDK.*updateSupportedBufferPoolCounters: BUFFER_POOL_WATERMARK_STAT_COUNTER: counter SAI_BUFFER_POOL_STAT_XOFF_ROOM_WATERMARK_BYTES is not supported on buffer pool oid:.*, rv: SAI_STATUS_NOT_IMPLEMENTED.*'
  Conditions:
    - Affected_test_cases:
      - tests/nightly/fdb/test_fdb_basic.py::TestFdbBasic::test_fdb_aging_time_expire

# Errors which should be ignored on SPC1 when install the p4-examples, p4-sampling, and enable them
- Errors_list:
    - '.*ERR p4.*examples: start.sh - unsupported DEVICE_TYPE=Spectrum.*'
    - '.*ERR p4.*sampling: start.sh - unsupported DEVICE_TYPE=Spectrum.*'
  Conditions:
    - Platform:
        sn2

# From ngts/tests/nightly/p4/sampling_example/p4_sampling_loganalyzer_ignore.txt
- Errors_list:
    - '.* ERR swss#orchagent: :- removeTunnelNextHop: Remove Tunnel next hop unable to find EVPN VTEP.*'
    - '.* ERR swss#orchagent: :- removeOverlayNextHops: Tunnel Nexthop .*delete failed.*'
    - '.* ERR syncd#SAI:.*\[SAI_SWITCH.ERR\].*mlnx_sai_switch.c.*Shared memory of the SAI already exists, destroying it and re-creating'
    - '.* WARNING syncd#SAI.*\[SAI_SWITCH.WARNING\].*mlnx_sai_switch.c.*sai_qos_db_create.*Shared memory of the SAI QOS already exists, destroying it and re-creating'
    - '.* WARNING syncd#SAI.*\[SAI_SWITCH.WARNING\].*mlnx_sai_switch.c.*sai_buffer_db_create.*Shared memory of the SAI buffer already exists, destroying it and re-creating'
    - '.* WARNING syncd#SAI.*\[SAI_SWITCH.WARNING\].*mlnx_sai_switch.c.*sai_acl_db_create.*Shared memory of the SAI ACL already exists, destroying it and re-creating'
    - '.* WARNING syncd#SAI.*\[SAI_SWITCH.WARNING\].*mlnx_sai_switch.c.*sai_tunnel_db_create.*Shared memory of the SAI TUNNEL already exists, destroying it and re-creating'
    - '.* WARNING syncd#SDK.*\[SXD_DPT.WARNING\].*sxd_dpt_init().*Shared memory of the DPT already exists,destroying it and re-creating'
  Conditions:
    - Affected_test_cases:
      - tests/nightly/p4/sampling_example/test_entry_advance.py::TestEntryTraffic::test_enable_disable_p4_sampling
      - tests/nightly/p4/sampling_example/test_entry_advance.py::TestEntryTraffic::test_p4_sampling_traffic_concussive
      - tests/nightly/p4/sampling_example/test_entry_priority.py::test_entries_with_different_priority
      - tests/nightly/p4/sampling_example/test_entry_priority.py::test_entries_with_same_priority
      - tests/nightly/p4/sampling_example/test_entry_scaling.py::TestEntryScaling::test_scaling_entries
# p4-sampling related err msg
- Errors_list:
    - '.* ERR syncd#SDK: \[SPAN.ERR\] SPAN module already initialized'
  Conditions:
    - Affected_test_cases:
      - tests/nightly/p4/sampling_example/test_entry_advance.py::TestEntryTraffic::test_enable_disable_p4_sampling
      - tests/nightly/p4/sampling_example/test_entry_advance.py::TestEntryTraffic::test_p4_sampling_traffic_concussive
      - tests/nightly/p4/sampling_example/test_entry_priority.py::test_entries_with_different_priority
      - tests/nightly/p4/sampling_example/test_entry_priority.py::test_entries_with_same_priority
      - tests/nightly/p4/sampling_example/test_entry_scaling.py::TestEntryScaling::test_scaling_entries
      # this err can also happen in test case doing "config reload -y" when p4-sampling is installed and enabled
      - tests/push_build_tests/L3/dhcp_relay/test_dhcp6_relay.py::TestDHCP6Relay::test_dhcp6_relay_remove_dhcp_server

- Errors_list:
    - '.* ERR swss#orchagent: :- removeLag: Failed to remove ref count.*\d+.*LAG PortChannel.*'
    - '.* ERR swss#orchagent: message repeated \d+ times: \[ :- removeLag: Failed to remove ref count \d+ LAG PortChannel\d+\]'
  Conditions:
    - Affected_test_cases:
      - tests/push_build_tests/L3/crm/test_crm.py::test_crm_route
      - tests/push_build_tests/L3/crm/test_crm.py::test_crm_neighbor_and_nexthop
      - tests/push_build_tests/L3/crm/test_crm.py::test_crm_nexthop_group_and_member
      - tests/push_build_tests/L3/crm/test_crm.py::test_crm_fdb_entry
      - tests/push_build_tests/L3/crm/test_crm.py::test_crm_acl
      - pc/test_po_update.py::test_po_update_io_no_los
      - vxlan/test_vnet_route_leak.py::test_vnet_route_leak
      - tests/push_build_tests/L3/dhcp_relay/test_dhcp6_relay.py
      - drop_packets/test_wjh.py::test_wjh_starts_after_config_reload
      - system_health/test_system_health.py
      Redmine:
      - 2615940

- Errors_list:
    - '.* ERR swss#orchagent: :- removeLag: Failed to remove non-empty LAG PortChannel.*'
  Conditions:
    - Affected_test_cases:
      - pc/test_po_update.py::test_po_update
      Redmine:
      - 2615940

- Errors_list:
    - '.* ERR bgp#bgpmon: \*ERROR\* Failed with rc:1 when execute: \[''vtysh'', ''-c'', ''show bgp summary json''\]'
    - '.* INFO bgp#supervisord .* INFO exited: bgpd \(terminated by SIGABRT \(core dumped\); not expected\)'
    - '.* INFO bgp#supervisor-proc-exit-listener: Process ''bgpd'' exited unexpectedly\. Terminating supervisor ''bgp'''
  Conditions:
    - Affected_test_cases:
      - tests/nightly/fec/test_fec.py::TestFec::test_fec_capabilities_loopback_ports
      Redmine:
      - 3339955
      Branch:
        - 202205
        - 202211

- Errors_list:
    - '.*ERR kernel:.*mlxsw_minimal .* Eeprom query failed.*'
  Conditions:
    - Affected_test_cases:
      - tests/nightly/show_techsupport/test_techsupport.py::test_techsupport_mellanox_sdk_dump
      - tests/nightly/app_extension/test_app_extension_basic.py::test_app_techsupport_integration
      - tests/nightly/app_extension/test_app_extension_reboot.py::test_app_start_delay_after_reboot
      - platform_tests/sfp/test_sfputil.py
      - platform_tests/fwutil/test_fwutil.py::test_fwutil_install_file
      - show_techsupport/test_techsupport.py::test_techsupport
      - show_techsupport/test_auto_techsupport.py
      - show_techsupport/test_techsupport_no_secret.py::test_secret_removed_from_show_techsupport
      - tests/push_build_tests/L3/dhcp_relay/test_dhcp6_relay.py::TestDHCP6Relay::test_dhcp6_relay_remove_dhcp_server
      Redmine:
        - 2915388

- Errors_list:
    - '.*WARNING syncd#SDK: \[HOST_INTERFACE\.WARNING\] Receive event of FW SOS.*'
  Conditions:
    - Affected_test_cases:
      - tests/nightly/show_techsupport/test_techsupport.py::test_techsupport_mellanox_sdk_dump

- Errors_list:
    - '.*ERR kernel: \[.*\d+\.\d+\] Register access failed \(reg_id=0x9014, status=0x1\).*'
  Conditions:
    - Redmine:
        - 3495609

- Errors_list:
    - '.*ERR kernel: \[.*\d+\.\d+\] Register access failed \(reg_id=0x5008, status=0x7\).*'
  Conditions:
    - Affected_test_cases:
      - tests/push_build_tests/general/wjh/test_wjh.py
      Redmine:
        - 3519344
      Platform:
        - sn5600_simx

- Errors_list:
    - '.*ERR.*dhcp_relay#dhcrelay\[\d+\]:\sparse_option_buffer:\smalformed\soption\sdhcp6\.<unknown>\s\(code 29797\):\soption\slength\sexceeds\soption\sbuffer\slength\.'
    - '.*ERR.*dhcp_relay#dhcrelay\[\d+\]:\smessage\srepeated\s\d+\stimes:\s\[\sparse_option_buffer:\smalformed\soption\sdhcp6\.<unknown>\s\(code 29797\):\soption\slength\sexceeds\soption\sbuffer\slength\.'
  Conditions:
    - Affected_test_cases:
      - tests/push_build_tests/L3/dhcp_relay/test_dhcp6_relay.py::TestDHCP6Relay::test_dhcpv6_relay_client_request_with_malformed_payload

- Errors_list:
    - '.* ERR dhcp_relay#dhcp6relay: bind: Failed to bind to socket'
  Conditions:
    - Redmine:
      - 2954292
      Branch:
        - 202012
        - 202111
        - master
        - 202211

- Errors_list:
    - '.* ERR swss#fdbsyncd: :- readData: netlink reports an error=-25 on reading a netlink socket'
  Conditions:
    - Redmine:
      - 2606325
      Branch:
        - 202012

- Errors_list:
    - '.* WARNING syncd#SDK: :- discover: skipping since it causes crash: SAI_STP_ATTR_BRIDGE_ID'
  Conditions:
    - Affected_test_cases:
      - pc/test_po_update.py::test_po_update_io_no_loss
      - vxlan/test_vnet_route_leak.py::test_vnet_route_leak
      - ecmp/inner_hashing/test_wr_inner_hashing.py
      - autorestart/test_container_autorestart.py
      - copp/test_copp.py::TestCOPP::test_no_policer
      - copp/test_copp.py::TestCOPP::test_policer
      - route/test_static_route.py::test_static_route_ecmp
      - system_health/test_system_health.py
      - iface_loopback_action/test_iface_loopback_action.py::test_loopback_action_reload

- Errors_list:
    - '.* ERR syncd#SDK: \[SAI_DEBUG_COUNTER.ERR\] mlnx_sai_debug_counter.c\[\d+\]- mlnx_debug_counter_availability_get: Unsupported debug counter type - \d'
    - '.* ERR syncd#SDK: \[SAI_PORT.ERR\] mlnx_sai_port.c\[\d+\]- mlnx_get_port_stats_ext: Invalid port counter \d+'
    - '.* ERR syncd#SAI: \[SAI_SWITCH.ERR\] mlnx_sai_switch.c\[\d+\]- sai_db_create: mlnx_sai_switch.c\[\d+\]- sai_db_create: Shared memory of the SAI already exists, destroying it and re-creating'
    - '.* WARNING syncd#SAI: \[SAI_SWITCH.WARNING\] mlnx_sai_switch.c\[\d+\]- sai_qos_db_create: mlnx_sai_switch.c\[\d+\]- sai_qos_db_create: Shared memory of the SAI QOS already exists, destroying it and re-creating'
    - '.* WARNING syncd#SAI: \[SAI_SWITCH.WARNING\] mlnx_sai_switch.c\[\d+\]- sai_buffer_db_create: mlnx_sai_switch.c\[\d+\]- sai_buffer_db_create: Shared memory of the SAI buffer already exists, destroying it and re-creating'
    - '.* WARNING syncd#SAI: \[SAI_SWITCH.WARNING\] mlnx_sai_switch.c\[\d+\]- sai_acl_db_create: mlnx_sai_switch.c\[\d+\]- sai_acl_db_create: Shared memory of the SAI ACL already exists, destroying it and re-creating'
    - '.* WARNING syncd#SAI: \[SAI_SWITCH.WARNING\] mlnx_sai_switch.c\[\d+\]- sai_tunnel_db_create: mlnx_sai_switch.c\[\d+\]- sai_tunnel_db_create: Shared memory of the SAI TUNNEL already exists, destroying it and re-creating'
    - '.* WARNING syncd#SDK: \[SXD_DPT.WARNING\] sxd_dpt_init\(\): Shared memory of the DPT already exists,destroying it and re-creating'
  Conditions:
    - Affected_test_cases:
      - pc/test_po_update.py::test_po_update_io_no_loss
      - vxlan/test_vnet_route_leak.py::test_vnet_route_leak
      - system_health/test_system_health.py
      - autorestart/test_container_autorestart.py
      - dhcp_relay/test_dhcp_relay.py::test_interface_binding
      - copp/test_copp.py::TestCOPP::test_no_policer
      - copp/test_copp.py::TestCOPP::test_policer
      - route/test_static_route.py::test_static_route_ecmp
      Branch:
        - 202012

- Errors_list:
    - '.* ERR syncd#SDK: \[SAI_BRIDGE.ERR\] mlnx_sai_bridge.c\[\d+\]- mlnx_bridge_port_lag_or_port_get: Invalid port type - 2'
    - '.* ERR syncd#SDK: \[SAI_UTILS.ERR\] mlnx_sai_utils.c\[\d+\]- get_dispatch_attribs_handler: Failed getting attrib SAI_BRIDGE_PORT_ATTR_ISOLATION_GROUP'
    - '.* ERR syncd#SDK: \[SAI_UTILS.ERR\] mlnx_sai_utils.c\[\d+\]- get_dispatch_attribs_handler: Failed getting attrib SAI_BRIDGE_ATTR_UNKNOWN_UNICAST_FLOOD_GROUP'
    - '.* ERR syncd#SDK: \[SAI_UTILS.ERR\] mlnx_sai_utils.c\[\d+\]- get_dispatch_attribs_handler: Failed getting attrib SAI_BRIDGE_ATTR_UNKNOWN_MULTICAST_FLOOD_GROUP'
    - '.* ERR syncd#SDK: \[SAI_UTILS.ERR\] mlnx_sai_utils.c\[\d+\]- get_dispatch_attribs_handler: Failed getting attrib SAI_BRIDGE_ATTR_BROADCAST_FLOOD_GROUP'
    - '.* ERR syncd#SDK: \[SAI_UTILS.ERR\] mlnx_sai_utils.c\[\d+\]- get_dispatch_attribs_handler: Failed getting attrib SAI_BRIDGE_PORT_ATTR_PORT_ID'
    - '.* ERR syncd#SDK: \[SAI_UTILS.ERR\] mlnx_sai_utils.c\[\d+\]- sai_get_attributes: Failed attribs dispatch'
    - '.* ERR syncd#SDK: \[SAI_UTILS.ERR\] mlnx_sai_utils.c\[\d+\]- sai_get_attributes: Failed to get attribute'
    - '.* ERR syncd#SDK: \[SAI_BRIDGE.ERR\] mlnx_sai_bridge.c\[\d+\]- mlnx_bridge_port_isolation_group_get: Isolation group is only supported for bridge port type port'
    - '.* ERR syncd#SDK: \[SAI_BRIDGE.ERR\] mlnx_sai_bridge.c\[\d+\]- mlnx_bridge_1d_oid_to_data: Unexpected bridge type 0 is not 1D'
  Conditions:
    - Redmine:
      - 2619129

- Errors_list:
    - '.*ERR lldp#lldp-syncd \[lldp_syncd\] ERROR: Could not infer system information from.*'
  Conditions:
    - Affected_test_cases:
      - autorestart/test_container_autorestart.py
      Redmine:
        - 3010810

- Errors_list:
    - '.*ERR teamd#teamsyncd: :- poll_descriptors: readData error: Unable to initialize team socket: Cannot assign requested address'
  Conditions:
    - Affected_test_cases:
      - autorestart/test_container_autorestart.py
      Redmine:
        - 3071644
      GitHub:
        - https://github.com/Azure/sonic-buildimage/issues/10867

- Errors_list:
    - '.* WARNING syncd#SDK: \[SAI_TUNNEL.WARNING\] mlnx_sai_tunnel.c\[\d+\]- mlnx_sdk_fill_tunnel_ttl_data: TTL uniform model is not supported for non-ipinip type on Spectrum 1, using default settings in switch'
  Conditions:
    - Redmine:
        - 2954740
      Branch:
        - 202111
        - master
        - 202211
      Platform:
        - x86_64-mlnx_msn2
        - x86_64-mlnx_msn2700-r0
        - x86_64-mlnx_msn2010-r0

- Errors_list:
    - '.* ERR syncd#SDK: \[SAI_BRIDGE.ERR\] mlnx_sai_bridge.c\[630\]- mlnx_bridge_port_sai_to_log_port_not_locked: Invalid bridge port type 4 - should be port or sub-port'
    - '.* ERR swss#orchagent: :- flushFDBEntries: Flushing FDB failed. rv:-5'
  Conditions:
    - Affected_test_cases:
      - vxlan/test_vxlan_decap.py::test_vxlan_decap[Removed]
      - vxlan/test_vnet_vxlan.py
      Redmine:
        - 2954778
      Branch:
        - 202111
        - master
        - 202211

- Errors_list:
    - '.* ERR teamd#tlm_teamd: :- get_dump: Can''t get dump for LAG ''PortChannel\d+''. Skipping'
  Conditions:
    - Affected_test_cases:
      - pc/test_po_update.py::test_po_update
      Redmine:
        - 2934692
      Branch:
        - 202111
        - master
        - 202211

- Errors_list:
    - '.*ERR teamd#tlm_teamd: :- process_add_queue:.*connect to teamd after 10 attempts. LAG.*'
  Conditions:
    - Affected_test_cases:
      - tests/sub_port_interfaces/test_sub_port_interfaces.py::TestSubPorts::test_admin_status_down_disables_forwarding[port_in_lag]
      Redmine:
        - 2910559
      Branch:
        - 202111

- Errors_list:
    - '.* teamd\[\d+\]: segfault at .* ip .* sp .* error 4 in libteam.so.5.6.0.*'
  Conditions:
    - Affected_test_cases:
      - tests/nightly/lag/test_lag.py
      Redmine:
        - 2910559
      Branch:
        - 202111
        - master
        - 202012
        - 202211

- Errors_list:
    - '.* ERR syncd#SDK: \[PORT_DB.ERR\] Failed to get SWID\(255\) type - Parameter Exceeds Range'
    - '.* ERR syncd#SDK: \[PORT.ERR\] SWID\(255\) type mismatch'
    - '.* ERR syncd#SDK: \[PORT.ERR\] SWID\(0\) type mismatch'
    - '.* ERR syncd#SDK: \[PORT.ERR\] Failed to retrieve counters values for prio \(\d\)'
    - '.* ERR syncd#SDK: \[PORT.ERR\] port_buff_cntr_get failed, for chip type CHIP_TYPE_SWITCH_SPECTRUM.*, err = Parameter Exceeds Range'
    - '.* ERR syncd#SDK: \[PORT.ERR\] port_tc_cntr_get failed, for chip type CHIP_TYPE_SWITCH_SPECTRUM.*, err = Parameter Exceeds Range'
    - '.* ERR syncd#SDK: \[SAI_BUFFER.ERR\] mlnx_sai_buffer.c\[\d+\]- mlnx_sai_get_ingress_priority_group_stats_ext: Failed to get port pg counters - Parameter Exceeds Range'
    - '.* ERR syncd#SDK: :- collectPriorityGroupCounters: PG_DROP_STAT_COUNTER: failed to get \d+/\d+ stats of PG 0x.*: -5'
    - '.* ERR syncd#SDK: \[PORT.ERR\] Failed to retrieve counters values for TC \(\d\)'
    - '.* ERR syncd#SDK: \[PORT.ERR\] port_tc_cntr_get failed, for chip type CHIP_TYPE_SPECTRUM.*, err = Parameter Exceeds Range'
    - '.* ERR syncd#SDK: \[PORT.ERR\] port_buff_cntr_get failed, for chip type CHIP_TYPE_SPECTRUM.*, err = Parameter Exceeds Range'
    - '.* ERR syncd#SDK: \[SAI_QUEUE.ERR\] mlnx_sai_queue.c\[\d+\]- mlnx_get_queue_statistics_ext: Failed to get port tc counters - Parameter Exceeds Range'
    - '.* ERR syncd#SDK: :- collectQueueCounters: QUEUE_STAT_COUNTER: failed to get stats of queue 0x.*: -5'
  Conditions:
    - Affected_test_cases:
      - tests/nightly/dynamic_port_breakout
      Redmine:
        - 2934289
      Branch:
        - 202111
        - master
        - 202211

- Errors_list:
    - '.* ERR memory_checker: \[memory_checker\] Failed to execute the command ''docker stats --no-stream --format \\{\\{.MemUsage\\}\\} .*''. Return code: ''1'''
  Conditions:
    - Affected_test_cases:
      - tests/nightly/fec/test_fec.py::TestFec::test_fec_bug_2705016
      - tests/nightly/fec/test_fec.py::TestFec::test_fec_capabilities_loopback_ports
      - tests/nightly/auto_negotition/test_auto_neg.py::TestAutoNeg::test_auto_neg_conf
      - tests/nightly/lag/test_lag.py::test_core_functionality_with_reboot
      Redmine:
        - 2966714
      Branch:
        - 202111
        - master
        - 202211

- Errors_list:
    - '.* ERR syncd#SDK: :- threadFunction: time span WD exceeded \d+ ms for create:SAI_OBJECT_TYPE_SWITCH:oid:0x.*'
    - '.* ERR syncd#SDK: :- logEventData: op: create, key: SAI_OBJECT_TYPE_SWITCH:oid:0x.*'
    - '.* ERR syncd#SDK: :- logEventData: fv: SAI_SWITCH_ATTR_FDB_EVENT_NOTIFY: 0x.*'
    - '.* ERR syncd#SDK: :- logEventData: fv: SAI_SWITCH_ATTR_PORT_STATE_CHANGE_NOTIFY: 0x.*'
    - '.* ERR syncd#SDK: :- logEventData: fv: SAI_SWITCH_ATTR_BFD_SESSION_STATE_CHANGE_NOTIFY: 0x.*'
    - '.* ERR syncd#SDK: :- logEventData: fv: SAI_SWITCH_ATTR_SWITCH_SHUTDOWN_REQUEST_NOTIFY: 0x.*'
    - '.* ERR syncd#SDK: :- setEndTime: event ''create:SAI_OBJECT_TYPE_SWITCH:oid:0x.*'' took \d+ ms to execute'
    - '.* ERR syncd#SDK: :- logEventData: fv: SAI_SWITCH_ATTR_INIT_SWITCH: true'
  Conditions:
    - Redmine:
      - 3172522
      Branch:
        - 202111
        - master
        - 202205
        - 202211

- Errors_list:
    - '.* ERR syncd#SDK: \[SAI_PORT.ERR\] mlnx_sai_port.c.*mlnx_get_port_stats_ext: Failed to wait for bulk counter read event.*'
    - '.* ERR syncd#SDK.*collectPortCounters: Failed to get stats of port*'
    - '.* ERR syncd#SDK: \[SAI_PORT.ERR\] mlnx_sai_port.c.* mlnx_port_stats_wait_for_bulk_read_event: Bulk read event status is not OK.*'
    - '.* ERR syncd#SDK: \[SAI_PORT.ERR\] mlnx_sai_port.c.*mlnx_port_stats_allocate_sx_bulk_buffer: Failed to create buffer: Driver.*Return Status is Non-Zero.*'
    - '.* ERR syncd#SDK: \[SAI_PORT.ERR\] mlnx_sai_port.c\[6757\]- mlnx_get_port_stats_ext: Failed to allocate SDK buffer.*'
    - '.* ERR swss#orchagent: :- wait: SELECT operation result: TIMEOUT on object_type_get_availability_response.*'
    - '.* ERR swss#orchagent: :- wait: failed to get response for object_type_get_availability_response.*'
    - '.* ERR swss#orchagent: :- on_switch_shutdown_request: Syncd stopped.*'
  Conditions:
    - Redmine:
      - 2942594
      Platform:
        - simx

- Errors_list:
    - '.* ERR syncd#SDK: \[SAI_PORT.ERR\] mlnx_sai_port.c\[\d+\]- mlnx_get_port_stats_ext: Failed to allocate SDK buffer.*'
  Conditions:
    - Redmine:
      - 3141564
      Platform:
        - simx

- Errors_list:
    - ".*ERR pmon#chassis_db_init: Fail to decode DMI /sys/firmware/dmi/entries/\\d+-\\d+/raw due to IndexError\\('list index out of range'\\)"
  Conditions:
    - Platform:
      - simx

- Errors_list:
    - '.*ERR syncd#SDK: \[SAI_OBJECT.ERR\] mlnx_sai_object.c\[\d+\]- .* Bulk read event status is not OK.*'
    - '.*ERR syncd#SDK: \[SAI_PORT.ERR\] mlnx_sai_port.c\[\d+\]- .* Failed to prepare bulk counter for port stats.'
    - '.*ERR syncd#SDK.*collectPortCounters: Failed to get stats of port*'
  Conditions:
    - Redmine:
      - 3154876
      Platform:
        - simx

- Errors_list:
    - '.*ERR syncd#SDK: \[SAI_BUFFER.ERR\] mlnx_sai_buffer.c\[\d+\].*Failed to prepare bulk counter for pg occupancy stats.*'
    - '.*ERR syncd#SDK: \[SAI_QUEUE\.ERR\] mlnx_sai_queue.c\[\d*\]- .*Failed to prepare bulk counter for queue stats.'
  Conditions:
    - Redmine:
      - 3356398
      Platform:
        - simx

- Errors_list:
    - '.* ERR syncd#SDK: \[SAI_LAG.ERR\] mlnx_sai_lag.c\[\d+\]- mlnx_hostif_reapply: Failed running.*'
    - '.* ERR syncd#SDK: \[SAI_LAG.ERR\] mlnx_sai_lag.c\[\d+\]- mlnx_remove_lag_member: Error reapplying host interface on port.*'
    - '.* ERR syncd#SDK: :- sendApiResponse: api SAI_COMMON_API_REMOVE failed in syncd mode: SAI_STATUS_FAILURE.*'
    - '.* ERR swss#orchagent: :- remove: remove status: SAI_STATUS_FAILURE.*'
    - '.* ERR swss#orchagent: :- removeLagMember: Failed to remove member.* from .*'
    - '.* ERR swss#orchagent: :- handleSaiRemoveStatus: Encountered failure in remove operation, exiting orchagent.*'
  Conditions:
    - Redmine:
        - 3141585
      Platform:
        - simx

- Errors_list:
    - '.* ERR syncd#SDK: \[SAI_BUFFER.ERR] mlnx_sai_buffer.c\[\d+\]- .* Failed to find.*'
    - '.* ERR syncd#SDK: :- exit_with_sai_failure: saisdkdump exited with SAI rc:.* Failed to create a switch .'
  Conditions:
    - Redmine:
        - 3160523
      Platform:
        - simx

- Errors_list:
    - '.*ERR sflow#hsflowd: device .* Get SIOCGIFFLAGS failed : No such device'
  Conditions:
    - Redmine:
        - 3160535
      Platform:
        - simx

- Errors_list:
    - '.*ERR wjhcli: :- requestDaemon: Timeout waiting for daemon to send data'
  Conditions:
    - Redmine:
        - 3160544
      Platform:
        - simx

- Errors_list:
    - '.*ERR syncd#SDK: \[SX_API_INIT.ERR\] Could not open SX-API client communication channel.'
    - '.*ERR syncd#SDK: \[SAI_SWITCH.ERR\] mlnx_sai_switch.c\[\d+\]- mlnx_connect_switch: mlnx_sai_switch.c\[\d+\]- mlnx_connect_switch: .* Communication Error.'
  Conditions:
    - Redmine:
        - 3160591
      Platform:
        - simx

- Errors_list:
    - '.* ERR pmon#thermalctld: Failed to read from file /var/run/hw-management/led/led_fan\d_capability - FileNotFoundError\(2, ''No such file or directory''\)'
  Conditions:
    - Redmine:
      - 2972123
      Platform:
      - x86_64-nvidia_sn2201-r0

- Errors_list:
    - '.* ERR swss#vlanmgrd: :- main: Runtime error: \/bin\/bash -c .*'
  Conditions:
    - Affected_test_cases:
      - tests/nightly/lag/test_lag.py::test_core_functionality_with_reboot
      Redmine:
      - 3014357

- Errors_list:
    - '.*ERR sonic_yang: Data Loading Failed:Duplicated instance of "profile_list" leaf-list.*'
    - '.*ERR ConfigMgmt: Data Loading Failed.*Duplicated instance of "profile_list" leaf-list.*'
  Conditions:
    - Affected_test_cases:
      - dhcp_relay/test_dhcpv6_relay.py::test_dhcp_relay_after_link_flap
      Redmine:
      - 2972065

- Errors_list:
    - '.* ERR syncd#SDK: :- guard: RedisReply catches system_error: command:.*Lua redis.* command arguments must be strings or integers.*Input\/output error.*'
    - '.* ERR syncd#SDK: :- runRedisScript: Caught exception while running Redis lua script: RedisReply catches system_error: command:.*Lua redis.* command arguments must be strings or integers.*Input\/output error.*'
    - '.* ERR syncd#SDK: :- guard: RedisReply catches system_error: command: .*attempt to perform arithmetic on local .*in_octets.* \(a boolean value\).*Input\/output error.*'
    - '.* ERR syncd#SDK: :- runRedisScript: Caught exception while running Redis lua script: RedisReply catches system_error: command:.*attempt to perform arithmetic on local.*'
  Conditions:
    - Redmine:
      - 2972668
      Platform:
        - simx

- Errors_list:
    - '.* ERR kernel: \[.*\] mlxsw_minimal 2-0048: Could not acquire lock.*'
    - '.* ERR kernel: \[.*\] hwmon hwmon\d+: Failed to query module temperature.*'
    - '.* ERR kernel: \[.*\] mlxsw_minimal \d+-0048: Failed to query temp sensor.*'
    - '.* ERR kernel: \[.*\] mlxsw_minimal 2-0048: Failed to query PWM.*'
    - '.* ERR kernel: \[.*\] mlxsw_minimal 2-0048: Failed to query fan.*'
    - '.* ERR pmon#thermalctld: Failed to read from file /run/hw-management/thermal/module.*_temp_fault - OSError.*'
  Conditions:
    - Redmine:
      - 2856406

- Errors_list:
    - '.* ERR syncd#SDK: \[SAI_PORT.ERR\] mlnx_sai_port.c\[\d+\]- mlnx_port_by_log_id: Failed lookup port config by log id.*'
    - '.* ERR syncd#SDK: \[SAI_QUEUE.ERR\] mlnx_sai_queue.c\[\d+\]- mlnx_queue_cfg_lookup: Filed to lookup queue by index \d+ on port log id.*'
    - '.* ERR syncd#SDK: :- collectQueueCounters: QUEUE_WATERMARK_STAT_COUNTER: failed to get stats of queue 0x.*: -9'
  Conditions:
    - Affected_test_cases:
      - tests/nightly/dynamic_port_breakout/test_dpb_speeds.py
      Redmine:
      - 2754703

- Errors_list:
    - '.* ERR swss#orchagent: message repeated \d+ times: .* :- removeLag: Failed to remove LAG PortChannel\d+, it is still in VLAN.*'
  Conditions:
    - Affected_test_cases:
      - tests/nightly/lag/test_lag.py
      Redmine:
      - 2825653

- Errors_list:
    - '.* ERR swss#orchagent: :- update: FdbOrch LEARN notification: Failed to locate vlan port from bv_id .*'
  Conditions:
    - Affected_test_cases:
      - tests/push_build_tests/L2/vlan/test_vlan.py::TestVLAN::test_vlan_trunk_mode
      - tests/push_build_tests/L2/vlan/test_vlan.py::TestVLAN::test_vlan_access_with_trunk_mode
      - tests/push_build_tests/general/wjh/test_wjh.py::test_l1_agg_drop
      - tests/push_build_tests/L2/vlan/test_vlan.py::TestVLAN::test_vlan_on_split_port
      - tests/nightly/lag/test_lag.py::test_core_functionality_with_reboot
      Redmine:
      - 3074216

- Errors_list:
    - '.* ERR swss#orchagent: :- update: FdbOrch MOVE notification: Failed to locate vlan port from bv_id .*'
  Conditions:
    - Affected_test_cases:
      - tests/push_build_tests/L2/vlan/test_vlan.py::TestVLAN::test_vlan_trunk_mode
      - tests/push_build_tests/L2/vlan/test_vlan.py::TestVLAN::test_vlan_access_with_trunk_mode
      - tests/push_build_tests/general/wjh/test_wjh.py::test_l1_agg_drop
      - tests/push_build_tests/L2/vlan/test_vlan.py::TestVLAN::test_vlan_on_split_port
      Redmine:
      - 3074230

- Errors_list:
    - '.* ERR swss#orchagent: :- update: Unsupported FDB Flush: .*'
  Conditions:
    - Affected_test_cases:
      - tests/push_build_tests/L2/vlan/test_vlan.py::TestVLAN::test_vlan_trunk_mode
      - tests/push_build_tests/L2/vlan/test_vlan.py::TestVLAN::test_vlan_access_with_trunk_mode
      - tests/push_build_tests/L2/vlan/test_vlan.py::TestVLAN::test_vlan_on_split_port
      - tests/push_build_tests/L2/vlan/test_vlan.py::TestVLAN::test_vlan_4094_5
      - tests/nightly/fdb/test_fdb_advance.py::TestFdbAdvance::test_fdb_item_be_removed_after_removing_corresponding_vlan
      Redmine:
      - 3074219

- Errors_list:
    - '.* ERR kernel.*Failed to query module temperature thresholds'
  Conditions:
    - Redmine:
        - 2915388

- Errors_list:
    - '.* WARNING syncd#SDK: \[SAI_SWITCH\.WARNING\] mlnx_sai_switch\.c\[\d+\]- event_thread_func: sx_api_host_ifc_recv on callback fd returned unknown port, waiting for next packet.*'
    - '.* WARNING syncd#SDK: message repeated \d+ times: \[ \[SAI_SWITCH\.WARNING\] mlnx_sai_switch\.c\[\d+\]- event_thread_func: sx_api_host_ifc_recv on callback fd returned unknown port, waiting for next packet\]'
  Conditions:
    - Redmine:
        - 3001584

- Errors_list:
    - '.* ERR syncd#SDK: \[SAI_UTILS.ERR\] mlnx_sai_utils.c\[\d+\]- mlnx_log_port_to_object: Failed to find log port \d+ in SAI DB'
  Conditions:
    - Affected_test_cases:
      - vxlan/test_vnet_vxlan.py
      Redmine:
      - 3001583
      Branch:
      - 202012

- Errors_list:
    - '.* ERR syncd#SDK: \[EMAD_RX_THREAD.ERR\] EMAD transaction FW error.*'
    - '.* ERR syncd#SDK: \[EMAD.ERR\] emad-send failed on register.*'
    - '.* ERR syncd#SDK: \[REG_BULK.ERR\] sx_reg_layer_sxd_reg_call - Error at access reg call reg_id.*'
    - '.* ERR syncd#SDK: \[REG_BULK.ERR\] __reg_bulk_post_completion_cb Error got in completion data sxd_status .*'
    - '.* ERR syncd#SDK: \[MGMT_LIB.ERR\] Slot .* Module .* Attr get, MCION GET failed.*'
  Conditions:
    - Affected_test_cases:
      - show_techsupport/test_techsupport.py
      - app_extension/test_app_extension_basic.py::test_app_techsupport_integration
      - tests/show_techsupport/test_auto_techsupport.py
      - tests/show_techsupport/test_techsupport_no_secret.py

- Errors_list:
    - '.* ERR dhclient\[\d+\]: send_packet: No such device or address'
    - '.* ERR dhclient\[\d+\]: dhclient\.c:\d+: Failed to send \d+ byte long packet over .* interface.*'
  Conditions:
    - Redmine:
      - 3006222
      Platform:
      - simx

- Errors_list:
    - '.* ERR dhclient\[\d+\]: receive_packet failed on .*: Network is down'
  Conditions:
    - Affected_test_cases:
      - tests/push_build_tests/L3/dhcp_relay/test_dhcp6_relay::test_dhcp6_relay_multiple_dhcp_servers
      - tests/push_build_tests/L3/dhcp_relay/test_dhcp6_relay::test_dhcp6_relay_remove_dhcp_server
      Platform:
        - simx

- Errors_list:
    - '.* ERR systemd\[\d+\]: Failed to start what-just-happened container'
  Conditions:
    - Affected_test_cases:
      - tests/push_build_tests/L3/static_route/test_static_route.py::test_basic_static_route
      - tests/push_build_tests/general/wjh/test_wjh.py
      - tests/push_build_tests/system/test_cpu_ram_hdd_usage.py
      - tests/push_build_tests/L3/dhcp_relay/test_dhcp_relay.py
      - tests/push_build_tests/L3/dhcp_relay/test_dhcp6_relay.py
      Redmine:
      - 3038334

- Errors_list:
    - ".* ERR bgp#bgpcfgd: Peer .*: Can't update the peer. Only 'admin_status' attribute is supported"
    - '.* ERR swss#intfmgrd: :- setIntfIp: Command .*\/sbin\/ip address "add" .* failed with rc 2'
    - '.* ERR swss#intfmgrd: :- setIntfIp: Command .*\/sbin\/ip -6 address "add" .* failed with rc 2'
    - '.* ERR syncd#SDK: \[SX_API_COS.ERR\] Port buffers configuration is not supported for LAG'
    - '.* ERR syncd#SDK: \[SAI_PORT.ERR\] mlnx_sai_port\.c\[\d+\]- mlnx_port_qos_map_.* Failed to get prio to buff qos map - Parameter Error'
    - '.* ERR syncd#SDK: \[SAI_QOS_MAPS.ERR\] mlnx_sai_qosmaps.c\[\d+\]- mlnx_qos_map_list_set: Failed to update port \d+ with new QoS map'
    - '.* ERR syncd#SDK: \[SAI_UTILS.ERR\] mlnx_sai_utils.c\[\d+\]- sai_set_attribute: Failed set attrib dispatch'
    - '.* ERR syncd#SDK: :- sendApiResponse: api SAI_COMMON_API_SET failed in syncd mode: SAI_STATUS_INVALID_PARAMETER'
    - '.* ERR syncd#SDK: :- processQuadEvent: VID: oid:.* RID: oid:.*'
    - '.* ERR syncd#SDK: :- processQuadEvent: attr: SAI_QOS_MAP_ATTR_MAP_TO_VALUE_LIST: .*'
    - '.* ERR swss#orchagent: :- modifyQosItem: Failed to modify map. status:.*'
    - '.* ERR swss#orchagent: :- processWorkItem: Failed to set \[.*_MAP:AZURE\]'
    - '.* ERR swss#orchagent: :- doTask: Failed to process QOS task, drop it'
  Conditions:
    - Affected_test_cases:
      - sub_port_interfaces/test_show_subinterface.py
      - sub_port_interfaces/test_sub_port_interfaces.py
      - sub_port_interfaces/test_sub_port_l2_forwarding.py
      Redmine:
      - 3050436
      Branch:
      - master
      - 202111
      - 202211

- Errors_list:
    - '.* ERR syncd#SDK: \[FDB_UC\.ERR\] FDB: not supported fid type \(\d+\) for fid \(\d+\)\. \(Success\)'
  Conditions:
    - Affected_test_cases:
      - sub_port_interfaces
      Redmine:
      - 3224978

- Errors_list:
    - '.* ERR swss#orchagent: message repeated \d+ times: \[ :- update: Failed to get port by bridge port ID 0x.*.\]'
  Conditions:
    - Affected_test_cases:
      - tests/nightly/lag/test_lag.py::test_core_functionality_with_reboot
      Redmine:
      - 3030960
      Branch:
      - 202012
      - 202111

- Errors_list:
    - '.* ERR wjhd: :- removeBufferConfiguration: Fail to deinit SDK telemetry, error: \[4\]: \[Communication Error\]'
    - '.* ERR wjhd\[\d+\]: \[WJH_LIB.ERROR\s+\].*'
    - '.* ERR wjhd\[\d+\]: :- deleteDropGroupReason:.*'
    - '.* ERR wjhd\[\d+\]: :- destroy: Failed to destroy  channel.*'
    - '.* ERR what-just-happened#wjhd\[\d+\]: :- destroy: Failed to destroy wjh channel.*'
    - '.* ERR wjhd\[\d+\]: :- deinitialize: Failed to de-initialize WJH library, status 1.*'

  Conditions:
    - Affected_test_cases:
      - autorestart/test_container_autorestart.py

- Errors_list:
    - '.*ERR wjhcli: :- connect: connect\(\) failed to connect to daemon: No such file or directory.*'
  Conditions:
    - Redmine:
        - 3044595

- Errors_list:
    - ".*Failed to add device '/dev/sda\\d*' to watch: Operation not permitted.*"
    - ".*Failed to add device '/dev/loop\\d*' to watch: Operation not permitted.*"
  Conditions:
    - Redmine:
        - 3044633

- Errors_list:
    - ".*ERR pmon#psud: sensor -s does not recover PSU threshold sensor after 5 seconds.*"
  Conditions:
    - Redmine:
        - 3042689

- Errors_list:
    - '.*ERR pmon#thermalctld: Failed to read from file /var/run/hw-management/thermal/psu1_fan_max - ValueError\("invalid literal for int\(\) with base 10:.*"\).*'
  Conditions:
    - Redmine:
        - 3045534

- Errors_list:
    - '.*ERR pmon#xcvrd.*: Expected to get redis type \d+ got type \d+, err: NON-STRING-REPLY.*'
  Conditions:
    - Redmine:
        - 3016938

- Errors_list:
    - '.* ERR pmon#xcvrd: Receive PMPE error event on module \d+: status 3 error type 1.*'
  Conditions:
    - Redmine:
      - 2976288

- Errors_list:
    - '.* ERR pmon#thermalctld: Failed to get minimum ambient temperature, use pessimistic instead.*'
  Conditions:
    - Affected_test_cases:
      - platform_tests/test_platform_info.py::test_show_platform_temperature_mocked
      Redmine:
      - 3058264

- Errors_list:
    - '.* ERR syncd#SDK:.*command \d+ not found in api_cmd_db.*'
  Conditions:
    - Affected_test_cases:
      - platform_tests/sfp/test_sfputil.py::test_check_sfputil_reset
      Redmine:
      - 3068928

- Errors_list:
    - '.* ERR hostcfgd: sonic-kdump-config --num_dumps.*'
    - '.* ERR dhclient\[\d+\]: receive_packet failed on.*'
    - '.* ERR dhclient\[\d+\]: dhclient.c:\d+: Failed to send.*'
    - '.* ERR dhclient\[\d+\]: send_packet.*: No such device*'
    - '.* ERR dhclient\[\d+\]: dhc\d+: send_packet\d+.*'
  Conditions:
    - Affected_test_cases:
      - tests/nightly/logging/test_log_analyzer_errors_during_deploy_sonic.py
      Redmine:
      - 3061632

- Errors_list:
    - '.*ERR systemd\[\d+\]: Failed to start Rotate log files.*'
  Conditions:
    - Affected_test_cases:
      - tests/nightly/logging/test_log_analyzer_errors_during_deploy_sonic.py
      Redmine:
      - 3320283

- Errors_list:
    - '.*ERR watchdogutil: Failed to get watchdog module.*'
  Conditions:
    - Affected_test_cases:
      - tests/nightly/logging/test_log_analyzer_errors_during_deploy_sonic.py
      Redmine:
      - 3273006

- Errors_list:
    - '.* INFO kernel: \[   \d+\.\d+\] orchagent\[\d+\]: segfault at 60 ip \S+ sp \S+ error 4 in libc-\d+.\d+.so\[\S+\+\S+\].*'
    - '.* ERR hostcfgd: sudo systemctl start pmon\.service - failed: return code - 1, output:#012None.*'
  Conditions:
    - Affected_test_cases:
      - tests/nightly/logging/test_log_analyzer_errors_during_deploy_sonic.py
      Redmine:
      - 3168487

- Errors_list:
    - '.* ERR .*rsyslogd: omfwd\/udp: socket \d+: sendto\(\) error: Network is unreachable.*'
    - '.* ERR .*rsyslogd: omfwd: socket \d+: error 101 sending via udp: Network is unreachable.*'
  Conditions:
    - Redmine:
      - 3168474
      GitHub:
      - https://github.com/sonic-net/sonic-buildimage/issues/6675

- Errors_list:
    - '.* ERR .*#rsyslogd: imfile: error reading state file for .*'
  Conditions:
    - Redmine:
      - 3186637

- Errors_list:
    - '.* ERR systemd\[\d\]: \/etc\/systemd\/system\/mst\.service:97: Invalid section header.*'
  Conditions:
    - Redmine:
      - 3168291

- Errors_list:
    - '.* ERR healthd: Container folder does not exist.*'
  Conditions:
    - Affected_test_cases:
      - tests/nightly/app_extension/test_app_extension_upgrade.py
      Redmine:
      - 3099493

- Errors_list:
    - '.*ERR lldp#lldpmgrd\[\d+\]: unknown operation.*'
    - '.*ERR syncd#SDK: \[SAI_PORT.ERR\] mlnx_sai_port.c\[\d+\]- mlnx_port_by_log_id: Failed lookup port config.*'
    - '.*ERR syncd#SDK: \[SAI_QUEUE.ERR\] mlnx_sai_queue.c\[\d+\]- mlnx_queue_cfg_lookup: Filed to lookup queue.*'
    - '.*ERR syncd#SDK: :- collectQueueCounters: QUEUE_WATERMARK_STAT_COUNTER: failed to get stats of queue.*'
  Conditions:
    - Affected_test_cases:
      - tests/nightly/dynamic_port_breakout/test_dpb_all_ports.py
      Redmine:
      - 3099410

- Errors_list:
    - '.*ERR swss#orchagent: :- mcCounterCheck: Invalid port oid.*'
    - '.*ERR swss#orchagent: :- pfcFrameCounterCheck: Invalid port oid.*'
  Conditions:
    - Affected_test_cases:
      - tests/nightly/dynamic_port_breakout/test_dpb_all_ports.py
      Redmine:
      - 3327983

- Errors_list:
    - '.*ERR syncd#SDK: :- setEndTime: event .?create:SAI_OBJECT_TYPE_SWITCH.*'
    - '.*ERR syncd#SDK: :- logEventData: op: create, key: SAI_OBJECT_TYPE_SWITCH.*'
    - '.*ERR syncd#SDK: :- logEventData: fv: SAI_SWITCH_ATTR_FDB_EVENT_NOTIFY.*'
    - '.*ERR syncd#SDK: :- logEventData: fv: SAI_SWITCH_ATTR_PORT_STATE_CHANGE_NOTIFY.*'
    - '.*ERR syncd#SDK: :- logEventData: fv: SAI_SWITCH_ATTR_SWITCH_SHUTDOWN_REQUEST_NOTIFY.*'
  Conditions:
    - Affected_test_cases:
      - tests/nightly/fec/test_fec.py
      Redmine:
      - 3061632

- Errors_list:
    - '.*ERR bgp#bgpcfgd: Directory: Can.?t remove key .?PortChannel.*'
    - '.*ERR bgp#bgpcfgd: Directory: Can.?t remove key .?Vlan.*'
  Conditions:
    - Affected_test_cases:
      - tests/nightly/lag/test_lag.py
      Redmine:
      - 3101252

- Errors_list:
    - '.* ERR pmon#xcvrd: Receive PMPE unknown event on module \d+: status 5'
    - '.* ERR pmon#xcvrd: message repeated \d+ times: \[ Receive PMPE unknown event on module \d+: status 5\]'
  Conditions:
    - Affected_test_cases:
      - tests/nightly/lag/test_lag.py::test_lag_members_scale
      - tests/nightly/lag/test_lag.py::test_lags_scale
      Redmine:
      - 3101770
      Platform:
      - sn2201

- Errors_list:
    - '.* ERR healthd: system_service''state'''
  Conditions:
    - Affected_test_cases:
      - tests/nightly/lag/test_lag.py::test_lags_scale
      - tests/push_build_tests/general/qos/test_qos_reload.py::test_qos_reload_ports
      Redmine:
      - 3102116

- Errors_list:
    - '.* WARNING kernel: \[.+\] get_operation_tlv: Err: Got status 0x4 for register 0x9053'
  Conditions:
    - Redmine:
      - 3105020

- Errors_list:
    - '.* WARNING kernel: \[.*\] get_operation_tlv: Err: Got status .* for register .*'
  Conditions:
    - Affected_test_cases:
      - tests/nightly/app_extension/test_app_extension_reboot.py::test_app_start_delay_after_reboot
      - tests/nightly/auto_negotition/test_auto_neg.py::TestAutoNeg::test_auto_neg_conf
      - tests/nightly/lag/test_lag.py::test_lag_members_scale
      - platform_tests/fwutil/test_fwutil.py::test_fwutil_install_file
      - platform_tests/fwutil/test_fwutil.py::test_fwutil_install_url
      Redmine:
      - 3110376
      Branch:
      - master
      - 202211

- Errors_list:
    - '.* ERR kernel.* PMBus status register not found'
    - '.* ERR kernel.* Chip identification failed'
    - '.* WARNING kernel.* probe of .* failed with error -22'
  Conditions:
    - Affected_test_cases:
      - platform_tests/fwutil/test_fwutil.py::test_fwutil_install_url
      - platform_tests/fwutil/test_fwutil.py::test_fwutil_install_file
      - platform_tests/fwutil/test_fwutil.py::test_fwutil_update_current
      Platform:
      - 4600c
      Reason: "when 4600c downgrade CPLD these errors are expected "

- Errors_list:
    - '.* ERR pmon#xcvrd: :- checkReplyType: Expected to get redis type \d+ got type \d+, err: NON-STRING-REPLY'
    - '.* ERR pmon#xcvrd: :- guard: RedisReply catches system_error: command: .*, reason: Expected to get redis type \d+ got type \d+, err: NON-STRING-REPLY: Input/output error'
  Conditions:
    - Affected_test_cases:
      - tests/nightly/lag/test_lag.py::test_lag_members_scale
      - tests/nightly/lag/test_lag.py::test_lags_scale
      Redmine:
      - 3120567
      Platform:
      - 2201

- Errors_list:
    - '.* ERR pmon#thermalctld: Failed to read from file /var/run/hw-management/thermal/fan\d_speed_get - OSError\(6, ''No such device or address''\)'
  Conditions:
    - Affected_test_cases:
      - show_techsupport/test_auto_techsupport.py::TestAutoTechSupport
      Redmine:
      - 3216785
      Branch:
      - 202205

- Errors_list:
    - ".* ERR ntpd\\[\\d+\\]: leapsecond file \\('/usr/share/zoneinfo/leap-seconds.list'\\): expired 1 day ago.*"
    - ".* ERR ntpd\\[\\d+\\]: leapsecond file \\('/usr/share/zoneinfo/leap-seconds.list'\\): expired less than \\d+ days ago.*"
  Conditions:
    - Affected_test_cases:
      - tests/nightly/logging/test_log_analyzer_errors_during_deploy_sonic.py::test_check_errors_in_log_during_deploy_sonic_image
      Redmine:
      - 3120607

- Errors_list:
    - '.* ERR show: Fail to decode DMI /sys/firmware/dmi/entries/2-0/raw due to PermissionError\(13, ''Permission denied''\)'
  Conditions:
    - Affected_test_cases:
      - tests/nightly/logging/test_log_analyzer_errors_during_deploy_sonic.py::test_check_errors_in_log_during_deploy_sonic_image
      Redmine:
      - 3120621
      Platform:
      - 2201

- Errors_list:
    - '.* ERR syncd#SDK: \[MGMT_LIB\.ERR\] Slot \[\d+\] Module \[\d+\] has logport \[.*\] in enabled state.*'
    - '.* ERR syncd#SDK: \[SDK_MGMT_LIB\.ERR\] Failed in __sdk_mgmt_phy_module_pwr_attr_set, error:.*'
    - '.* ERR pmon#-c: Error occurred when setting power mode for SFP module \d+, slot \d+, error code 1.*'
  Conditions:
    - Affected_test_cases:
      - platform_tests/sfp/test_sfputil.py::test_check_sfputil_low_power_mode
    - Redmine:
      - 3123080
      Branch:
      - master
      - 202211

- Errors_list:
    - '.* ERR syncd#SDK: :- translateVidToRid: unable to get RID for VID oid:0x.*'
  Conditions:
    - Redmine:
      - 3001563
      Branch:
      - master
      - 202111
      - 202205
      - 202211

# #3071827: Won't fix
- Errors_list:
    - '.* ERR radv#radvd\[\d+\]: Vlan1000 not found: No such device.*'
  Conditions:
    - Affected_test_cases:
      - autorestart/test_container_autorestart.py

- Errors_list:
    - '.* ERR pmon#psud: Fail to read model number: No key PN_VPD_FIELD in VPD /var/run/hw-management/eeprom/psu1_vpd.*'
    - '.* ERR pmon#psud: Fail to read serial number: No key SN_VPD_FIELD in VPD /var/run/hw-management/eeprom/psu1_vpd.*'
    - '.* ERR pmon#psud: Fail to read revision: No key REV_VPD_FIELD in VPD /var/run/hw-management/eeprom/psu1_vpd.*'
    - ".* ERR healthd: system_service'state' .*"
    - '.* ERR pmon#psud: Failed to read from file /var/run/hw-management/eeprom/psu1_vpd - UnicodeDecodeError.*'
  Conditions:
    - Redmine:
      - 3130554
      Platform:
      - msn2700

- Errors_list:
    - '.* ERR swss#orchagent: :- meta_sai_on_port_state_change_single: data.port_id oid.* has unexpected type: SAI_OBJECT_TYPE_NULL, expected PORT, BRIDGE_PORT or LAG.*'
    - '.* ERR swss#orchagent: :- handlePortStatusChangeNotification: Failed to get port object for port id.*'
    - '.* ERR swss#orchagent: :- doTask: Failed to get port object for port id.*'
  Conditions:
    - Redmine:
      - 3131583

- Errors_list:
    - '.*ERR pmon#thermalctld: Failed to read from file \/var\/run\/hw-management\/thermal\/fan.*'
    - '.*ERR pmon#thermalctld: Failed to read fan direction from \/var\/run\/hw-management\/thermal\/fan.*'
  Conditions:
    - Redmine:
      - 3537920
      Platform:
      - 2210

# Below error should be ignored permanently for this test(issue: 3131511 related to 2200131 which is "Won't fix"
- Errors_list:
    - '.* ERR pmon#xcvrd: Receive PMPE error event on module \d+: status \d+ error type \d+.*'
    - '.* ERR pmon#xcvrd: Got unrecognized event \d+, ignored.*'
    - '.* ERR pmon#xcvrd: Ethernet\d+: Got SFP error event 19'
  Conditions:
    - Affected_test_cases:
      - platform_tests/sfp/test_sfputil.py

- Errors_list:
    - '.* ERR swss#orchagent: :- recordingFileReopen: failed to open recording file : No such file or directory.*'
  Conditions:
    - Redmine:
      - 3144113
    - Branch:
      - 202205

- Errors_list:
    - '.* WARNING kernel:.*get_operation_tlv: Err: Got status 0x4 for register 0x9029.*'
  Conditions:
    - Affected_test_cases:
      - show_techsupport/test_techsupport.py
      - show_techsupport/test_auto_techsupport.py
      - tests/nightly/app_extension/test_app_extension_basic.py::test_app_techsupport_integration
      - tests/nightly/show_techsupport/test_techsupport.py::test_techsupport_mellanox_sdk_dump
    - Redmine:
      - 3149713

- Errors_list:
    - '.* ERR syncd#SDK: \[SX_API_INTERNAL.ERR\] Failed command read at communication channel: Connection reset by peer.*'
    - '.* WARNING syncd#SDK: :- discover: skipping since it causes crash: SAI_STP_ATTR_BRIDGE_ID.*'
  Conditions:
    - Affected_test_cases:
      -  bgp/test_traffic_shift.py
    - Redmine:
      - 3067340

- Errors_list:
    - '.* ERR swss#orchagent: :- wait: SELECT operation result: TIMEOUT on getresponse.*'
    - '.* ERR swss#orchagent: :- wait: failed to get response for getresponse.*'
    - '.* ERR swss#orchagent: :- create: create status: SAI_STATUS_FAILURE.*'
    - '.* ERR swss#orchagent: :- main: Failed to create a switch, rv:-1.*'
  Conditions:
    - Affected_test_cases:
      - tests/nightly/logging/test_log_analyzer_errors_during_deploy_sonic.py
      Redmine:
      - 3440734

- Errors_list:
    - '.* ERR syncd#SDK: :- guard: RedisReply catches system_error.*attempt to perform arithmetic on local.*in_octets.*\(a boolean value\).*'
    - '.* ERR syncd#SDK: :- runRedisScript: Caught exception while running Redis lua script: RedisReply catches system_error.*attempt to perform arithmetic on local.*in_octets.*\(a boolean value\).*'
    - '.* ERR syncd#SDK: :- guard: RedisReply catches system_error.*Lua redis\(\) command arguments must be strings or integers.*'
    - '.* ERR syncd#SDK: :- runRedisScript: Caught exception while running Redis lua script: RedisReply catches system_error.*Lua redis\(\) command arguments must be strings or integers.*'
  Conditions:
    - Redmine:
      - 3166325

- Errors_list:
    - '.* ERR hw-management: mlxreg_io is not loaded.*'
  Conditions:
    - Redmine:
      - 3177482

- Errors_list:
    - '.* ERR vnet_route_check.py:.*results.*missed_in_asic_db_routes.*Vnet.*'
    - '.* ERR vnet_route_check.py:  Vnet Route Mismatch reported.*'
  Conditions:
    - Affected_test_cases:
      - vxlan/test_vnet_route_leak.py
      Redmine:
      - 3165489

- Errors_list:
    - '.* ERR bgp#fpmsyncd: :- onRouteMsg: Invalid VRF name .*ifindex \d+.*'
  Conditions:
    - Redmine:
        - 3221776

- Errors_list:
    - '.* ERR dhcp_relay#dhcp6relay: bind: Failed to bind socket to link local ipv6 address on interface Vlan1000 after 6 retries with Success.*'
  Conditions:
    - Affected_test_cases:
      - tests/nightly/logging/test_log_analyzer_errors_during_deploy_sonic.py
      Redmine:
      - 3136253

- Errors_list:
    - '.* ERR syncd#SDK: :- processSwitches: failed to create switch RID: SAI_STATUS_FAILURE.*'
    - '.* ERR syncd#SDK: :- run: Runtime error during syncd init: :- processSwitches: failed to create switch RID: SAI_STATUS_FAILURE.*'
    - '.* ERR syncd#SDK: \[SAI_SWITCH.ERR\] mlnx_sai_switch.c.*- mlnx_dvs_mng_stage: Failed running.*ip link set address.*dev swid0_eth > \/dev\/null 2\>&1.*'
    - '.* ERR kernel:.*sx_core: create EMAD sdq 0 failed. err: -16.*'
    - '.* ERR syncd#SDK: \[SAI_SWITCH.ERR\] mlnx_sai_switch.c.*- mlnx_resource_mng_stage: mlnx_sai_switch.c.*mlnx_resource_mng_stage: failed to set pci profile in asic, error: Device or resource busy.*'
    - '.* ERR syncd#SDK: :- sendApiResponse: api SAI_COMMON_API_CREATE failed in syncd mode: SAI_STATUS_FAILURE'
    - '.* ERR syncd#SDK: :- processQuadEvent: attr: SAI_SWITCH_ATTR_INIT_SWITCH: true.*'
    - '.* ERR syncd#SDK: :- processQuadEvent: attr: SAI_SWITCH_ATTR_FDB_EVENT_NOTIFY.*'
    - '.* ERR syncd#SDK: :- processQuadEvent: attr: SAI_SWITCH_ATTR_PORT_STATE_CHANGE_NOTIFY.*'
    - '.* ERR syncd#SDK: :- processQuadEvent: attr.*SAI_SWITCH_ATTR_SWITCH_SHUTDOWN_REQUEST_NOTIFY.*'
    - '.* ERR swss#orchagent: :- create: create status: SAI_STATUS_FAILURE.*'
    - '.* ERR swss#orchagent: :- main: Failed to create a switch, rv:-1.*'
  Conditions:
    - Affected_test_cases:
      - autorestart/test_container_autorestart.py::test_containers_autorestart
      Redmine:
      - 3116539

- Errors_list:
    - '.* ERR syncd#SAI: \[SAI_SWITCH.ERR\] mlnx_sai_switch.c.*- sai_db_create: mlnx_sai_switch.c.*- sai_db_create: Shared memory of the SAI already exists, destroying it and re-creating.*'
  Conditions:
    - Affected_test_cases:
      - bgp/test_traffic_shift.py
      Redmine:
      - 3144720

- Errors_list:
    - '.*sonic ERR hostcfgd: sonic-kdump-config --disable - failed: return code.*output:#.*None.*'
    - '.*sonic ERR hostcfgd: sonic-kdump-config --memory.*failed: return code.*, output:#.*None.*'
  Conditions:
    - Affected_test_cases:
      - tests/nightly/logging/test_log_analyzer_errors_during_deploy_sonic.py
      Redmine:
      - 2951102

- Errors_list:
    - ".*ERR mellanox_buffer_migrator: Trying to get DEVICE_METADATA from DB but doesn't exist, skip migration.*"
  Conditions:
    - Affected_test_cases:
      - tests/nightly/logging/test_log_analyzer_errors_during_deploy_sonic.py
      Redmine:
      - 3278707

- Errors_list:
    - '.* ERR sflow#port_index_mapper: \<built-in function Select_select\> returned a result with an error set'
  Conditions:
    - Affected_test_cases:
      - tests/push_build_tests/general/qos/test_qos_reload.py::test_qos_reload_ports
      Redmine:
      - 3172649

- Errors_list:
    - '.* ERR pmon#chassis_db_init: Fail to decode DMI /sys/firmware/dmi/entries/2-0/raw due to IndexError\(''list index out of range''\)'
  Conditions:
    - Affected_test_cases:
      - tests/push_build_tests/general/qos/test_qos_reload.py::test_qos_reload_ports
      Redmine:
      - 3430646
      Platform:
      - simx

- Errors_list:
    - '.* ERR syncd#SDK: :- addObject: Queue Counter RID oid.*provide the statistic.*'
  Conditions:
    - Redmine:
      - 2876749
      Branch:
      - master
      - 202211

- Errors_list:
    - '.*ERR syncd#SDK: \[SAI_MIRROR.ERR\] mlnx_sai_mirror.c.*- mlnx_mirror_policer_sx_attrs_validate: Span policer must be SAI_POLICER_COLOR_SOURCE_BLIND.*'
    - '.*ERR syncd#SDK: :- sendApiResponse: api SAI_COMMON_API_CREATE failed in syncd mode:.*'
    - '.*ERR syncd#SDK: :- processQuadEvent: attr: SAI_MIRROR_SESSION_ATTR_MONITOR_PORT: oid:.*'
    - '.*ERR syncd#SDK: :- processQuadEvent: attr: SAI_MIRROR_SESSION_ATTR_TYPE: SAI_MIRROR_SESSION_TYPE_ENHANCED_REMOTE.*'
    - '.*ERR syncd#SDK: :- processQuadEvent: attr: SAI_MIRROR_SESSION_ATTR_ERSPAN_ENCAPSULATION_TYPE: SAI_ERSPAN_ENCAPSULATION_TYPE_MIRROR_L3_GRE_TUNNEL.*'
    - '.*ERR syncd#SDK: :- processQuadEvent: attr: SAI_MIRROR_SESSION_ATTR_IPHDR_VERSION.*'
    - '.*ERR syncd#SDK: :- processQuadEvent: attr: SAI_MIRROR_SESSION_ATTR_TOS:.*'
    - '.*ERR syncd#SDK: :- processQuadEvent: attr: SAI_MIRROR_SESSION_ATTR_TTL.*'
    - '.*ERR swss#orchagent: :- create: create status.*'
    - '.*ERR swss#orchagent: :- activateSession: Failed to activate mirroring session mirror_session_dscp.*'
    - '.*ERR swss#orchagent: :- handleSaiCreateStatus: Encountered failure in create operation, exiting orchagent, SAI API: SAI_API_MIRROR, status:.*'
    - '.*ERR syncd#SDK: :- processQuadEvent: attr: SAI_MIRROR_SESSION_ATTR_SRC_IP_ADDRESS.*'
    - '.*ERR syncd#SDK: :- processQuadEvent: attr: SAI_MIRROR_SESSION_ATTR_DST_IP_ADDRESS:.*'
    - '.*ERR syncd#SDK: :- processQuadEvent: attr: SAI_MIRROR_SESSION_ATTR_SRC_MAC_ADDRESS.*'
    - '.*ERR syncd#SDK: :- processQuadEvent: attr: SAI_MIRROR_SESSION_ATTR_DST_MAC_ADDRESS:.*'
    - '.*ERR syncd#SDK: :- processQuadEvent: attr: SAI_MIRROR_SESSION_ATTR_GRE_PROTOCOL_TYPE.*'
    - '.*ERR syncd#SDK: :- processQuadEvent: attr: SAI_MIRROR_SESSION_ATTR_POLICER: oid.*'
  Conditions:
    - Affected_test_cases:
      - generic_config_updater/test_monitor_config.py
      Redmine:
      - 3174870

- Errors_list:
    - '.*ERR swss#orchagent: :- createEntry: detection_time missing.*'
    - '.*ERR swss#orchagent: :- doTask: Failed to process PFC watchdog SET task, invalid entry.*'
    - '.*ERR swss#orchagent: :- createEntry: Failed to parse PFC Watchdog Ethernet.* configuration\. Unknown attribute NULL.*'
  Conditions:
    - Affected_test_cases:
      - generic_config_updater/test_pfcwd_interval.py::test_stop_pfcwd
      Redmine:
      - 3449977

- Errors_list:
    - ".* ERR teamd#tlm_teamd: :- process_add_queue: Can't connect to teamd after 10 attempts. LAG.*"
  Conditions:
    - Affected_test_cases:
      - iface_loopback_action
    - Redmine:
      - 3109165

- Errors_list:
    - ".* ERR swss#intfmgrd: :- main: Runtime error: \/sbin\/ip link set .*mtu.*"
  Conditions:
    - Affected_test_cases:
      - iface_loopback_action/test_iface_loopback_action.py::test_loopback_action_reload
    - Redmine:
      - 3259489

- Errors_list:
    - '.* ERR syncd#SDK: \[SX_API_INTERNAL\.ERR\] Invalid handle: handle is NULL'
    - '.* ERR syncd#SDK: \[SAI_SWITCH\.ERR\] mlnx_sai_switch\.c\[\d+\]- mlnx_switch_fdb_record_check_and_age: Failed to get port .+ learn mode - Invalid Handle'
  Conditions:
    - Affected_test_cases:
      - iface_loopback_action/test_iface_loopback_action.py::test_loopback_action_reload
      Redmine:
      - 3308748
      Branch:
      - 202205

- Errors_list:
    - ".* sai_db_create: Shared memory of the SAI already exists, destroying it and re-creating.*"
  Conditions:
    - Redmine:
      - 3144720


- Errors_list:
    - '.* WARNING kernel: .* probe of 5-006a failed with error -22.*'
  Conditions:
    - Affected_test_cases:
      - platform_tests/fwutil/test_fwutil.py::test_fwutil_install_file
    - Redmine:
      - 3278778

- Errors_list:
    - ".* ERR hostcfgd: sudo systemctl enable eventd.timer - failed: return code - 1, output:#.*None.*"
    - '.* ERR eventd#eventd: :- main: ERR:The eventd service started.*'
    - '.* ERR eventd#eventd: :- deserialize: deserialize Failed: input stream errorstr.*data type: std::__cxx11::basic_string<char, std::char_traits<char>, std::allocator<char> >&.*'
    - '.* ERR eventd#eventd: :- zmq_read_part: Failed to deserialize part rc=-2.*'
    - '.* ERR eventd#eventd: :- zmq_read_part: last:errno.*'
    - '.* ERR eventd#eventd: :- zmq_message_read: Failure to read part1 rc.*'
    - '.* ERR eventd#eventd: :- zmq_message_read: last:errno.*'
  Conditions:
    - Affected_test_cases:
      - tests/push_build_tests/general/qos/test_qos_reload.py
      - platform_tests/fwutil/test_fwutil.py::test_fwutil_install_url
      - platform_tests/fwutil/test_fwutil.py::test_fwutil_update_current
      - tests/nightly/logging/test_log_analyzer_errors_during_deploy_sonic.py::test_check_errors_in_log_during_deploy_sonic_image
      - tests/nightly/lag/test_lag.py::test_lags_scale
    - Redmine:
      - 3201740

- Errors_list:
    - '.* ERR syncd#SDK: \[SAI_UTILS.ERR\] mlnx_sai_utils.c.*- mlnx_object_to_type: Expected object SCHEDULER_GROUP got QUEUE.*'
    - '.* ERR swss#orchagent: :- getSchedulerGroup: Failed to get child list for scheduler group:.* of port:Ethernet.*'
    - '.* ERR swss#orchagent: :- applySchedulerToQueueSchedulerGroup: Failed to find a scheduler group for port: Ethernet.* queue:.*'
    - '.* ERR swss#orchagent: :- handleQueueTable: Failed setting field:scheduler to port:Ethernet.*, queue:\d+, line:.*'
    - '.* ERR swss#orchagent: :- doTask: Failed to process QOS task, drop it.*'
  Conditions:
    - Affected_test_cases:
      - tests/push_build_tests/general/qos/test_qos_reload.py
    - Redmine:
      - 3205239

- Errors_list:
    - '.* ERR syncd#SAI: \[SAI_OBJECT.ERR\] mlnx_sai_object.c\[\d+\]- sai_object_type_get_availability: Can''t get object type availability before creating a switch'
    - '.* ERR syncd#SAI: message repeated \d+ times: \[ \[SAI_OBJECT.ERR\] mlnx_sai_object.c\[\d+\]- sai_object_type_get_availability: Can''t get object type availability before creating a switch\]'
  Conditions:
    - Redmine:
        - 3358104
      Platform:
        - arm64-nvda_bf-mbf2h536c
        - arm64-nvda_bf-9009d3b600cvaa

- Errors_list:
    - '.* ERR syncd#SDK: :- collectData: Failed to get stats of Port Counter.*'
  Conditions:
    - Redmine:
        - 3205278
      Platform:
        - simx

- Errors_list:
    - '.* ERR pmon#xcvrd: Error! Unable to read data for \d+ port, page \d+ offset \d+, rc = 1, err msg: Sending access register.*'
  Conditions:
    - Redmine:
      - 3213401

- Errors_list:
    - '.* ERR .*echo_receive: failing to read echo rc.*'
    - '.* ERR .*echo_receive: last:errno=.*'
  Conditions:
    - Redmine:
      - 3216736
      Branch:
      - master
      - 202211

- Errors_list:
    - '.* ERR syncd#SDK: \[BULK_COUNTER\.ERR\] BULK-CNTR ioctl failed \(cmd=\d+\) error Invalid argument.*'
    - '.* ERR syncd#SDK: \[BULK_COUNTER\.ERR\] BULK-CNTR transaction parameter is invalid.*'
    - '.* ERR syncd#SDK: \[BULK_COUNTER\.ERR\] Port-Counter-Transaction-Start: failed to start transaction in driver.*'
    - '.* ERR syncd#SDK: \[BULK_COUNTER\.ERR\] failed to start port counters bulk-read transaction.*'
    - '.* ERR kernel: \[.*\] Bulk-Counter DB add - invalid buffer_id.*'
  Conditions:
    - Affected_test_cases:
      - tests/nightly/routing/test_routing.py::TestRouting::test_reboot
      - tests/nightly/fec/test_fec.py::TestFec::test_fec_capabilities_loopback_ports
      - tests/push_build_tests/general/qos/test_qos_reload.py::test_qos_reload_ports
      Redmine:
      - 3216771
      Branch:
      - 202205
      - master

- Errors_list:
    - '.* ERR wjhcli: :- requestDaemon: Timeout waiting for daemon to send data.*'
    - '.* ERR wjhd: :- send: send\(\): failed to sent data to client: Broken pipe.*'
  Conditions:
    - Affected_test_cases:
      - tests/nightly/show_techsupport/test_techsupport.py::test_techsupport_mellanox_sdk_dump
      - tests/show_techsupport/test_auto_techsupport.py
      - tests/show_techsupport/test_techsupport_no_secret.py
      Redmine:
      - 3216781
      Branch:
      - 202205

- Errors_list:
    - ".*ERR bgp#bgpcfgd: Peer.*: Can't update the peer. Only 'admin_status' attribute is supported.*"
  Conditions:
    - Affected_test_cases:
      - bgp/test_bgp_bounce.py
      Redmine:
      - 3217740

- Errors_list:
    - ".*ERR swss#orchagent: :- set: switch id oid:0x0 doesn't exist.*"
    - '.*ERR swss#orchagent: :- updatePortOperStatus: Failed to set host interface  operational status down.*'
  Conditions:
    - Affected_test_cases:
      - tests/nightly/dynamic_port_breakout/test_dpb_all_ports.py
      Redmine:
      - 2872994

- Errors_list:
    - '.*ERR dhclient.*: receive_packet failed on .*: Network is down.*'
    - '.*ERR dhclient.*: send_packet: No such device or address*'
    - '.*ERR dhclient.*: dhclient.c:.*: Failed to send \d+ byte long packet over .* interface.*'
    - '.*ERR dhclient\[\d+\]: send_packet6: No such device.*'
    - '.*ERR dhclient\[\d+\]: dhc6: send_packet6\(\) sent -.* of .* bytes.*'
  Conditions:
    - Affected_test_cases:
      - tests/nightly/logging/test_log_analyzer_errors_during_deploy_sonic.py
      Redmine:
      - 3114029

- Errors_list:
    - '.*INFO kernel.*dhcp6relay.*segfault at.*ip.*sp.*error.*in libswsscommon.*'
  Conditions:
    - Affected_test_cases:
      - tests/push_build_tests/L3/dhcp_relay/test_dhcp6_relay.py::TestDHCP6Relay::test_dhcp6_relay_remove_dhcp_server
      Redmine:
      - 3238357

- Errors_list:
    - '.* ERR syncd#SDK: :- setQueueCounterList: Queue RID oid:.* can''t provide the statistic'
    - '.* ERR syncd#SDK: :- addObject: Queue Counter RID oid:.* can''t provide the statistic'
  Conditions:
    - Redmine:
      - 2876749
      Platform:
        - simx

- Errors_list:
    - '.* ERR systemd\[\d+\]: Failed to start Update hostname based on configdb.'
  Conditions:
    - Redmine:
      - 3238754
      Platform:
        - simx

- Errors_list:
    - '.*ERR wjhd\[\d+\]: \[WJH_LIB.ERROR\s+\]: Failed to create a span session, err: Command Error.*'
    - '.*ERR wjhd\[\d+\]: \[WJH_LIB.ERROR\s+\]: Wjh lib dev specific cb span init failed, err.*'
    - '.*ERR wjhd\[\d+\]: \[WJH_LIB.ERROR\s+\]: Failed to set WJH span configuration, err.*'
    - '.*ERR wjhd\[\d+\]: \[WJH_LIB.ERROR\s+\]: Failed to initialize the WJH buffer drop mechanism, err.*'
    - '.*ERR wjhd\[\d+\]: \[WJH_LIB.ERROR\s+\]: wjh_drop_reason_group_init_cb failed, err.*'
    - '.*ERR wjhd\[\d+\]: :- setDropGroupReason: Failed to initialize drop reason group BUFFER for channel buffer, status.*'
    - '.*ERR wjhd\[\d+\]: :- initializeDefaultWjhChannels: Failed to initialize default channels.*'
    - '.*ERR wjhd\[\d+\]: :- main: exception: :- initializeDefaultWjhChannels: Failed to initialize default channels.*'
    - '.*ERR wjhd\[\d+\]: :- removeBufferConfiguration: Fail to deinit SDK telemetry, error: \[\d+\]: \[Invalid Handle\].*'
    - '.*ERR wjhd\[\d+\]: :- removeBufferConfiguration: Failed to close SDK handler, error: \[\d+\]: \[Invalid Handle\].*'
    - '.*ERR wjhd\[\d+\]: \[WJH_LIB.ERROR\s+\]: User channel \d+ is not destroyed, destroy it first.*'
    - '.*ERR wjhd\[\d+\]: \[WJH_LIB.ERROR\s+\]: wjh_db_deinit_resource_check failed, err.*'
    - '.*ERR wjhd\[\d+\]: :- deinitialize: Failed to de-initialize WJH library, status.*'
  Conditions:
    - Affected_test_cases:
      - tests/push_build_tests/general/qos/test_qos_reload.py::test_qos_reload_ports
      Redmine:
      - 3238763

# The below errors should be ignored, because it is caused by FW was busing(err is -16) , and it is an expected behaviour
- Errors_list:
    - '.*ERR kernel: \[.*\] Fails to get module type, err: -16.*'
    - '.*ERR pmon#xcvrd: Failed to read sfp=\d+ EEPROM.*page=\/sys\/module\/sx_core.*eeprom\/pages.*Device or resource busy.*'
    - '.*ERR pmon#xcvrd: message repeated \d+ times: \[ Failed to read sfp=\d+ EEPROM.*page=\/sys\/module\/sx_core.*eeprom\/pages.*Device or resource busy.*\]'
    - '.*ERR kernel: \[.*\] Fails to access .* register MCIA \(module:\d+, page:\d+, device_addr:\d+, size:\d+, i2c_addr:.*, slot:\d+, status:.*err: -16.*'
    - '.*ERR kernel: \[.*\] Fails to read module eeprom, status: -16.*'
    - '.*ERR kernel: \[.*\] Fails to access .* module eeprom, status: -16.*'
    - '.*ERR pmon#xcvrd: Failed to get SFP type, index=\d+, error=\[Errno \d+\] Device or resource busy'
  Conditions:
    - Affected_test_cases:
      - tests/nightly/show_techsupport/test_techsupport.py
      - tests/nightly/app_extension/test_app_extension_basic.py::test_app_techsupport_integration
      - show_techsupport/test_auto_techsupport.py
      - show_techsupport/test_techsupport_no_secret.py
      - show_techsupport/test_techsupport.py
      - tests/nightly/arp/test_arp.py::test_arp_gratuitous_without_arp_update
      - tests/nightly/fec/test_fec.py
      - tests/nightly/auto_negotition/test_auto_neg.py::TestAutoNeg::test_auto_neg_toggle_peer_port
      - tests/nightly/auto_negotition/test_auto_neg.py::TestAutoNeg::test_auto_neg_conf
      - tests/nightly/auto_negotition/test_auto_neg_negative.py::TestAutoNegNegative::test_negative_advertised_speed_type_mismatch
      - tests/nightly/evpn_vxlan/tech_support/test_evpn_vxlan_tech_support.py

- Errors_list:
    - '.* ERR healthd: Get unit status .*''LoadState'''
    - '.* ERR healthd: system_service\[Errno \d+\] Connection reset by peer'
    - '.* ERR healthd: .*system_service\[Errno \d+\] Broken pipe.*'
  Conditions:
    - Affected_test_cases:
      - tests/nightly/lag/test_lag.py::test_core_functionality_with_reboot
      - tests/nightly/fec/test_fec.py
      - tests/nightly/auto_negotition/test_auto_neg.py::TestAutoNeg::test_auto_neg_conf
      - iface_loopback_action/test_iface_loopback_action.py::test_loopback_action_reload
      Redmine:
      - 3352372

- Errors_list:
    - '.* ERR swss#vxlanmgrd: :- doVxlanTunnelMapCreateTask: Map already present : vtep\d+:map_\d+_Vlan\d+'
    - '.* ERR swss#intfmgrd: :- setIntfIp: Command ''/sbin/ip address "add" ".*" broadcast ".*" dev ".*"'' failed with rc \d+'
    - '.* ERR swss#intfmgrd: :- setIntfIp: Command ''/sbin/ip -6 address "add" ".*" broadcast ".*" dev ".*"'' failed with rc \d+'
    - '.* ERR swss#intfmgrd: :- setIntfIp: Command ''/sbin/ip address "add" ".*" dev ".*"'' failed with rc \d+'
    - '.* ERR swss#orchagent: :- addOperation: Vxlan tunnel .* is already exists'
    - '.* ERR sflow#port_index_mapper: <built-in function Select_select> returned a result with an error set'
    - '.* WARNING syncd#SDK: :- discover: skipping since it causes crash: SAI_STP_ATTR_BRIDGE_ID'
    - '.* ERR swss#vxlanmgrd: :- doVxlanEvpnNvoCreateTask: Only Single NVO object allowed.*'
  Conditions:
    - Affected_test_cases:
      - tests/push_build_tests/general/doroce/test_doroce.py
      Redmine:
      - 3263991

- Errors_list:
    - '.* ERR kernel: \[.*\] Fails to access \(\d+\) module eeprom, status: -\d+.'
    - '.* ERR pmon#xcvrd: Failed to read sfp=\d+ EEPROM page=/sys/module/sx_core/asic\d+/module\d+/eeprom/pages/.*/data, page_offset=\d+,\s+size=\d+, offset=\d+, error = \[Errno \d+\] Input/output error'
    - '.* ERR pmon#xcvrd: message repeated \d+ times: \[ Failed to read sfp=\d+ EEPROM page=/sys/module/sx_core/asic\d+/module\d+/eeprom/pages/.*/data, page_offset=\d+,\s+size=\d+, offset=\d+, error = \[Errno \d+\] Input/output error\]'
  Conditions:
    - Affected_test_cases:
      - tests/nightly/show_techsupport/test_techsupport.py::test_techsupport_mellanox_sdk_dump
      - show_techsupport/test_auto_techsupport.py
      - show_techsupport/test_techsupport_no_secret.py
      - show_techsupport/test_techsupport.py::test_techsupport
      - platform_tests/sfp/test_sfputil.py::test_check_sfputil_reset
      - tests/nightly/app_extension/test_app_extension_basic.py::test_app_techsupport_integration
      Redmine:
      - 3263805

- Errors_list:
    - '.* ERR pmon#sensord: Error getting sensor data: emc\d+/#\d+: Can''t read'
  Conditions:
    - Affected_test_cases:
      - show_techsupport/test_auto_techsupport.py
      Redmine:
      - 3273940
      Branch:
      - 202205
      Platform:
      - 2201

- Errors_list:
    - '.* ERR hostcfgd: Hostname was not updated: Already set up'
  Conditions:
    - Redmine:
      - 3273797
      Branch:
      - 202211

- Errors_list:
    - '.*Bulk-Cntr PPCNT parser - unexpected local port.*'
  Conditions:
    - Affected_test_cases:
      - tests/push_build_tests/general/qos/test_qos_reload.py
      Redmine:
      - 3279709

- Errors_list:
    - '.*Failed to start Update logrotate configuration.*'
  Conditions:
    - Affected_test_cases:
      - platform_tests/fwutil/test_fwutil.py::test_fwutil_update_current
      Redmine:
      - 3289596

- Errors_list:
    - '.*ERR kernel.*Unknown EEPROM type.*'
  Conditions:
    - Affected_test_cases:
      - tests/show_techsupport/test_auto_techsupport.py::TestAutoTechSupport::test_max_limit
      - platform_tests/sfp/test_sfputil.py
      - tests/nightly/app_extension/test_app_extension_basic.py::test_app_techsupport_integration
      Redmine:
      - 3283464

- Errors_list:
    - '.*ERR kernel: \[.*\] mlxreg-hotplug mlxreg-hotplug: Failed to request irq: -22.*'
    - '.*WARNING kernel: \[.*\] mlxreg-hotplug: probe of mlxreg-hotplug failed with error -22.*'
  Conditions:
    - Affected_test_cases:
      - tests/nightly/lag/test_lag.py::test_core_functionality_with_reboot
      - tests/nightly/fec/test_fec.py::TestFec::test_fec_capabilities_loopback_ports
      - tests/nightly/routing/test_routing.py::TestRouting::test_reboot
      - tests/push_build_tests/system/test_startup_time_degradation.py
      Redmine:
      - 3446516
      Platform:
      - simx

- Errors_list:
    - '.*ERR syncd#SDK: \[SAI_DEBUG_COUNTER\.ERR\] mlnx_sai_debug_counter\.c\[\d+\]- mlnx_debug_counter_db_idx_to_data: Debug counter at index \d+ is removed or not created yet.*'
    - '.*ERR syncd#SDK: :- collectSwitchDebugCounters: Failed to get stats of port.*'
    - '.*ERR syncd#SDK: :- collectData: Failed to get stats of Switch Debug Counter.*'
  Conditions:
    - Affected_test_cases:
      - drop_packets/test_configurable_drop_counters.py
      Redmine:
      - 3310078

- Errors_list:
    - '.*ERR swss#buffermgrd: :- isHeadroomResourceValid: Unable to update profile for port Ethernet\d+. Accumulative headroom size exceeds limit.*'
    - '.*ERR swss#buffermgrd: :- refreshPgsForPort: Update speed \(\d+\) and cable length .* for port Ethernet0 failed, accumulative headroom size exceeds the limit*'
    - '.*ERR swss#buffermgrd: :- doTask: Failed to process table update.*'
  Conditions:
    - Affected_test_cases:
      - platform_tests/test_auto_negotiation.py
      Redmine:
      - 3331335

# Errors which should be ignored in tests which doing reboot
- Errors_list:
    - '.* ERR healthd: system_service.*'
  Conditions:
    - Affected_test_cases:
      # Canonical
      - tests/nightly/app_extension/test_app_extension_reboot.py::test_app_start_delay_after_reboot
      - tests/nightly/auto_negotition/test_auto_neg.py::TestAutoNeg::test_auto_neg_conf
      - tests/nightly/copp/test_copp.py::test_copp_policer
      - tests/nightly/fdb/test_fdb_basic.py::TestFdbBasic::test_fdb_aging_time_expire
      - tests/nightly/fec/test_fec.py::TestFec::test_fec_capabilities_loopback_ports
      - tests/nightly/fec/test_fec.py::TestFec::test_fec_capabilities_hosts_ports
      - tests/nightly/fec/test_fec.py::TestFec::test_negative_fec
      - tests/nightly/fec/test_fec.py::TestFec::test_fec_bug_2705016
      - tests/nightly/p4/sampling_example/test_entry_scaling.py::TestEntryScaling::test_scaling_entries
      - tests/nightly/p4/sampling_example/test_entry_priority.py::test_entries_with_different_priority
      - tests/nightly/p4/sampling_example/test_entry_priority.py::test_entries_with_same_priority
      - tests/nightly/p4/sampling_example/test_entry_advance.py::TestEntryTraffic::test_enable_disable_p4_sampling
      - tests/nightly/p4/sampling_example/test_entry_advance.py::TestEntryTraffic::test_p4_sampling_traffic_concussive
      - tests/nightly/p4/examples_application/test_reboot/test_reboot.py::test_p4_examples_reboot
      - tests/nightly/lag/test_lag.py::test_core_functionality_with_reboot
      - tests/nightly/lag/test_lag.py::test_lag_min_links
      - tests/nightly/lag/test_lag.py::test_lag_members_scale
      - tests/nightly/lag/test_lag.py::test_lags_scale
      - tests/nightly/lag/test_lag.py::test_port_cannot_be_added_to_lag
      - tests/push_build_tests/general/qos/test_qos_reload.py::test_qos_reload_ports
      - tests/nightly/routing/test_routing.py::TestRouting::test_reboot
      # Community
      - pc/test_po_update.py::test_po_update_io_no_loss
      - vxlan/test_vnet_route_leak.py::test_vnet_route_leak
      - drop_packets/test_wjh.py::test_wjh_starts_after_config_reload
      - platform_tests/fwutil/test_fwutil.py::test_fwutil_install_file
      - platform_tests/fwutil/test_fwutil.py::test_fwutil_install_url
      - platform_tests/fwutil/test_fwutil.py::test_fwutil_update_current
      - platform_tests/fwutil/test_fwutil.py::test_fwutil_update_next
      - platform_tests/fwutil/test_fwutil.py::test_fwutil_auto
      - copp/test_copp.py::TestCOPP::test_add_new_trap
      - copp/test_copp.py::TestCOPP::test_remove_trap
      - copp/test_copp.py::TestCOPP::test_trap_config_save_after_reboot
      - vxlan/test_vnet_vxlan.py
      - ecmp/inner_hashing/test_wr_inner_hashing.py
      - dhcp_relay/test_dhcp_relay.py::test_interface_binding
      - autorestart/test_container_autorestart.py
      - iface_loopback_action/test_iface_loopback_action.py::test_loopback_action_reload
      # Ignore reboot related errors for test which checks errors after SONiC image deploy
      - tests/nightly/logging/test_log_analyzer_errors_during_deploy_sonic.py
      - system_health/test_system_health.py
      Redmine:
      - 3294192
      Branch:
      - 202205
      - 202211

- Errors_list:
    - '.* ERR python: :- initializeGlobalConfig: Sonic database config global file doesn.*t exist at \/var\/run\/redis\/sonic-db\/database_global.json.*'
  Conditions:
    - Affected_test_cases:
      - tests/nightly/logging/test_log_analyzer_errors_during_deploy_sonic.py
      - show_techsupport/test_auto_techsupport.py::TestAutoTechSupport::test_max_limit
      Redmine:
      - 3333068

- Errors_list:
    - '.* ERR kernel.* QAT: AE0 is inactive.*'
    - '.* ERR kernel.* QAT: failed to get device out of reset.*'
    - '.* ERR kernel.* qat_hal_clr_reset error.*'
    - '.* ERR kernel.* Failed to init the AEs.*'
    - '.* ERR kernel.* Failed to initialise Acceleration Engine.*'
    - '.* WARNING kernel.* probe of .* failed with error -14.*'
  Conditions:
    - Affected_test_cases:
      - tests/nightly/lag/test_lag.py::test_core_functionality_with_reboot
      - tests/nightly/fec/test_fec.py::TestFec::test_fec_capabilities_hosts_ports
      Redmine:
        - 3333468
      Platform:
        - 2201

- Errors_list:
    - '.* ERR teamd#teammgrd: :- addLagMember: Failed to add Ethernet\d+ to port channel .*'
  Conditions:
    - Affected_test_cases:
      - tests/nightly/lag/test_lag.py
      Redmine:
        - 3137284

- Errors_list:
    - '.* ERR decode-syseeprom: Nowhere to read syseeprom from! No symlink found'
    - '.* ERR hw-management: hw-management is already started'
    - '.* ERR systemd\[\d+\]: Failed to start Chassis HW management service of Mellanox systems.'
    - '.* ERR show: Nowhere to read syseeprom from! No symlink found'
    - '.* ERR install-pending-fw.py: Nowhere to read syseeprom from! No symlink found'
    - '.* ERR healthd: Failed to read from file /var/run/hw-management/led/led_status_capability - FileNotFoundError\(2, .No such file or directory.\)'
    - '.* ERR healthd:- FileNotFoundError\(2, ''No such file or directory''\)'
    - '.* ERR sonic-db-cli: :- guard: RedisReply catches system_error: command: .*, reason: ERR wrong number of arguments for ''hset'' command: Input/output error'
    - '.* ERR wrong number of arguments for ''hset'' command: Input/output error: Input/output error'
    - '.* ERR hostcfgd: Failed to get status of snmp.service: rc=-15 stderr=b'''''
    - '.* ERR hostcfgd: \[''sudo'', ''systemctl'', ''start'', ''.*.service''\] - failed: return code - \d+, output:.*'
    - '.* ERR hostcfgd: \[''systemctl'', ''(start|restart)'', ''.*''\] - failed: return code - \d+, output:.*'
  Conditions:
    - Redmine:
        - 3507983

- Errors_list:
    - '.* ERR pmon#thermalctld: Failed to read from file /var/run/hw-management/thermal/fan1_speed_get - OSError.*'
  Conditions:
    - Affected_test_cases:
      - tests/nightly/show_techsupport/test_techsupport.py::test_techsupport_mellanox_sdk_dump
      - show_techsupport/test_auto_techsupport.py::TestAutoTechSupport::test_rate_limit_interval
      Redmine:
        - 3334337
      Platform:
        - 2201

- Errors_list:
    - '.* ERR swss#orchagent: :- doPortTask: Failed to set port Ethernet\d+ AN from 0 to 1.*'
  Conditions:
    - Affected_test_cases:
      - tests/nightly/fec/test_fec.py::TestFec::test_fec_capabilities_hosts_ports
      Redmine:
        - 3335880

- Errors_list:
    - '.* ERR syncd#SDK: \[SAI_INTERFACE_QUERY_ETH.ERR\] mlnx_sai_interfacequery_eth.c\[\d+\]- sai_dbg_generate_dump_ext: Failed to lock DFW semaphore - Connection timed out'
    - '.* ERR syncd#SDK: \[SX_API_DBG.ERR\] dump generation failed'
    - '.* ERR syncd#SDK: \[SX_API_DBG.ERR\] Cr space dump failed#\d+'
    - '.* ERR syncd#SDK: \[SX_API_DBG.ERR\] FW dump generation failed to move meta file to:\[/tmp/saisdkdump/sdkdump_ext_meta_.*\]'
    - '.* ERR syncd#SDK: \[COMP_LIB.ERR\] failed to rename file:\[/tmp/saisdkdump/.*.tmp\] to:\[/tmp/saisdkdump/.*\] code:\[2,No such file or directory\]'
    - '.* ERR syncd#SDK: \[SX_API_DBG.ERR\] FW dump generation failed to move CR file to:\[/tmp/saisdkdump/.*]'
  Conditions:
    - Affected_test_cases:
      - tests/push_build_tests/general/qos/test_qos_reload.py::test_qos_reload_ports
      - tests/nightly/app_extension/test_app_extension_basic.py::test_app_techsupport_integration
      - tests/nightly/evpn_vxlan/tech_support/test_evpn_vxlan_tech_support.py::TestEvpnVxlanTechSupport::test_tech_support
      - show_techsupport/test_auto_techsupport.py
      - show_techsupport/test_techsupport_no_secret.py
      - tests/nightly/show_techsupport/test_techsupport.py::test_techsupport_mellanox_sdk_dump
    - Platform:
      - simx
      Redmine:
      - 3272016

- Errors_list:
    - '.* ERR syncd#SAI: \[SAI_SWITCH.ERR\] mlnx_sai_switch.c\[\d+\]- mlnx_initialize_dev_mac_address: Failed, Need valid mac addresses for device, mac: /tmp/sai.profile'
    - '.* ERR syncd#SAI: \[SAI_SWITCH.ERR\] mlnx_sai_switch.c\[\d+\]- mlnx_connect_switch: mlnx_initialize_dev_mac_address failed in connect  0xffffffff'
    - '.* ERR syncd#SAI: \[SAI_SWITCH.ERR\] mlnx_sai_switch.c\[\d+\]- mlnx_create_switch: Failed to create the switch'
    - '.* ERR syncd#SAI: :- exit_with_sai_failure: saisdkdump exited with SAI rc: 0xffffffff, msg: Failed to create a switch .'
  Conditions:
    - Affected_test_cases:
      - show_techsupport/test_techsupport_no_secret.py
    - Platform:
      - arm64-nvda_bf-mbf2h536c
      - arm64-nvda_bf-9009d3b600cvaa
      Redmine:
      - 3398655

# Errors which should be ignored in test_containers_autorestart. The detaiils in RM 3315995
- Errors_list:
    - '.* ERR what-just-happened#wjhd: :- removeBufferConfiguration: Fail to deinit SDK telemetry, error: \[4\]: \[Communication Error\]'
    - '.* ERR what-just-happened#wjhd\[\d+\]: \[WJH_LIB.ERROR  \]: Failed to set trap ID \(\d+\) to trap group \(\d+\) with trap action \(\d+\), error: Communication Error'
    - '.* ERR what-just-happened#wjhd\[\d+\]: \[WJH_LIB.ERROR  \]: Failed to set traps.'
    - '.* ERR what-just-happened#wjhd\[\d+]: \[WJH_LIB.ERROR  \]: Failed to enable severity bits .* on drop reason group \d+'
    - '.* ERR what-just-happened#wjhd\[\d+\]: \[WJH_LIB.ERROR  \]: wjh_drop_reason_group_disable_cb failed, err = 1.'
    - '.* ERR what-just-happened#wjhd\[\d+\]: :- deleteDropGroupReason: Failed to disable drop group ACL on channel acl, status 1'
    - '.* ERR what-just-happened#wjhd\[\d+\]: \[WJH_LIB.ERROR  \]: Drop reason group \(\d+\) is bound to user channel \(id: \d+\), please unbind first.'
    - '.* ERR what-just-happened#wjhd\[\d+\]: :- destroy: Failed to destroy channel acl, status 1'
    - '.* ERR what-just-happened#wjhd\[\d+\]: \[WJH_LIB.ERROR  \]: Failed to get the current number of ports, err: Invalid Handle'
    - '.* ERR what-just-happened#wjhd\[\d+\]: \[WJH_LIB.ERROR  \]: Failed to bind all ports to the span session, err: 1'
    - '.* ERR what-just-happened#wjhd\[\d+\]: \[WJH_LIB.ERROR  \]: Failed to set drop reason bits .* on group \d+ to state 0.'
    - '.* ERR what-just-happened#wjhd\[\d+\]: \[WJH_LIB.ERROR  \]: Failed to enable drop reasons for drop group 0.'
    - '.* ERR what-just-happened#wjhd\[\d+\]: :- deleteDropGroupReason: Failed to disable drop group BUFFER on channel buffer, status 1'
    - '.* ERR what-just-happened#wjhd\[\d+\]: :- destroy: Failed to destroy channel buffer, status 1'
    - '.* ERR what-just-happened#wjhd\[\d+\]: \[WJH_LIB.ERROR  \]: Failed to set trap ID \(\d+\) to trap group \(\d+\) with trap action \(\d+\), error: Invalid Handle'
    - '.* ERR what-just-happened#wjhd\[\d+\]: :- deleteDropGroupReason: Failed to disable drop group L\d on channel forwarding, status 1'
    - '.* ERR what-just-happened#wjhd\[\d+\]: :- deleteDropGroupReason: Failed to disable drop group TUNNEL on channel forwarding, status 1'
    - '.* ERR what-just-happened#wjhd\[\d+]\: :- destroy: Failed to destroy channel forwarding, status 1'
    - '.* ERR what-just-happened#wjhd\[\d+\]: \[WJH_LIB.ERROR  \]: Failed to unbind policer \(\d+\) from trap group \(\d+\), error: Invalid Handle'
    - '.* ERR what-just-happened#wjhd\[\d+\]: \[WJH_LIB.ERROR  \]: wjh_user_channel_destroy_cb failed, err = 1.'
    - '.* ERR what-just-happened#wjhd\[\d+\]: \[WJH_LIB.ERROR  \]: __wjh_user_channel_destroy failed, err = 1'
    - '.* ERR what-just-happened#wjhd\[\d+\]: :- destroy: Failed to destroy channel layer-1, status 1'
    - '.* ERR what-just-happened#wjhd\[\d+\]: \[WJH_LIB.ERROR  \]: User channel \d+ is not destroyed, destroy it first.'
    - '.* ERR what-just-happened#wjhd\[\d+\]: \[WJH_LIB.ERROR  \]: wjh_db_deinit_resource_check failed, err = 1'
    - '.* ERR what-just-happened#wjhd\[\d+\]: :- deinitialize: Failed to de-initialize WJH library, status \d+.*'
    - '.* ERR what-just-happened#wjhd\[23\]: \[WJH_LIB.ERROR  \]: WJH libs are not initialized.*'
    - '.* ERR what-just-happened#wjhd\[\d+\]: :- removeBufferConfiguration: Failed to close SDK handler, error: \[\d+\]: \[Invalid Handle\].*'
    - '.* ERR what-just-happened#wjhd\[\d+\]: :- removeBufferConfiguration: Fail to deinit SDK telemetry, error: \[\d+\]: \[Invalid Handle\].*'
    - '.* ERR what-just-happened#wjhd\[\d+\]: :- main: exception: :- initialize: Failed to initialize WJH library .*'
    - '.* ERR what-just-happened#wjhd\[\d+\]: :- initialize: Failed to initialize WJH library .*'
    - '.* ERR syncd#SDK: \[SPAN.ERR\] __span_delete for span_session_id 0 failed, err: Resource is in use.*'
    - '.* ERR syncd#SDK: \[SPAN.ERR\] SPAN session \d+ still has policer ID \d+ bound, so can.* be destroyed.*'
    - '.* ERR what-just-happened#wjhd\[\d+\]: \[WJH_LIB.ERROR  \]: __wjh_resources_pre_init_clean_up failed, err = d+.*'
    - '.* ERR what-just-happened#wjhd\[\d+\]: \[WJH_LIB.ERROR  \]: Failed to disable monitor on buffer drop reason group.*'
    - '.* ERR what-just-happened#wjhd\[\d+\]: \[WJH_LIB.ERROR  \]: wjh buffer cleanup failed to destroy WJH span configuration, err: \d+.*'
    - '.* ERR what-just-happened#wjhd\[\d+\]: \[WJH_LIB.ERROR  \]: Wjh lib dev specific cb span deinit failed, err=\d+.*'
    - '.* ERR what-just-happened#wjhd\[\d+\]: \[WJH_LIB.ERROR  \]: Failed to destroy the span session, err: Resource is in use.*'
    - '.* ERR what-just-happened#wjhd\[\d+\]: \[WJH_LIB.ERROR  \]: wjh buffer cleanup failed to destroy the ACL configuration, err: \d+.*'
    - '.* ERR what-just-happened#wjhd\[\d+\]: \[WJH_LIB.ERROR  \]: Wjh lib dev specific cb for acl create failed, err=\d.*'
    - '.* ERR what-just-happened#wjhd\[\d+\]: \[WJH_LIB.ERROR  \]: Failed to unbind ACL group to the analyzer port, err:.*'
    - '.* ERR syncd#SDK: \[ACL.ERR\] ACL : Error at check access for group id\[\d+\].*'
    - '.* ERR syncd#SDK: \[ACL.ERR\] ACL : Failed to get ACL \(or ACL group entry type\), ACL id\[\d+\].*'
    - '.* ERR syncd#SDK: \[ACL.ERR\] Get acl \[\d+\].*'
    - '.* ERR syncd#SDK: \[ACL.ERR\] Trying to get a non-allocated table id \[\d+\].*'
    - '.* ERR syncd#SDK: \[ACL.ERR\] ACL: ACL group access denied, entry type is not FLEX_ACL_ENTRY_TYPE_USER_E..*'
  Conditions:
    - Affected_test_cases:
      - autorestart/test_container_autorestart.py::test_containers_autorestart

# Errors which should be ignored in tests which doing reboot/reload
- Errors_list:
    - '.* ERR watchdogutil: Failed to get watchdog module'
  Conditions:
    - Affected_test_cases:
      # Canonical
      - tests/nightly/app_extension/test_app_extension_reboot.py::test_app_start_delay_after_reboot
      - tests/nightly/auto_negotition/test_auto_neg.py::TestAutoNeg::test_auto_neg_conf
      - tests/nightly/copp/test_copp.py::test_copp_policer
      - tests/nightly/fdb/test_fdb_basic.py::TestFdbBasic::test_fdb_aging_time_expire
      - tests/nightly/fec/test_fec.py::TestFec::test_fec_capabilities_loopback_ports
      - tests/nightly/fec/test_fec.py::TestFec::test_fec_capabilities_hosts_ports
      - tests/nightly/fec/test_fec.py::TestFec::test_negative_fec
      - tests/nightly/fec/test_fec.py::TestFec::test_fec_bug_2705016
      - tests/nightly/p4/sampling_example/test_entry_scaling.py::TestEntryScaling::test_scaling_entries
      - tests/nightly/p4/sampling_example/test_entry_priority.py::test_entries_with_different_priority
      - tests/nightly/p4/sampling_example/test_entry_priority.py::test_entries_with_same_priority
      - tests/nightly/p4/sampling_example/test_entry_advance.py::TestEntryTraffic::test_enable_disable_p4_sampling
      - tests/nightly/p4/sampling_example/test_entry_advance.py::TestEntryTraffic::test_p4_sampling_traffic_concussive
      - tests/nightly/p4/examples_application/test_reboot/test_reboot.py::test_p4_examples_reboot
      - tests/nightly/lag/test_lag.py::test_core_functionality_with_reboot
      - tests/nightly/lag/test_lag.py::test_lag_min_links
      - tests/nightly/lag/test_lag.py::test_lag_members_scale
      - tests/nightly/lag/test_lag.py::test_lags_scale
      - tests/nightly/lag/test_lag.py::test_port_cannot_be_added_to_lag
      - tests/push_build_tests/general/qos/test_qos_reload.py::test_qos_reload_ports
      - tests/nightly/routing/test_routing.py::TestRouting::test_reboot
      - tests/push_build_tests/system/test_startup_time_degradation.py::TestStartupTime::test_startup_time_degradation
      # 2 tests below temporary added - they doing "config reload -y"
      - tests/push_build_tests/L3/dhcp_relay/test_dhcp6_relay.py::TestDHCP6Relay::test_dhcp6_relay_remove_dhcp_server
      - tests/push_build_tests/L3/dhcp_relay/test_dhcp6_relay.py::TestDHCP6Relay::test_dhcp6_relay_multiple_dhcp_servers
      # Community
      - pc/test_po_update.py::test_po_update_io_no_loss
      - vxlan/test_vnet_route_leak.py::test_vnet_route_leak
      - drop_packets/test_wjh.py::test_wjh_starts_after_config_reload
      - platform_tests/fwutil/test_fwutil.py::test_fwutil_install_file
      - platform_tests/fwutil/test_fwutil.py::test_fwutil_install_url
      - platform_tests/fwutil/test_fwutil.py::test_fwutil_update_current
      - platform_tests/fwutil/test_fwutil.py::test_fwutil_update_next
      - platform_tests/fwutil/test_fwutil.py::test_fwutil_auto
      - copp/test_copp.py::TestCOPP::test_add_new_trap
      - copp/test_copp.py::TestCOPP::test_remove_trap
      - copp/test_copp.py::TestCOPP::test_trap_config_save_after_reboot
      - vxlan/test_vnet_vxlan.py
      - ecmp/inner_hashing/test_wr_inner_hashing.py
      - dhcp_relay/test_dhcp_relay.py::test_interface_binding
      - autorestart/test_container_autorestart.py
      - iface_loopback_action/test_iface_loopback_action.py::test_loopback_action_reload
      # Ignore reboot related errors for test which checks errors after SONiC image deploy
      - tests/nightly/logging/test_log_analyzer_errors_during_deploy_sonic.py
      - system_health/test_system_health.py
      - qos/test_buffer.py::test_port_admin_down
      Redmine:
      - 3273006

# Errors which should be ignored in tests which doing warm-reboot
- Errors_list:
    - '.* ERR syncd#SDK: \[DBG\.ERR\] Fatal failure not allowed when BOOT_MODE_ISSU_STARTED'
  Conditions:
    - Affected_test_cases:
      # Canonical
      - tests/nightly/app_extension/test_app_extension_reboot.py::test_app_start_delay_after_reboot
      - tests/nightly/auto_negotition/test_auto_neg.py::TestAutoNeg::test_auto_neg_conf
      - tests/nightly/copp/test_copp.py::test_copp_policer
      - tests/nightly/fdb/test_fdb_basic.py::TestFdbBasic::test_fdb_aging_time_expire
      - tests/nightly/fec/test_fec.py::TestFec::test_fec_capabilities_loopback_ports
      - tests/nightly/fec/test_fec.py::TestFec::test_fec_capabilities_hosts_ports
      - tests/nightly/fec/test_fec.py::TestFec::test_negative_fec
      - tests/nightly/fec/test_fec.py::TestFec::test_fec_bug_2705016
      - tests/nightly/p4/sampling_example/test_entry_scaling.py::TestEntryScaling::test_scaling_entries
      - tests/nightly/p4/sampling_example/test_entry_priority.py::test_entries_with_different_priority
      - tests/nightly/p4/sampling_example/test_entry_priority.py::test_entries_with_same_priority
      - tests/nightly/p4/sampling_example/test_entry_advance.py::TestEntryTraffic::test_enable_disable_p4_sampling
      - tests/nightly/p4/sampling_example/test_entry_advance.py::TestEntryTraffic::test_p4_sampling_traffic_concussive
      - tests/nightly/p4/examples_application/test_reboot/test_reboot.py::test_p4_examples_reboot
      - tests/nightly/lag/test_lag.py::test_core_functionality_with_reboot
      - tests/nightly/lag/test_lag.py::test_lag_min_links
      - tests/nightly/lag/test_lag.py::test_lag_members_scale
      - tests/nightly/lag/test_lag.py::test_lags_scale
      - tests/nightly/lag/test_lag.py::test_port_cannot_be_added_to_lag
      - tests/push_build_tests/general/qos/test_qos_reload.py::test_qos_reload_ports
      - tests/nightly/routing/test_routing.py::TestRouting::test_reboot
      # 2 tests below temporary added - they doing "config reload -y"
      - tests/push_build_tests/L3/dhcp_relay/test_dhcp6_relay.py::TestDHCP6Relay::test_dhcp6_relay_remove_dhcp_server
      - tests/push_build_tests/L3/dhcp_relay/test_dhcp6_relay.py::TestDHCP6Relay::test_dhcp6_relay_multiple_dhcp_servers
      # Community
      - pc/test_po_update.py::test_po_update_io_no_loss
      - vxlan/test_vnet_route_leak.py::test_vnet_route_leak
      - drop_packets/test_wjh.py::test_wjh_starts_after_config_reload
      - platform_tests/fwutil/test_fwutil.py::test_fwutil_install_file
      - platform_tests/fwutil/test_fwutil.py::test_fwutil_install_url
      - platform_tests/fwutil/test_fwutil.py::test_fwutil_update_current
      - platform_tests/fwutil/test_fwutil.py::test_fwutil_update_next
      - platform_tests/fwutil/test_fwutil.py::test_fwutil_auto
      - copp/test_copp.py::TestCOPP::test_add_new_trap
      - copp/test_copp.py::TestCOPP::test_remove_trap
      - copp/test_copp.py::TestCOPP::test_trap_config_save_after_reboot
      - vxlan/test_vnet_vxlan.py
      - ecmp/inner_hashing/test_wr_inner_hashing.py
      - dhcp_relay/test_dhcp_relay.py::test_interface_binding
      - autorestart/test_container_autorestart.py
      - iface_loopback_action/test_iface_loopback_action.py::test_loopback_action_reload
      # Ignore reboot related errors for test which checks errors after SONiC image deploy
      - tests/nightly/logging/test_log_analyzer_errors_during_deploy_sonic.py
      - system_health/test_system_health.py
      - qos/test_buffer.py::test_port_admin_down
      Redmine:
      - 3359849

- Errors_list:
    - '.* ERR docker-wait-any: :- blockable: Bad DB request \[STATE_DB\].*'
    - '.* ERR docker-wait-any: :- guard: RedisReply catches system_error: command:.* reason: WRONGTYPE Operation against a key holding the wrong kind of value: Input\/output error.*'
  Conditions:
    - Affected_test_cases:
      - drop_packets/test_wjh.py::test_wjh_starts_after_config_reload
      - tests/nightly/lag/test_lag.py::test_lags_scale
      - tests/push_build_tests/general/qos/test_qos_reload.py::test_qos_reload_ports
      Redmine:
      - 3359469

- Errors_list:
    - '.*ERR pmon#.*: Failed to read from file .* - OSError\(\d+, ''No such device or address''\).*'
  Conditions:
    - Affected_test_cases:
      - platform_tests/test_platform_info.py::test_thermal_control_fan_status
      - tests/nightly/evpn_vxlan/tech_support/test_evpn_vxlan_tech_support.py::TestEvpnVxlanTechSupport::test_tech_support
      - tests/nightly/app_extension/test_app_extension_basic.py::test_app_techsupport_integration
      - show_techsupport/test_auto_techsupport.py
      Redmine:
      - 3345290

- Errors_list:
    - '.* ERR systemd\[\d+\]: Failed to start System Logging Service.*'
  Conditions:
    - Affected_test_cases:
      - tests/nightly/logging/test_log_analyzer_errors_during_deploy_sonic.py
      Redmine:
      - 3362009

- Errors_list:
    - '.*ERR kernel:.* mlx5_core .* mlx5e_get_module_info: cable type not recognized:.*'
    - '.*ERR kernel: .* mlx5_core .* mlx5_query_module_eeprom:.* Module ID not recognized:.*'
    - '.*ERR kernel: .* mlx5_core .* mlx5e_get_module_eeprom: mlx5_query_eeprom.*'
  Conditions:
    - Redmine:
      - 3084763
      Platform:
      - nvda_bf

- Errors_list:
    - '.* ERR (syncd|pmon)#sonic-db-cli: :- guard: RedisReply catches system_error: command:.* reason: WRONGTYPE Operation against a key holding the wrong kind of value: Input\/output error.*'
  Conditions:
    - Redmine:
        - 3388311
      Branch:
        - 202211

- Errors_list:
    - '.* ERR syncd#SDK: :- logEventData: fv: SAI_QUEUE_ATTR_INDEX: \d+'
    - '.* ERR syncd#SDK: :- logEventData: fv: SAI_QUEUE_ATTR_TYPE: SAI_QUEUE_TYPE_ALL'
    - '.* ERR syncd#SDK: :- logEventData: op: get, key: SAI_OBJECT_TYPE_QUEUE:oid:0x.*'
    - '.* ERR syncd#SDK: :- setEndTime: event ''get:SAI_OBJECT_TYPE_QUEUE:oid:.*'' took \d+ ms to execute'
    - '.* ERR syncd#SDK: :- collectData: Failed to get stats of Priority Group Counter 0x.*: -1'
    - '.* ERR syncd#SDK: \[SAI_BUFFER.ERR\] mlnx_sai_buffer.c\[\d+\]- mlnx_sai_get_ingress_priority_group_stats_ext: Failed to get port pg counters - TIMEOUT.'
    - '.* ERR syncd#SDK: \[PORT.ERR\] port_buff_cntr_get failed, for chip type CHIP_TYPE_SWITCH_SPECTRUM\d, err = TIMEOUT'
    - '.* ERR syncd#SDK: \[PORT.ERR\] Failed to retrieve counters values for prio \(\d\)'
    - '.* ERR syncd#SDK: \[PORT.ERR\] Can''t send GET-PPCNT EMAD for port \[0x.*\], err \(TIMEOUT\)'
    - '.* ERR syncd#SDK: \[REG_BULK.ERR\] __reg_bulk_post_completion_cb Error got in completion data sxd_status \[12\]-\[TIMEOUT\].'
    - '.* ERR syncd#SDK: \[REG_BULK.ERR\] sx_reg_layer_sxd_reg_call - Error at access reg call reg_id 0x.*, error: TIMEOUT'
    - '.* ERR syncd#SDK: \[EMAD.ERR\] emad-send failed on register 0x.*, iteration \d+, status=\d+'
    - '.* ERR syncd#SDK: \[SAI_SWITCH.ERR\] mlnx_sai_switch.c\[\d+\]- mlnx_switch_generate_dump: Error generating extended sdk dump, sx status: Internal Error'
    - '.* ERR syncd#SDK: \[EMAD_TRANSACTION.ERR\] ACCESS_REG TIMEOUT: timeout_usec=\d+, tid=0x.*, reg=0x.*, state=\d+, dev_id=\d, access_cmd=\d+'
    - '.* ERR kernel: \[.*\] sx_core \d+:\d+:\d+.\d+: command 0x\d+ \(SX_CMD_ACCESS_REG\) timeout for cmd-ifc completion event on device \d+'
    - '.* ERR kernel: \[.*\] sx_core: CMD-IFC timeout for device:\[\d+\] sending SDK health event \(if enabled\).'
    - '.* ERR kernel: \[.*\] sx_core: failed to disconnect trap group \d+'
    - '.* ERR kernel: \[.*\] __monitor_file_read\(\): disconnect rdq \d from TG failed. err: -\d+'
    - '.* ERR kernel: \[.*\] sx_core: ioctl_read failed err:-\d+, buf_cnt:1, buff_list:.*, buff_list_cnt:.*'
    - '.* ERR syncd#SDK: :- logEventData: fv: QUEUE_COUNTER_ID_LIST: SAI_QUEUE_STAT_SHARED_WATERMARK_BYTES'
    - '.* ERR syncd#SDK: :- logEventData: op: SET, key: QUEUE_WATERMARK_STAT_COUNTER:oid:0x.*'
    - '.* ERR syncd#SDK: :- threadFunction: time span WD exceeded \d+ ms for SET:QUEUE_WATERMARK_STAT_COUNTER:oid:0x.*'
  Conditions:
    - Redmine:
      - 3373851
      Branch:
        - 202211

- Errors_list:
    - '.* ERR syncd#SDK: \[SX_API_DBG.ERR\] sxd_ioctl \(CTRL_CMD_ACCESS_REG - MGIR\) error: \[Connection timed out\]'
    - '.* ERR syncd#SDK: \[SX_API_DBG.ERR\] Failed to retrieve tiles information during FW dump generation'
    - '.* ERR syncd#SDK: \[SX_API_DBG.ERR\] Cr space dump failed#\d+'
    - '.* ERR syncd#SDK: \[SX_API_DBG.ERR\] FW dump failed, err: Internal Error'
  Conditions:
    - Redmine:
      - 3404143
      Branch:
        - 202211

- Errors_list:
    - '.* ERR syncd#SDK: :- logEventData: fv: SAI_SWITCH_ATTR_PORT_STATE_CHANGE_NOTIFY: .*'
    - '.* ERR syncd#SDK: :- logEventData: fv: SAI_SWITCH_ATTR_FDB_EVENT_NOTIFY: .*'
    - '.* ERR syncd#SDK: :- logEventData: fv: SAI_SWITCH_ATTR_INIT_SWITCH: .*'
    - '.* ERR syncd#SDK: :- logEventData: op: create, key: SAI_OBJECT_TYPE_SWITCH:.*'
    - '.* ERR syncd#SDK: :- threadFunction: time span WD exceeded \d+ ms for create:SAI_OBJECT_TYPE_SWITCH:.*'
    - '.* ERR syncd#SDK: :- logEventData: fv: SAI_SWITCH_ATTR_SWITCH_SHUTDOWN_REQUEST_NOTIFY:.*'
    - '.* ERR syncd#SDK: :- setEndTime: event ''create:SAI_OBJECT_TYPE_SWITCH:oid:0[xX][0-9a-fA-F]+'' took \d+ ms to execute.*'
  Conditions:
    - Redmine:
      - 3432623
      Branch:
        - 202211_SPC4_CS

- Errors_list:
    - '.* ERR systemd\[\d+\]: Failed to start Rotate log files'
  Conditions:
    - Redmine:
      - 3432683
      Branch:
        - 202211_SPC4_CS

- Errors_list:
    - '.* ERR what-just-happened#wjhd\[\d+\]: \[WJH_LIB.ERROR  \]: sx_lib_host_ifc_recv_list failed, error: Driver''s Return Status is Non-Zero.'
    - '.* ERR what-just-happened#wjhd\[\d+\]: \[WJH_LIB.ERROR  \]: __wjh_non_l1_cyclic_channel_read failed, err: 1'
  Conditions:
    - Redmine:
      - 3404138
      Branch:
        - 202211

- Errors_list:
    - '.* ERR what-just-happened#wjhd: :- sendRecv: Failed to receive Layer-1 Route Netlink reply message'
    - '.* ERR what-just-happened#wjhd: :- pull: Layer-1 Route Netlink socket communication error'
  Conditions:
    - Redmine:
      - 3410449
      Branch:
        - 202211
      Platform:
        - simx

- Errors_list:
    - '.* ERR kernel: .* No PCI link reporting capability.*'
    - '.* ERR kernel: .* DMAR: DRHD: handling fault status reg .*'
    - '.* ERR kernel: .* DMAR: \[DMA Read\] Request device .* PASID .* PTE Read access is not set.*'
    - '.* ERR syncd#SDK: \[HOST_INTERFACE.ERR\] FW CR timeout on log_address:.*\[Crspace timeout is due to internal FW process\].*'
    - '.* ERR syncd#SDK: \[HOST_INTERFACE.ERR\] FW health event device.* FW cause:\[1,FW CR SPACE TIMEOUT EVENT\] severity:\[3,FW NORMAL SEVERITY\] register.*'
  Conditions:
    - Redmine:
        - 3395468

- Errors_list:
    - '.*ERR syncd#SDK: \[HOST_INTERFACE\.ERR\] FW CR timeout on log_address:\[0x.*\] old_event:\[\d+\] log_id:\[\d+\] log_ip:\[0x\d+\] \[crspace timeout case is unknown\. Check FW\].*'
  Conditions:
    - Redmine:
        - 3420176
      Platform:
        - x86_64-nvidia_sn5600-r0

- Errors_list:
    - '.*ERR syncd#SDK: \[HOST_INTERFACE.ERR\].*FW assert msg: \[run_fw_assert_checker, old event, see the details by searching the original syndrome value in code\], FW assert event.*'
    - '.*ERR syncd#SDK: \[HOST_INTERFACE.ERR\].*FW health event device:\[\d+\] FW cause:\[\d+,FW ASSERT EVENT\] severity:\[\d+,FW FATAL SEVERITY\] register\[0x90f0\], long_process:\[\d+\],command_type:\[EMAD\], IRISC:\[\d+\], method:\[read\].*'
    - '.*ERR syncd#SDK: \[HOST_INTERFACE.ERR\].*FW SOS device:\[\d+] sending SDK health:\[fatal\] event cause:\[FW health issue,\d+\] \(irisc:\[\d+]\).*'
  Conditions:
    - Redmine:
        - 3394692
      Platform:
        - x86_64-nvidia_sn5600-r0

- Errors_list:
    - '.*ERR mlnx-fw-upgrade\.sh: no such file: \/etc\/mlnx\/.*'
  Conditions:
    - Redmine:
        - 3413755
      Platform:
        - x86_64-nvidia_sn5600-r0

- Errors_list:
    - '.* ERR syncd#SDK: \[ACL\.ERR\] Failed calculating key blocks - too many keys selected.*'
    - '.* ERR syncd#SDK: \[SAI_ACL\.ERR\] mlnx_sai_acl\.c\[\d+\]- mlnx_create_acl_table:  Failed to create flex key - Internal Error.*'
    - '.* ERR syncd#SDK: :- sendApiResponse: api SAI_COMMON_API_CREATE failed in syncd mode: SAI_STATUS_FAILURE.*'
    - '.* ERR syncd#SDK: :- processQuadEvent: attr: SAI_ACL_TABLE_ATTR_.*:.*'
    - '.* ERR swss#orchagent: :- create: create status: SAI_STATUS_FAILURE.*'
    - '.* ERR swss#orchagent: :- addAclTable: Failed to create ACL table EVERFLOWV6.*'
  Conditions:
    - Redmine:
        - 3415969

- Errors_list:
    - '.*ERR swss#orchagent.*doPortTask: Failed to get port id by alias:Ethernet.*'
  Conditions:
    - Affected_test_cases:
        - tests/nightly/dynamic_port_breakout/test_dpb_introp.py
      Redmine:
        - 3405332

- Errors_list:
    - '.* ERR swss#orchagent: :- mcCounterCheck: Invalid port oid.*'
    - '.* ERR swss#orchagent: :- pfcFrameCounterCheck: Invalid port oid.*'
  Conditions:
    - Affected_test_cases:
      - tests/nightly/dynamic_port_breakout/test_dpb_all_ports.py::TestDPBOnAllPorts::test_dpb_on_all_ports
      Redmine:
      - 3137469
      Platform:
      - 4600

- Errors_list:
    - '.* ERR syncd#SDK: \[SAI_OBJECT\.ERR\] mlnx_sai_object\.c\[\d+\]- mlnx_(?:allocate|deallocate)_sx_bulk_buffer: Failed to (?:create|destroy) buffer: Driver.* Return Status is Non-Zero.*'
    - '.* ERR syncd#SDK: \[SAI_QUEUE.ERR\] mlnx_sai_queue.c\[\d+\]- mlnx_sai_bulk_queue_stats_get: Failed to prepare bulk counter for queue stats.*'
    - '.* WARNING kernel: \[.*\] syncd: page allocation failure: order:\d+, mode:.*\(GFP_KERNEL\|__GFP_COMP\), nodemask=\(null\),cpuset=.*,mems_allowed=\d+.*'
    - '.* WARNING kernel: .* Node 0 DMA.* free:.* min:.* low:.* high:.* reserved_highatomic:.* active_anon:.* inactive_anon:.* active_file:.* inactive_file:.* unevictable:.* writepending:.* present:.* managed:.* mlocked:.* pagetables:.* bounce:.* free_pcp:.* local_pcp:.* free_cma:.*'
    - '.* WARNING kernel: .* Node 0 Normal.* free:.* min:.* low:.* high:.* reserved_highatomic:.* active_anon:.* inactive_anon:.* active_file:.* inactive_file:.* unevictable:.* writepending:.* present:.* managed:.* mlocked:.* pagetables:.* bounce:.* free_pcp:.* local_pcp:.* free_cma:.*'
    - '.* ERR syncd#SDK: \[SAI_BUFFER\.ERR\] mlnx_sai_buffer\.c\[\d+\]- mlnx_sai_bulk_ingress_priority_group_stats_get: Failed to .*: -1.*'
  Conditions:
    - Affected_test_cases:
      - show_techsupport/test_auto_techsupport.py
      - platform_tests/mellanox/test_check_sysfs.py
      Redmine:
      - 3425181

- Errors_list:
    - '.*ERR swss#orchagent.*doPortTask: Unsupported port speed.*'
  Conditions:
    - Redmine:
      - 3430196

- Errors_list:
    - '.*ERR syncd#SDK: \[SAI_UTILS\.ERR\] mlnx_sai_utils\.c.*sai_attribute_valid_condition_check: Attribute SAI_HOSTIF_TRAP_ATTR_TRAP_GROUP doesn.*match a valid conditions:.*SAI_HOSTIF_TRAP_ATTR_PACKET_ACTION : TRAP.*SAI_HOSTIF_TRAP_ATTR_PACKET_ACTION : COPY.*'
    - '.*ERR syncd#SDK: \[SAI_HOST_INTERFACE\.ERR\] mlnx_sai_host_interface\.c.*mlnx_create_hostif_trap: Failed attribs check.*'
    - '.*ERR syncd#SDK:.*sendApiResponse: api SAI_COMMON_API_CREATE failed in syncd mode: SAI_STATUS_FAILURE.*'
    - '.*ERR syncd#SDK.*processQuadEvent: attr: SAI_HOSTIF_TRAP_ATTR_TRAP_TYPE: SAI_HOSTIF_TRAP_TYPE_TTL_ERROR.*'
    - '.*ERR syncd#SDK.*processQuadEvent: attr: SAI_HOSTIF_TRAP_ATTR_TRAP_GROUP: oid:0x.*'
    - '.*ERR syncd#SDK.*processQuadEvent: attr: SAI_HOSTIF_TRAP_ATTR_PACKET_ACTION: SAI_PACKET_ACTION_DROP.*'
    - '.*ERR swss#orchagent.*create: create status: SAI_STATUS_FAILURE.*'
    - '.*ERR swss#orchagent.*applyAttributesToTrapIds: Failed to create trap \d+, rv:-1.*'
  Conditions:
    - Affected_test_cases:
        - drop_packets/test_wjh.py
      Redmine:
        - 3428827
      Platform:
        - 5600

- Errors_list:
    - '.* ERR what-just-happened#wjhd: :- parse_packet: Netlink message doesn''t have the NET_DM_ATTR_HW_TRAP_NAME'
    - '.* ERR what-just-happened#wjhd: :- dropmonsock_poll: Failed to read an event from Drop monitor socket'
  Conditions:
    - Affected_test_cases:
        - tests/nightly/sflow/test_sflow.py::test_sflow_agent_id
        - tests/push_build_tests/general/qos/test_qos_reload.py
      Redmine:
        - 3431869

- Errors_list:
    - '.* ERR kernel: \[.*\] sx_core: lag_id \d+ is invalid.*'
  Conditions:
    - Redmine:
      - 3437201
      Platform:
        - simx

- Errors_list:
    - '.* ERR lldp#lldp-syncd \[lldp_syncd\] ERROR: Failed to parse (LLDPd|lldp) .*does not match format ''%H:%M:%S'''
  Conditions:
    - Redmine:
        - 3431874
      Platform:
        - arm64-nvda_bf-mbf2h536c
        - arm64-nvda_bf-9009d3b600cvaa

- Errors_list:
    - '.*ERR syncd#SDK: \[HOST_INTERFACE\.ERR\] FW health event device:\[1\] FW cause:\[1,FW CR SPACE TIMEOUT EVENT\] severity:\[3,FW NORMAL SEVERITY\] register\[0x5028\], long_process:\[0\],command_type:\[EMAD\], IRISC:\[\d+\], method:\[write\].*'
  Conditions:
    - Redmine:
      - 3434337

- Errors_list:
    - '.* ERR syncd#SDK: \[ROUTER.ERR\] cntr \(0\) err: Entry Not Found.'
    - '.* ERR syncd#SDK: \[ROUTER.ERR\] counter get impl function failed with cmd=31 cntr 0, err=Entry Not Found'
    - '.* ERR syncd#SDK: \[SAI_RIF.ERR\] mlnx_sai_rif.c\[\d+\]- mlnx_get_router_interface_stats_ext: Failed to READ sx counter 0 - Entry Not Found'
    - '.* ERR syncd#SDK: :- collectData: Failed to get stats of Rif Counter 0x[a-f0-9]+: -7.*'
  Conditions:
    - Affected_test_cases:
        - tests/nightly/fec/test_fec.py
        - sub_port_interfaces/test_sub_port_interfaces.py
      Redmine:
        - 3430838

- Errors_list:
    - '.* ERR syncd#SAI: \[SAI_OBJECT.ERR\] ./src/mlnx_sai_object.c\[\d+\]- sai_object_type_get_availability: Resource availability for object type \d+ is not implemented'
  Conditions:
    - Redmine:
        - 3440885
      Platform:
        - arm64-nvda_bf-mbf2h536c
        - arm64-nvda_bf-9009d3b600cvaa

- Errors_list:
    - '.*ERR syncd#SDK: \[SAI_INTERFACE_QUERY_ETH\.ERR\] mlnx_sai_interfacequery_eth\.c\[\d+\]- sai_dbg_run_mlxtrace: Failed running.*mlxtrace_ext.*'
    - '.*ERR syncd#SDK: \[SAI_INTERFACE_QUERY_ETH\.ERR\] mlnx_sai_interfacequery_eth\.c\[\d+\]- sai_dbg_do_dump: Failed to run mlxtrace.*'
  Conditions:
    - Platform:
        - simx

- Errors_list:
    - '.*ERR pmon#sensord: Error getting sensor data: dps460.*'
  Conditions:
    - Redmine:
        - 3447925

- Errors_list:
    - '.* ERR neighbor_advertiser: EVERFLOW table does not exist.*'
  Conditions:
    - Affected_test_cases:
        - decap/test_decap.py
      Redmine:
        - 3431638
      Platform:
        - 5600

- Errors_list:
    - '.*ERR pmon#ycabled: Stop daemon main loop.*'
  Conditions:
    - Affected_test_cases:
        - dualtor_io/test_link_failure.py::test_active_link_admin_down_config_reload_upstream[active-active]
      Redmine:
        - 3521394

- Errors_list:
    - '.* ERR syncd#SDK: \[EMAD_TRANSACTION.ERR\] ACCESS_REG TIMEOUT: timeout_usec=\d+, tid=0x.*, reg=0x.*, state=\d+, dev_id=\d, access_cmd=\d+'
    - '.* ERR syncd#SDK: \[EMAD.ERR\] emad-send failed on register 0x.*, iteration \d+, status=\d+'
    - '.* ERR syncd#SDK: \[REG_BULK.ERR\] sx_reg_layer_sxd_reg_call - Error at access reg call reg_id 0x.*, error: TIMEOUT'
    - '.* ERR syncd#SDK: \[REG_BULK.ERR\] __reg_bulk_post_completion_cb Error got in completion data sxd_status \[12\]-\[TIMEOUT\].'
    - '.* ERR syncd#SDK: \[MGMT_LIB.ERR\] PDDR get failed \(TIMEOUT\).*'
    - '.* ERR syncd#SDK: \[HOST_INTERFACE.ERR]\ SX_HEALTH_FATAL: cause_string = \[timeout in FW response\], cause_id = \[\d+\].*'
    - '.* ERR kernel: .* SXD_HEALTH_FATAL:On device 1 cause =''EMAD completion timeout'' \[id = \d+\]- Stopping further device monitoring!.*'
    - '.* ERR syncd#SDK: \[SAI_SWITCH.ERR\] mlnx_sai_switch.c\[\d+\]- mlnx_switch_generate_dump: Error generating extended sdk dump, sx status: Resource is in use.*'
    - '.* ERR syncd#SDK: \[SAI_SWITCH.ERR\] mlnx_sai_switch.c\[\d+\]- mlnx_switch_health_event_handle: Health event happened, severity fatal, cause timeout in FW response.*'
  Conditions:
    - Affected_test_cases:
      - tests/show_techsupport/test_auto_techsupport.py::TestAutoTechSupport::test_max_limit
      Redmine:
        - 3527983
      Platform:
        - 5600

- Errors_list:
    - '.* ERR kernel: .* pstore: crypto_comp_decompress failed, ret = -22!.*'
  Conditions:
    - Redmine:
        - 3527217
      Platform:
        - x86_64-mlnx_msn2010-r0

# NVOS
- Errors_list:
    - '.* ERR nvued:   ERROR: lifecycle.py:\d+ Failed verify eth interface configuration.*'
  Conditions:
    - Affected_test_cases:
        - tests_nvos/interfaces/test_eth0_interface_dhcp.py::test_interface_eth0_mtu
        - tests_nvos/interfaces/test_eth0_interface_dhcp.py::test_interface_eth0_speed_duplex_autoneg

# NVOS
- Errors_list:
    - '.* ERR rsyslogd: omfwd: could not get addrinfo for hostname .*'
  Conditions:
    - Affected_test_cases:
        - tests_nvos/system/syslog/test_system_syslog.py::test_rsyslog_configurations
        - tests_nvos/system/syslog/test_system_syslog.py::test_rsyslog_configurations_openapi

# NVOS
- Errors_list:
    - '.* ERR admin: .*'
  Conditions:
    - Affected_test_cases:
        - tests_nvos/system/syslog/test_system_syslog.py::test_rsyslog_server_severity_levels
        - tests_nvos/system/syslog/test_system_syslog.py::test_rsyslog_server_severity_levels_openapi

# NVOS
- Errors_list:
    - '.* ERR rsyslogd: omfwd: remote server.*'
    - '.* ERR rsyslogd: cannot connect to.*'
  Conditions:
    - Affected_test_cases:
        - tests_nvos/system/syslog/test_system_syslog.py::test_rsyslog_protocol
        - tests_nvos/system/syslog/test_system_syslog.py::test_rsyslog_protocol_openapi

# NVOS
- Errors_list:
    - '.* INFO ib-utils#OpenSM\[\d+\]:  Loading Cached Option:enable_crashd = FALSE#012.*'
  Conditions:
    - Affected_test_cases:
        - tests_nvos/interfaces/test_ib_interface_configuration.py
        - tests_nvos/ib/test_set_unset_sm_state.py
        - tests_nvos/ib/test_unset_ib.py
        - tests_nvos/interfaces/test_ib_show_interface.py::test_ib_show_interface_all_state_up
        - tests_nvos/interfaces/test_ib_show_interface.py::test_ib_show_interface_all_state_up_openapi

# NVOS
- Errors_list:
    - '.* ERR nvued:   ERROR: lifecycle.py:\d+ Failed verify ib interface configuration.*'
  Conditions:
    - Affected_test_cases:
        - tests_nvos/interfaces/test_ib_interface_configuration.py::test_ib_interface_speed_invalid

# NVOS Errors which should be ignored in tests which doing reset service
- Errors_list:
    - '.* ERR health-statsd#health_history: ib-utils: Container .* is not running.*'
    - '.* ERR health-statsd#health_history: Summary: Not OK.*'
  Conditions:
    - Affected_test_cases:
        - tests_nvos/system/test_techsupport_feature.py::test_techsupport_with_dockers_down

# NVOS
- Errors_list:
    - '.*ERR systemd\[1\]: Failed to start LSB: LDAP connection daemon.*'
    - '.*ERR hostcfgd: \[.*\] - failed: return code - 1, output:#012b''.*'
  Conditions:
    - Affected_test_cases:
        - tests_nvos/general/security/test_aaa_ldap/test_aaa_ldap.py

# NVOS
- Errors_list:
    - '.* ERR auditd\[\d+\]: queue to plugins is full - dropping event.*'
    - '.* ERR auditd\[\d+\]: message repeated 4 times: \[ queue to plugins is full - dropping event\].*'
    - '.* ERR auditd\[\d+\]: auditd queue full reporting limit reached \- ending dropped event.*'
  Conditions:
    - Affected_test_cases:
        - tests_nvos/general/security/test_aaa_ldap/test_aaa_ldap.py
    - Redmine:
        - 3482718

# NVOS
- Errors_list:
    - '.*ERR hostcfgd: ldap server ip=.* is not a valid IP address.*'
  Conditions:
    - Affected_test_cases:
        - tests_nvos/general/security/test_aaa_ldap/test_aaa_ldap.py::test_ldap_basic_configurations_hostname
        - tests_nvos/general/security/test_aaa_ldap/test_aaa_ldap.py::test_ldap_priority_and_fallback_functionality
    - Redmine:
        - 3480907

# NVOS
- Errors_list:
    - '.* ERR nslcd\[\d+\]\: \[.*\].*ldap_result\(\) failed: Invalid DN.*'
  Conditions:
    - Affected_test_cases:
        - tests_nvos/general/security/test_aaa_ldap/test_aaa_ldap.py::test_ldap_invalid_base_dn_error_flow

# NVOS
- Errors_list:
    - '.* ERR nvued:   ERROR: lifecycle.py:\d+ Failed to run timedatectl#012Traceback \(most recent call last\):#012  File.*'
    - '.*ERR systemd-timedated\[\d+\]: Failed to set local time: Invalid argument.*'
    - '.*Failed to run timedatectl.*'
  Conditions:
    - Affected_test_cases:
        - tests_nvos/system/clock/test_system_clock.py::test_change_invalid_datetime_ntp_off_error_flow_openapi
        - tests_nvos/system/clock/test_system_clock.py::test_change_invalid_datetime_ntp_on_error_flow_openapi
        - tests_nvos/system/clock/test_system_clock.py::test_change_invalid_datetime_ntp_off_error_flow
        - tests_nvos/system/clock/test_system_clock.py::test_change_invalid_datetime_ntp_on_error_flow

# NVOS
- Errors_list:
    - '.* .* ERR nvued:   ERROR: lifecycle.py:\d+ File not found.*'
  Conditions:
    - Affected_test_cases:
        - tests_nvos/ib/test_ibdiagnet.py::test_ibdiagnet_delete
        - tests_nvos/ib/test_ibdiagnet.py::test_ibdiagnet_upload

# NVOS
- Errors_list:
    - '.* ERR nvued:   ERROR: lifecycle.py:\d+ User requested a .* reboot, but NVOS cant perform it.*'
  Conditions:
    - Affected_test_cases:
        - tests_nvos/system/test_system_reboot.py::test_reboot_command_type

# NVOS
- Errors_list:
    - '.* ERR kernel: \[ \d+.\d+\] ib_core: Method 1 already in use'
  Conditions:
    - Affected_test_cases:
        - tests_nvos/interfaces/test_ib0_interface_state.py::test_ib0_interface_state_openapi

# NVOS
- Errors_list:
    - '.* ERR nslcd\[\d+\]: .* no available LDAP server found: .*'
  Conditions:
    - Affected_test_cases:
        - tests_nvos/general/security/test_aaa_ldap/test_aaa_ldap.py::test_ldap_invalid_auth_port_error_flow
        - tests_nvos/general/security/test_aaa_ldap/test_aaa_ldap.py::test_ldap_invalid_bind_in_password_error_flow
        - tests_nvos/general/security/test_aaa_ldap/test_aaa_ldap.py::test_ldap_invalid_bind_dn_error_flow
        - tests_nvos/general/security/test_aaa_ldap/test_aaa_ldap.py::test_ldap_invalid_base_dn_error_flow
        - tests_nvos/general/security/test_aaa_ldap/test_aaa_ldap.py::test_ldap_invalid_credentials_error_flow

# NVOS : Errors which should be ignored in tests which doing reboot/reload
- Errors_list:
    - '.* ERR health-statsd#health_history: Containers: is not Status ok.*'
    - '.* ERR health-statsd#health_history: Disk check: is not Status ok.*'
    - '.* ERR health-statsd#health_history: memory_check: is not Status ok.*'
    - '.* ERR health-statsd#health_history: Summary: Not OK.*'
    - '.* ERR health-statsd#health_history: pmon: Container.*'
    - '.* ERR systemd\[1\]: Failed to start LSB: LDAP connection daemon.*'
    - '.* ERR watchdogutil: Failed to get watchdog module'
    - '.* ERR systemd\[1\]: Failed to start LSB: LDAP connection daemon.*'
    - '.* ERR watchdogutil: Failed to get watchdog module.*'
  Conditions:
    - Affected_test_cases:
        - tests_nvos/system/test_system_reboot.py
        - tests_nvos/general/config_commands/test_save_after_reboot.py::test_save_reboot
        - tests_nvos/ib/test_ibdiagnet.py::test_ibdiagnet_run
        - tests_nvos/system/test_install_system_firmware.py::test_install_system_firmware

# NVOS : Error - Bug 3494774 related
- Errors_list:
    - '.* ERR countermgrd: failed to get COUNTERS_PORT_NAME_MAP with: Unable to connect to redis: Cannot assign requested address.*'
  Conditions:
    - Affected_test_cases:
        - tests_nvos/general/config_commands/test_show_diff_history::test_diff_history_revision_ids
        - tests_nvos/general/config_commands/test_replace_patch.py::test_patch_positive
        - tests_nvos/system/test_show_system.py::test_system
        - tests_nvos/system/test_show_system.py::test_system_openapi
      Redmine:
        - 3494774

# NVOS : Errors - Bug 3474336 related
- Errors_list:
    - '.* ERR health-statsd#health_history: Containers: is not Status ok.*'
    - '.* ERR health-statsd#health_history: Disk check: is not Status ok.*'
    - '.* ERR health-statsd#health_history: memory_check: is not Status ok.*'
    - '.* ERR health-statsd#health_history: Summary: Not OK.*'
  Conditions:
    - Affected_test_cases:
        - tests_nvos/general/config_commands/test_apply_detach.py::test_apply_assume
        - tests_nvos/general/config_commands/test_replace_patch.py
        - tests_nvos/general/config_commands/test_show_diff_history.py
        - tests_nvos/system/test_show_system.py::test_system
        - tests_nvos/system/test_show_system.py::test_system_openapi
        - tests_nvos/system/test_show_system.py::test_show_system_cpu_openapi
      Redmine:
        - 3474336

# NVOS
- Errors_list:
    - '.*ERR hostcfgd: \[.*\] - failed.*'
  Conditions:
    - Affected_test_cases:
        - tests_nvos/ib/test_ibdiagnet.py::test_ibdiagnet_run_multiple_times
        - tests_nvos/system/test_system_reboot.py
      Redmine:
        - 3494875

# NVOS : Errors which should be ignored in tests using invalid url
- Errors_list:
    - '.* ERR nvued:   ERROR: lifecycle.py:\d+ File not found.*'
    - '.* ERR nvued:   ERROR: format_checkers.py:\d+.*'
    - '.* ERR nvued: message repeated 3 times: \[   ERROR: format_checkers.py:\d+.*'
    - '.* ERR nvued:   ERROR: format_checkers.py:\d+ Instance ffff:.*'
    - '.* ERR nvued: message repeated 3 times: \[   ERROR: format_checkers.py:\d+ Instance ffff.*'
  Conditions:
    - Affected_test_cases:
        - tests_nvos/system/test_system_documents.py::test_upload_document
        - tests_nvos/ib/test_ibdiagnet.py::test_ibdiagnet_upload
        - tests_nvos/system/test_techsupport_commands.py::test_techsupport_upload

- Errors_list:
    - '.* ERR syncd#SDK: \[SX_API_PORT.ERR\] sx_api_port_parsing_depth_set: This API is deprecated and will be removed in the future. Please use sx_api_port_parser_attr_set in its place.*'
    - '.* ERR syncd#SDK: \[SAI_UTILS.ERR\] mlnx_sai_utils.c\[\d+\]- sai_get_attributes: Failed to get attribute.*'
  Conditions:
    - Affected_test_cases:
        - tests/nightly/logging/test_log_analyzer_errors_during_deploy_sonic.py
        - tests/push_build_tests/general/qos/test_qos_reload.py
      Redmine:
        - 3472796

- Errors_list:
    - '.* ERR swss#buffermgrd: :- isHeadroomResourceValid: Unable to update profile for port Ethernet\d+. Accumulative headroom size exceeds limit.*'
    - '.* ERR swss#buffermgrd: :- doUpdateBufferProfileForSize: BUFFER_PROFILE headroom-override cannot be updated because Ethernet.* referencing it violates the resource limitation.*'
  Conditions:
    - Affected_test_cases:
        - tests/qos/test_buffer.py::test_headroom_override
      Redmine:
        - 3466071

# The issue of https://redmine.mellanox.com/issues/3266868 is won't fix, ignore below errors statically
- Errors_list:
    - '.* ERR kernel: \[.*\] Fails to access \(\d+\) register MCIA \(module:\d+, page:\d+, device_addr:\d+, size:\d+, i2c_addr:.*, slot:\d+, status:\d+\), err: -16.*'
    - '.* ERR kernel: \[.*\] Fails to get module type, err: -16.*'
    - '.* ERR kernel: \[ .*\] Fails to read module eeprom, status: -16.*'
    - '.* ERR kernel: \[.*\] Fails to access .* module eeprom, status: -16.*'
    - '.* ERR pmon#xcvrd:.*Failed to get SFP type, index=\d+, error=\[Errno \d+\] Device or resource busy.*'
  Conditions:
    - Affected_test_cases:
      - tests/nightly/auto_negotition/test_auto_neg_scale.py
      - tests/nightly/app_extension/test_app_extension_basic.py::test_app_techsupport_integration
      - show_techsupport/test_auto_techsupport.py::TestAutoTechSupport::test_sanity
      - qos/test_buffer.py::test_port_admin_down

- Errors_list:
    - ".*ERR sonic-ztp\\[\\d+\\]: Exception \\[Expecting ',' delimiter: line \\d+ column \\d+ \\(char \\d+\\)] encountered while verifying '\\/etc\\/sonic\\/config_db\\.json'.*"
  Conditions:
    - Redmine:
        - 3474406

- Errors_list:
    - '.*ERR swss#orchagent: :- updateVnetTunnel: Failed to parse key , no vrf is given.*'
  Conditions:
    - Redmine:
        - 3473183

- Errors_list:
    - '.*ERR syncd#SDK: \[SX_API_PORT\.ERR\] sx_api_port_parsing_depth_set: This API is deprecated and will be removed in the future\. Please use sx_api_port_parser_attr_set in its place.*'
  Conditions:
    - Redmine:
        - 3482636

- Errors_list:
    - '.*ERR pmon#psud: Fail to read model number: No key PN_VPD_FIELD.*'
    - '.*ERR pmon#psud: Fail to read serial number: No key SN_VPD_FIELD.*'
    - '.*ERR pmon#psud: Fail to read revision: No key REV_VPD_FIELD.*'
  Conditions:
    - Redmine:
      - 3546979
      Platform:
        - simx

- Errors_list:
    - '.*ERR swss#orchagent: :- removeVlan: Failed to remove ref count 1 VLAN Vlan.*'
  Conditions:
    - Redmine:
        - 3487047

- Errors_list:
    - '.* ERR swss#intfmgrd: :- setIntfIp: Command ''/sbin/ip address "add" ".*" broadcast ".*" dev ".*"'' failed with rc \d+'
  Conditions:
    - Redmine:
        - 3508074

- Errors_list:
    - '.*ERR hw-management-tc: ERROR - Missing max tachos config.*'
  Conditions:
    - Redmine:
      - 3527759
      Platform:
        - simx

- Errors_list:
    - '.*ERR kernel: .* mlxsw_minimal 2-0048: Failed to write PWM.*'
  Conditions:
    - Affected_test_cases:
        - tests/nightly/fec/test_fec.py
        - tests/nightly/auto_negotition/test_auto_neg.py::TestAutoNeg::test_auto_neg_conf
      Redmine:
        - 3488995

- Errors_list:
    - '.*ERR syncd#SDK: \[HOST_INTERFACE.ERR\] SX_HEALTH_FATAL Detected with cause : FW health issue \[id = 1\].*'
    - '.*ERR kernel: .* sx_core: SDK health event, device:.*'
    - '.*ERR kernel: .* SXD_HEALTH_FATAL:On device 1 cause =''FW health issue'' \[id = 1\]- Stopping further device monitoring!.*'
    - '.*ERR swss#orchagent: :- on_switch_shutdown_request: Syncd stopped.*'
    - '.*ERR hw-management-tc: ERROR - Read PWM error. Possible hw-management is not running.*'
    - '.*ERR hw-management-tc: message repeated .* times: \[ ERROR - Read PWM error. Possible hw-management is not running\].*'
  Conditions:
    - Redmine:
        - 3488969

- Errors_list:
    - '.*ERR syncd#SDK: .*- sai_set_attribute: Failed to set the attribute..*'
  Conditions:
    - Affected_test_cases:
        - tests/nightly/auto_negotition/test_auto_neg_negative.py::TestAutoNegNegative::test_negative_advertised_speed_type_mismatch
      Redmine:
        - 3488512

# In the test case test_sensor_errors[psu_err_present], it has an action to remove the psu file,
# when pmon try to read the file psu file "/var/run/hw-management/thermal/psu\d+_status",
# following error msg will be logged to syslog, it is not an real issue, so it is safe to ignore these err msg
- Errors_list:
    - '.*ERR pmon#psud: Failed to read from file \/var\/run\/hw-management\/thermal\/psu\d+_status - FileNotFoundError.*No such file or directory.*'
    - '.*ERR pmon#psud: Failed to read from file \/var\/run\/hw-management\/thermal\/psu\d+_status - ValueError.*invalid literal for int.* with base.*'
    - '.*ERR pmon#thermalctld: Failed to read from file \/var\/run\/hw-management\/thermal\/psu\d+_status - ValueError.*invalid literal for int.* with base.*'
  Conditions:
    - Affected_test_cases:
      - tests/nightly/new_hw_thermal_control/test_new_hw_tc_algorithm.py::TestNewTc::test_sensor_errors[psu_err_present]

# In the test case test_sensor_errors[fan_err_present], it has an action to remove the fan status file,
# when pmon try to read the file psu file "/var/run/hw-management/thermal/fan\d+_status",
# following error msg will be logged to syslog, it is not an real issue, so it is safe to ignore these err msg
- Errors_list:
    - '.*ERR pmon#thermalctld: Failed to read from file \/var\/run\/hw-management\/thermal\/fan\d+_status - FileNotFoundError.*No such file or directory.*'
  Conditions:
    - Affected_test_cases:
      - tests/nightly/new_hw_thermal_control/test_new_hw_tc_algorithm.py::TestNewTc::test_sensor_errors[fan_err_present]

# NVOS : Errors - Bug 3493347 related
- Errors_list:
    - '.*ERR dhclient\[\d+\]: send_packet: Network is unreachable.*'
    - '.*ERR dhclient\[\d+\]: send_packet: please consult README file regarding broadcast address.*'
    - '.*ERR dhclient\[\d+\]: dhclient.c:2879: Failed to send 300 byte long packet over fallback interface.*'
  Conditions:
    - Redmine:
        - 3493347

# NVOS
- Errors_list:
    - '.*INFO ib-utils#OpenSM\[\d+\]:  Loading Cached Option:enable_crashd = FALSE.*'
  Conditions:
    - Affected_test_cases:
      - tests_nvos/general/traffic/test_basic_traffic.py
      - tests_nvos/interfaces/test_ib_interface_counters.py
      - tests_nvos/interfaces/test_port_split.py
      Redmine:
        - 3498811

- Errors_list:
    - '.*ERR syncd#SDK: \[SAI_OBJECT\.ERR\] mlnx_sai_object\.c\[\d+\]- mlnx_wait_for_bulk_read_event: Bulk read event status is not OK.*'
    - '.*ERR kernel: \[.*\] SX_BULK_CNTR: operation TLV is missing in buffer.*'
    - '.*ERR syncd#SDK: \[SAI_PORT\.ERR\] mlnx_sai_port\.c\[\d+\]- mlnx_get_port_stats_ext: Failed to prepare bulk counter for port stats.*'
    - '.*ERR syncd#SDK: :- collectData: Failed to get stats of Port Counter.*'
  Conditions:
    - Redmine:
      - 3492750

# NVOS
- Errors_list:
    - '.*ERR health-statsd#health_history: .*: speed is out of range, speed=.*'
  Conditions:
    - Affected_test_cases:
      - tests_nvos/system/test_system_health.py::test_simulate_fan_speed_fault

# NVOS
- Errors_list:
    - '.*ERR health-statsd#health_history: ib-utils: Container .* is not running.*'
  Conditions:
    - Affected_test_cases:
      - tests_nvos/system/test_system_health.py::test_simulate_health_problem_with_docker_stop

# NVOS
- Errors_list:
    - '.*ERR health-statsd#health_history: bad_device: device is out of power.*'
  Conditions:
    - Affected_test_cases:
      - tests_nvos/system/test_system_health.py::test_simulate_health_problem_with_user_config_file
      - tests_nvos/system/test_system_health.py::test_system_health_files_with_rotation
      - tests_nvos/system/test_system_health.py::test_system_health_files

# NVOS - snmp error flows
- Errors_list:
    - ".*ERR health-statsd#health_history: snmp:snmp-subagent: 'snmp-subagent' is not running.*"
    - ".*ERR health-statsd#health_history: snmp:snmpd: 'snmpd' is not running.*"
    - ".*ERR health-statsd#health_history: snmp: Container 'snmp' is not running.*"
    - '.*ERR container: docker cmd: start for snmp failed with.*'
    - '.*ERR systemd\[\d+\]: Failed to start SNMP container.*'
    - '.*warn=True _uses_shell=False.*'
  Conditions:
    - Affected_test_cases:
      - tests_nvos/system/test_system_snmp.py::test_system_snmp_load_test
      - tests_nvos/system/test_system_snmp.py::test_system_snmp_redis_crash
      - tests_nvos/system/test_system_snmp.py::test_snmp_default_values_fields
      - tests_nvos/system/test_system_snmp.py::test_system_snmp_negative

# NVOS
- Errors_list:
    - '.*ERR health-statsd#health_history: Summary: Not OK.*'
  Conditions:
    - Affected_test_cases:
        - tests_nvos/system/test_system_snmp.py::test_system_snmp_load_test
        - tests_nvos/system/test_system_snmp.py::test_system_snmp_redis_crash
        - tests_nvos/system/test_system_snmp.py::test_snmp_default_values_fields
        - tests_nvos/system/test_system_snmp.py::test_system_snmp_load_test
        - tests_nvos/system/test_system_snmp.py::test_system_snmp_redis_crash
        - tests_nvos/system/test_system_snmp.py::test_snmp_default_values_fields
        - tests_nvos/system/test_system_health.py::test_simulate_health_problem_with_user_config_file
        - tests_nvos/system/test_system_health.py::test_system_health_files_with_rotation
        - tests_nvos/system/test_system_health.py::test_system_health_files
        - tests_nvos/system/test_system_health.py::test_simulate_health_problem_with_docker_stop
        - tests_nvos/system/test_system_health.py::test_simulate_fan_speed_fault
        - tests_nvos/system/test_system_snmp.py::test_system_snmp_negative

# NVOS
- Errors_list:
    - '.*ERROR: native.py:\d+ Port internal name for interface .* is empty.*'
    - '.*ERROR: ib_utils_funcs.py:\d+ Interface .* invalid supported_speeds None.*'
    - '.*ERROR: ib_utils_funcs.py:\d+ Interface .* invalid supported_speeds \[\], returning max None.*'
    - '.*ERROR: ib_utils_funcs.py:\d+ Interface .* invalid speed_admin None.*'
    - '.*ERROR: ib_utils_funcs.py:\d+ Interface .* admin_speed is None speed should be configured first.*'
  Conditions:
    - Affected_test_cases:
      - tests_nvos/interfaces/test_port_split.py::test_split_port_timings
      - tests_nvos/interfaces/test_port_split.py::test_split_port_counters
      - tests_nvos/interfaces/test_port_split.py::test_split_port_n_times
      Redmine:
        - 3498811

# NVOS - FW Health issue
- Errors_list:
    - '.*ERR syncd-ibv0#SDK: \[HOST_INTERFACE\.ERR\] FW fatal cause: HW cause id = \[.*\], cause_reg = \[.*\], cause_offset = \[.*\]'
    - '.*ERR syncd-ibv0#SDK: \[HOST_INTERFACE\.ERR\] FW health event device:\[\d+\] FW cause:\[\d+,FW FATAL CAUSE EVENT\] severity:\[\d+,FW FATAL SEVERITY\] register\[.*\], long_process:\[\d+\],command_type:\[CMD-IFC\], IRISC:\[\d+\], method:\[.*\]'
    - '.*ERR syncd-ibv0#SDK: \[HOST_INTERFACE\.ERR\] FW SOS device:\[\d+\] sending SDK health:\[fatal\] event cause:\[FW health issue,\d+\] \(irisc:\[\d+\]\)'
    - '.*ERR syncd-ibv0#SDK: \[HOST_INTERFACE\.ERR\] SX_HEALTH_FATAL Detected with cause : FW health issue \[id = \d+\]'
  Conditions:
    - Redmine:
      - 3498997

# NVOS - log issue
- Errors_list:
    - ".*ERR rsyslogd: file size limit cmd for file '\/var\/log\/nvued.log' did no resolve situation.*"
  Conditions:
    - Redmine:
      - 3512321

# NVOS - warning in traffic test
- Errors_list:
    - '.*WARNING kernel: \[ \d+.\d+\] NOHZ tick-stop error: Non-RCU local softirq.*'
  Conditions:
    - Affected_test_cases:
      - tests_nvos/general/traffic/test_basic_traffic.py::test_basic_traffic
      Redmine:
        - 3512421

# NVOS
- Errors_list:
    - '.*failed to get COUNTERS_PORT_NAME_MAP with: Unable to connect to redis: Cannot assign requested address.*'
  Conditions:
    - Redmine:
        - 3494774

# NVOS
- Errors_list:
    - '.*ERR hostcfgd: cmd: \[''chage'', ''-M'', ''180'', ''.*''\], return code: 1, output: b'''''
  Conditions:
    - Affected_test_cases:
        - tests_nvos/general/security/password_hardening/test_password_hardening_nvos.py::test_password_hardening_expiration_warning_functionality
        - tests_nvos/general/security/password_hardening/test_password_hardening_nvos.py::test_password_hardening_expiration_functionality
        - tests_nvos/general/security/password_hardening/test_password_hardening_nvos.py::test_password_hardening_functionality
      Redmine:
        - 3531935

# NVOS
- Errors_list:
    - '.*ERR healthd: configmgrd service status: Down, app status: Down, fail reason: Inactive.*'
    - '.*ERR healthd: interfaces-config service status: Down, app status: Down, fail reason: Inactive.*'
    - '.*ERR healthd: ntp-config service status: Down, app status: Down, fail reason: Inactive.*'
    - '.*ERR healthd: portsyncmgrd service status: Down, app status: Down, fail reason: Inactive.*'
    - '.*ERR healthd: swss-ibv0@0 service status: Down, app status: Down, fail reason: Inactive.*'
    - '.*ERR healthd: syncd-ibv0@0 service status: Down, app status: Down, fail reason: Inactive.*'
    - '.*ERR healthd: usercfgd service status: Down, app status: Down, fail reason: Inactive.*'
    - '.*ERR healthd: usercfgd service status: Starting, app status: Starting, fail reason.*'
    - '.*ERR healthd: system_serviceSet changed size during iteration.*'
    - '.*ERR healthd: interfaces-config service status: Starting, app status: Starting, fail reason.*'
    - '.*ERR healthd: swss-ibv0@0 service status: Starting, app status: Starting, fail reason.*'
    - '.*ERR healthd: syncd-ibv0@0 service status: Starting, app status: Starting, fail reason.*'
    - '.*ERR healthd: ntp-config service status: Starting, app status: Starting, fail reason.*'
  Conditions:
    - Affected_test_cases:
      - tests_nvos/system/test_system_reboot.py::test_reboot_command
      - tests_nvos/general/config_commands/test_save_after_reboot.py::test_save_reboot
      - tests_nvos/system/test_system_reboot.py::test_reboot_command_immediate
      - tests_nvos/system/test_system_reboot.py::test_reboot_command_force
      - tests_nvos/ib/test_ibdiagnet.py::test_ibdiagnet_run
      Redmine:
        - 3532697

# NVOS
- Errors_list:
    - '.*ERR health-statsd: unexpected exception #012#012  RAN: \/usr\/bin\/monit summary.*'
    - '.*ERR health-statsd#health_history: Fan: Failed to get fan information.*'
    - ".*ERR health-statsd#health_history: ib-utils: Container 'ib-utils' is not running.*"
    - '.*ERR health-statsd#health_history: monit: service is not ready.*'
    - ".*ERR health-statsd#health_history: pmon: Container 'pmon' is not running.*"
    - ".*ERR health-statsd#health_history: syncd-ibv00: Container 'syncd-ibv00' is not running.*"
    - ".*ERR health-statsd#health_history: PSU: Failed to get information.*"
  Conditions:
    - Affected_test_cases:
      - tests_nvos/general/config_commands/test_replace_patch.py::test_patch_positive
      - tests_nvos/general/config_commands/est_show_diff_history.py::test_diff_history_revision_ids
      Redmine:
        - 3531453
